Workbook

Sheet README
B2: RescueSwarm — Complete Bill of Materials
B3: NIDAR 2026–27 Track 1 · derived from the Sizing & Calculations report
B5: PURPOSE | C5: Every component required to build the 3-aircraft RescueSwarm system, the ground segment, the test rig, and the spares. Quantities and masses are traceable to the sizing model.
B6: DESIGN POINT | C6: Quadrotor · 18x6.1 CF folding props · T-Motor MN5008 KV170 · 6S3P 21700 Li-ion (18 cells, 292 Wh) · MTOW 5.71 kg · fleet 17.12 kg against a 25 kg cap (32% margin) · hover 784 W · endurance 17.9 min vs a 7.7 min design mission (2.3x).
B7: CHANGE FROM THE SIZING REPORT | C7: The report assumed 20 in props and a 6S2P pack. Real hardware forced two revisions: (1) the MN5008 is rated for 17-18 in props, so the baseline moves to 18x6.1 (hover power 666 W instead of 605 W); (2) 6S2P left only 9% current margin at peak thrust, so the pack goes to 6S3P. Both changes are documented on the Mass Rollup tab. MTOW rises 5.05 -> 5.71 kg; the fleet is still 32% under the cap.
B8: PRICES | C8: INDICATIVE BUDGETARY ESTIMATES IN INR, for planning only. They are not quotations. Import duty, GST and freight are added as separate lines on the Cost Summary. Re-price everything at the Phase 1 procurement gate.
B9: MASSES | C9: Manufacturer figures where published (marked in the Source column); otherwise engineering estimates. Weigh every part on arrival and update the Actual Mass column — the fleet weigh-in is a pass/fail rule check.
B10: HOW TO USE | C10: Blue cells are inputs you should edit. Black cells are formulas. Yellow cells are decisions still open. Fill the "Actual Mass" and "Actual Price" columns as parts arrive; the Mass Rollup and Cost Summary update automatically.
B11: TIERS | C11: Where a component has a wide price range (mesh radio, compute, GNSS), three options are listed: A = student budget, B = mid, C = professional. Tier A is costed in the totals. Swapping tiers only requires changing the Include column to 1/0.
B12: OPEN DECISIONS | C12: Highlighted yellow: quad vs hex, rolling vs global shutter camera, mesh radio tier, whether an RTK base is permitted by the organisers (see clarification question 1 in the Development Plan).
B14: TAB GUIDE
B15: 01 Air Vehicle BOM | C15: Everything on one aircraft. Multiply by 3 for the fleet.
B16: 02 Payload & Kits | C16: Survivor kits and the release mechanism, fleet quantities.
B17: 03 Ground Segment | C17: GCS, mesh ground node, RTK base, field infrastructure, safety.
B18: 04 Test & Lab Equipment | C18: Thrust stand, chargers, instruments, calibration targets.
B19: 05 Spares & Consumables | C19: What you must have in the field box and on the bench.
B20: 06 Software & Data | C20: Toolchain, datasets, services. Mostly free — listed so nothing is forgotten.
B21: 07 Mass Rollup | C21: Per-aircraft and fleet mass, checked against the 25 kg rule.
B22: 08 Cost Summary | C22: Programme cost by category, with duty/GST/freight and contingency.

Sheet 01 Air Vehicle BOM
A1: 01 — AIR VEHICLE BOM (per aircraft; multiply by 3)
A2: Masses in grams. Design point: quad, 18x6.1 props, MN5008 KV170, 6S3P 21700 Li-ion, MTOW 5.71 kg. Prices indicative INR, ex-duty.
A3: # | B3: Component | C3: Specification / Part | D3: Qty | E3: Unit Mass (g) | F3: Total Mass (g) | G3: Unit Price (INR) | H3: Ext. Price (INR) | I3: Actual Mass (g) | J3: Supplier / Source | K3: Lead Time | L3: Why this part / sizing reference | M3: Alternative
A4: STRUCTURE — target 1187 g (23.5% of MTOW), see Sizing §5
A5: 1 | B5: Arm tube | C5: Carbon fibre round tube 25 mm OD x 23 mm ID x 400 mm | D5: 4 | E5: 95 | F5: =D5*E5 | G5: 1200 | H5: =D5*G5 | J5: CF tube supplier / Hindoostan | K5: 2 wk | L5: Sizing §13: arm root moment 9.4 N·m at T/W=2 gives 22 MPa vs ~600 MPa UD carbon, SF 28. Bending is not the driver; the clamp joint is. | M5: 20x18 mm tube saves 40 g; SF still >15
A6: 2 | B6: Centre plate | C6: CF sandwich 2.5 mm, CNC cut, top + bottom | D6: 2 | E6: 155 | F6: =D6*E6 | G6: 3500 | H6: =D6*G6 | J6: CNC CF cutting service | K6: 3 wk | L6: Carries all four arm clamps and the battery tray. Custom cut — rule C3 forbids a market-ready airframe. | M6: 3 mm 3K twill if stiffness is short
A7: 3 | B7: Arm clamp set | C7: Machined Al 6061 or CF clamp, 25 mm bore, with anti-rotation key | D7: 4 | E7: 45 | F7: =D7*E7 | G7: 900 | H7: =D7*G7 | J7: Machine shop / T-Motor | K7: 3 wk | L7: Highest-risk mechanical joint on the aircraft. Must not creep under vibration. | M7: Folding clamp adds 25 g, aids transport
A8: 4 | B8: Motor mount plate | C8: CF 3 mm, 25 mm tube saddle, M3 x 4 pattern | D8: 4 | E8: 22 | F8: =D8*E8 | G8: 450 | H8: =D8*G8 | J8: CNC CF cutting service | K8: 3 wk | L8: Interfaces MN5008 3-hole 120° pattern to the arm. | M8: Integrated into arm clamp
A9: 5 | B9: Landing gear leg | C9: CF tube 16 mm x 300 mm with damped foot | D9: 4 | E9: 55 | F9: =D9*E9 | G9: 650 | H9: =D9*G9 | J9: CF tube supplier | K9: 2 wk | L9: Must absorb a 1.5 m/s touchdown at 5.71 kg and keep the payload magazine clear of the ground. | M9: Sprung skid; +40 g
A10: 6 | B10: Landing foot | C10: TPU moulded / 3D printed, 50 mm dia | D10: 4 | E10: 12 | F10: =D10*E10 | G10: 120 | H10: =D10*G10 | J10: In-house 3D print | K10: — | L10: Protects the tube end and damps landing impulse. | M10: Rubber vibration mount
A11: 7 | B11: Battery tray + strap | C11: CF tray, 2x hook-loop strap, foam pad | D11: 1 | E11: 85 | F11: =D11*E11 | G11: 700 | H11: =D11*G11 | J11: In-house + hardware | K11: 1 wk | L11: Retains a 1449 g pack under a 3 g landing load. | M11: Quick-release latch
A12: 8 | B12: FC vibration mount | C12: Silicone damping-ball plate, 4 balls, 20-30 shore | D12: 1 | E12: 18 | F12: =D12*E12 | G12: 450 | H12: =D12*G12 | J12: Holybro / generic | K12: 1 wk | L12: IMU vibration is the top cause of EKF failure on student builds. Sizing §13 flags vibration fatigue as the real structural driver. | M12: Gel pad + 3M VHB
A13: 9 | B13: Electronics canopy | C13: 3D-printed PETG/ASA shell with vents, IP-splash rated | D13: 1 | E13: 140 | F13: =D13*E13 | G13: 600 | H13: =D13*G13 | J13: In-house 3D print | K13: 1 wk | L13: Houses Jetson, mesh radio, PDB. Must accept the cooling blower duct (Sizing §14). | M13: CF shell, -60 g, +INR 4000
A14: 10 | B14: Compute bay duct + blower | C14: 5 V 40 mm blower + printed duct, active from power-on | D14: 1 | E14: 32 | F14: =D14*E14 | G14: 450 | H14: =D14*G14 | J14: Generic / in-house | K14: 1 wk | L14: Sizing §14: worst thermal case is the 5-min setup with props stopped, Jetson at 18 W, ambient 35 °C. | M14: Passive heatsink only — NOT recommended
A15: 11 | B15: Fastener kit | C15: M3 socket cap A2 (6-30 mm), nyloc, washers, M3 heat inserts | D15: 1 | E15: 110 | F15: =D15*E15 | G15: 900 | H15: =D15*G15 | J15: Local hardware | K15: 1 wk | L15: Assume ~120 fasteners per aircraft. Budget threadlocker separately. | M15: Titanium; -35 g, 5x cost
A16: 12 | B16: Standoffs / spacers | C16: M3 aluminium, 10-40 mm assorted | D16: 1 | E16: 60 | F16: =D16*E16 | G16: 350 | H16: =D16*G16 | J16: Local hardware | K16: 1 wk | L16: Stack spacing for the avionics tray. | M16: Nylon; -25 g, less stiff
A17: 13 | B17: Wiring channel / grommets | C17: Rubber grommets, spiral wrap, P-clips | D17: 1 | E17: 35 | F17: =D17*E17 | G17: 300 | H17: =D17*G17 | J17: Local hardware | K17: 1 wk | L17: Chafe protection where the harness passes through CF — CF dust is conductive and abrasive. | M17: —
A18: PROPULSION — target 934 g
A19: 14 | B19: Motor | C19: T-Motor Antigravity MN5008 KV170, 6-12S | D19: 4 | E19: 135 | F19: =D19*E19 | G19: 9500 | H19: =D19*G19 | J19: T-Motor / Indian distributor | K19: 4-6 wk | L19: Sizing §6: need 2.53 kgf/motor at T/W=2. MN5008 gives 4.1 kgf on 18x6.1 → T/W_max 2.87, hover at 35% of max. Over-motored, but the 32% fleet mass margin makes that a good trade for wind and failure headroom. | M19: MN4014 KV330: -25 g each, hover ~50% of max, less headroom
A20: 15 | B20: ESC | C20: 60 A 6-12S BLHeli-32 / AM32, DShot600, telemetry out | D20: 4 | E20: 45 | F20: =D20*E20 | G20: 3500 | H20: =D20*G20 | J20: T-Motor / Hobbywing / Flycolor | K20: 3-4 wk | L20: Sizing §6: 98 A pack peak = ~25 A per motor. A 60 A ESC is 2.4x margin, which is the right number for a heavy-lift build. | M20: 4-in-1 ESC saves wiring but is a single point of failure
A21: 16 | B21: Propeller pair | C21: 18 x 6.1 in CF folding, CW+CCW, T-Motor P18x6.1 or MF1806 | D21: 2 | E21: 116 | F21: =D21*E21 | G21: 2800 | H21: =D21*G21 | J21: T-Motor | K21: 4 wk | L21: Sizing §3: prop diameter drives hover power as 1/D. 18 in is the largest the MN5008 is rated for. Folding for transport. | M21: Fixed 18x6.1: -15 g/pair, cheaper, bulkier to ship
A22: 17 | B22: Prop adapter / hub | C22: M8 self-tightening or folding hub, matched to motor shaft | D22: 4 | E22: 14 | F22: =D22*E22 | G22: 650 | H22: =D22*G22 | J22: T-Motor | K22: 4 wk | L22: Must match the MN5008 shaft. Confirm included in motor kit before ordering. | M22: Included with some motor SKUs
A23: POWER — target 1449 g pack + 275 g distribution
A24: 18 | B24: Li-ion cell | C24: Molicel INR21700-P45B, 4500 mAh, 45 A continuous | D24: 18 | E24: 70 | F24: =D24*E24 | G24: 750 | H24: =D24*G24 | J24: Cell distributor (authentic only) | K24: 3-4 wk | L24: Sizing §4: 6S3P = 292 Wh, 13.5 Ah, 135 A burst vs a 98 A peak demand (38% margin). Counterfeits are common — buy from an authorised source and capacity-test every cell. | M24: Samsung 50S: +5% energy, 25 A/cell, needs 6S4P
A25: 19 | B25: Cell holder + nickel | C25: 21700 holders, 0.15 x 8 mm pure nickel strip, fish paper | D25: 1 | E25: 120 | F25: =D25*E25 | G25: 1400 | H25: =D25*G25 | J25: Battery build supplier | K25: 2 wk | L25: Spot-welded pack. Nickel cross-section sized for 135 A burst. | M25: Pre-built 6S3P pack from a vendor
A26: 20 | B26: BMS / balance board | C26: 6S balance lead board with per-cell taps, 100 A discharge path | D26: 1 | E26: 45 | F26: =D26*E26 | G26: 1800 | H26: =D26*G26 | J26: Generic | K26: 2 wk | L26: Balance charging and per-cell monitoring. Discharge path may bypass the BMS if it cannot take 135 A. | M26: Balance leads only, no BMS
A27: 21 | B27: Pack wrap + case | C27: Heat shrink, foam, hard-shell frame | D27: 1 | E27: 95 | F27: =D27*E27 | G27: 800 | H27: =D27*G27 | J27: Local | K27: 1 wk | L27: Protects cells from vibration and crash puncture. | M27: —
A28: 22 | B28: Main connector | C28: XT90-S anti-spark, male + female with pigtails | D28: 2 | E28: 22 | F28: =D28*E28 | G28: 350 | H28: =D28*G28 | J28: Amass / generic | K28: 1 wk | L28: Anti-spark is mandatory at 292 Wh — a plain XT90 will arc and pit. | M28: AS150 + XT150 for >120 A
A29: 23 | B29: Power distribution board | C29: PDB rated 200 A continuous, 10 AWG pads | D29: 1 | E29: 55 | F29: =D29*E29 | G29: 2200 | H29: =D29*G29 | J29: Mauch / Holybro / generic | K29: 2 wk | L29: Sizing §6: 98 A peak. 200 A rating gives thermal margin at 45 °C ambient. | M29: Solder direct to a copper bus bar
A30: 24 | B30: Power module / current sensor | C30: Hall-effect 100-200 A, 6-14S, with 5 V FC supply | D30: 1 | E30: 42 | F30: =D30*E30 | G30: 3200 | H30: =D30*G30 | J30: Mauch HS-200 / Holybro PM07 | K30: 2-3 wk | L30: Battery telemetry drives the low-battery failsafe (rule C16) and the SoC display on the GCS (rule C11). | M30: Shunt-based; cheaper, less accurate at low current
A31: 25 | B31: BEC 5 V | C31: 5 V 5 A switching, low-noise, for FC + peripherals | D31: 1 | E31: 28 | F31: =D31*E31 | G31: 900 | H31: =D31*G31 | J31: Mateksys / generic | K31: 1 wk | L31: Separate rail from the compute BEC so a Jetson brownout cannot take the FC down. | M31: Use FC internal BEC — not recommended at this power
A32: 26 | B32: BEC 12 V | C32: 12 V 5 A switching, for Jetson + mesh radio | D32: 1 | E32: 34 | F32: =D32*E32 | G32: 1100 | H32: =D32*G32 | J32: Mateksys / generic | K32: 1 wk | L32: Jetson Orin Nano needs a clean 12 V at ~4 A peak. Sizing §14: 42 W total avionics. | M32: 19 V module for a barrel-jack carrier
A33: 27 | B33: Silicone wire 10 AWG | C33: Red + black, 2 m total | D33: 1 | E33: 110 | F33: =D33*E33 | G33: 600 | H33: =D33*G33 | J33: Local | K33: 1 wk | L33: Sizing §6: 98 A peak → 10 AWG mains. | M33: 8 AWG if runs exceed 300 mm
A34: 28 | B34: Silicone wire 14 AWG | C34: Motor phase leads, 6 m | D34: 1 | E34: 95 | F34: =D34*E34 | G34: 500 | H34: =D34*G34 | J34: Local | K34: 1 wk | L34: 25 A per motor peak → 14 AWG is comfortable. | M34: 12 AWG
A35: 29 | B35: Signal wire + connectors | C35: 22-26 AWG, JST-GH 4/6 pin sets, DuPont, heat shrink | D35: 1 | E35: 80 | F35: =D35*E35 | G35: 1200 | H35: =D35*G35 | J35: Local / Holybro | K35: 1 wk | L35: JST-GH is the Pixhawk standard; do not improvise connectors on a flight article. | M35: —
A36: 30 | B36: Low-voltage buzzer | C36: Piezo with FC drive | D36: 1 | E36: 10 | F36: =D36*E36 | G36: 200 | H36: =D36*G36 | J36: Generic | K36: 1 wk | L36: Audible pre-arm and low-battery warning; also a lost-model locator. | M36: —
A37: AVIONICS — target 175 g
A38: 31 | B38: Flight controller | C38: Pixhawk 6C / Holybro Pix32 v6, H7, triple IMU, ArduPilot or PX4 | D38: 1 | E38: 45 | F38: =D38*E38 | G38: 28000 | H38: =D38*G38 | J38: Holybro / CUAV | K38: 3-4 wk | L38: Sizing §1: proven autopilot handles stabilisation and failsafes; the companion handles autonomy. Triple IMU matters for the vibration environment. | M38: CubeOrange+ (+30 g, +INR 25k, better isolation) · VEGA-based FC as a NIDAR indigenisation stretch goal
A39: 32 | B39: GNSS rover (RTK) | C39: u-blox ZED-F9P module, multi-band, with helical antenna | D39: 1 | E39: 55 | F39: =D39*E39 | G39: 32000 | H39: =D39*G39 | J39: Holybro H-RTK F9P / ArduSimple | K39: 4 wk | L39: Sizing §11: RTK takes geotag CEP50 from 2.54 m to 1.08 m by removing the dominant GNSS term. THIS IS THE SINGLE HIGHEST-LEVERAGE AVIONICS PURCHASE. | M39: M9N (non-RTK): CEP ~2.5 m, saves INR 27k
A40: 33 | B40: GNSS secondary (heading) | C40: Second ZED-F9P for moving-baseline yaw | D40: 1 | E40: 50 | F40: =D40*E40 | G40: 30000 | H40: =D40*G40 | J40: Holybro / ArduSimple | K40: 4 wk | L40: Sizing §11 case C: with RTK, attitude becomes a leading error term. Dual-antenna heading removes magnetometer error, which is severe near a 100 A power bus. | M40: Single GNSS + compass; accept ~1° yaw error
...

Sheet 02 Payload & Kits
A1: 02 — PAYLOAD, KITS AND GROUND-TRUTH TARGETS (fleet quantities)
A2: Fleet-level quantities, not per aircraft. Kit mass and dimensions are fixed by rule C6.
A3: # | B3: Component | C3: Specification / Part | D3: Qty | E3: Unit Mass (g) | F3: Total Mass (g) | G3: Unit Price (INR) | H3: Ext. Price (INR) | I3: Actual Mass (g) | J3: Supplier / Source | K3: Lead Time | L3: Why this part / sizing reference | M3: Alternative
A4: SURVIVOR KITS — rule C6: exactly 200 g, 200 x 100 x 50 mm rigid rectangular box
A5: 1 | B5: Kit outer box | C5: Rigid ABS/corrugated PP, 200x100x50 mm, sealed, high-visibility orange | D5: 14 | E5: 55 | F5: =D5*E5 | G5: 180 | H5: =D5*G5 | J5: Local fabricator | K5: 2 wk | L5: Rule C6 fixes the dimensions. 14 built for 12 flown (3 aircraft x 4) plus 2 spares. Sizing §10: must survive a 9.7 m/s impact. | M5: 3D-printed shell; heavier, slower to produce
A6: 2 | B6: Impact padding | C6: Closed-cell EVA foam liner, 8 mm | D6: 14 | E6: 18 | F6: =D6*E6 | G6: 60 | H6: =D6*G6 | J6: Local | K6: 1 wk | L6: Sizing §10: impact speed 9.7 m/s from a 6 m release. Foam protects contents and reduces bounce. | M6: Bubble wrap — poor repeatability
A7: 3 | B7: Kit contents | C7: Bandage roll, ORS sachets, whistle, glow stick, emergency blanket, water pouch | D7: 14 | E7: 110 | F7: =D7*E7 | G7: 220 | H7: =D7*G7 | J7: Pharmacy / local | K7: 1 wk | L7: Contents must total exactly 200 g with the box and padding. Ballast to trim to spec, then weigh each kit individually. | M7: Ballast-only dummy kits for test flying — build 20 of these
A8: 4 | B8: Trim ballast | C8: Lead/steel shot in a sealed sachet, to bring each kit to 200.0 g | D8: 14 | E8: 17 | F8: =D8*E8 | G8: 20 | H8: =D8*G8 | J8: Local | K8: 1 wk | L8: Rule C6 is exact. Weigh on a 0.1 g scale and record per kit. | M8: —
A9: 5 | B9: Test dummy kits | C9: Ballast-only boxes to the same mass and dimensions, for drop testing | D9: 24 | E9: 200 | F9: =D9*E9 | G9: 150 | H9: =D9*G9 | J9: In-house | K9: 1 wk | L9: Development Plan P8 requires ≥30 instrumented drops. Do not consume real kits in testing. | M9: Reuse real kits — risks contamination and wear
A10: GROUND-TRUTH TARGETS (for the P7 detection and P8 delivery campaigns)
A11: 6 | B11: Survivor mannequin | C11: Human-size dummy, articulable to supine/prone/seated, weather-tolerant | D11: 6 | E11: 4000 | F11: =D11*E11 | G11: 3500 | H11: =D11*G11 | J11: Local fabricator | K11: 3 wk | L11: Development Plan P7: HERIDAL/SARD targets are ~0.1% of frame area in atypical postures. You must train and test against the same. | M11: Volunteers only — cannot be left in the field between passes
A12: 7 | B12: Target clothing set | C12: Varied colour/contrast sets, incl. low-contrast earth tones | D12: 6 | E12: 400 | F12: =D12*E12 | G12: 600 | H12: =D12*G12 | J12: Local | K12: 1 wk | L12: Prevents the model from learning "bright clothing" as the detection cue. | M12: —
A13: 8 | B13: Drop-zone target mat | C13: 5 m marked concentric-ring mat with a surveyed centre | D13: 3 | E13: 2500 | F13: =D13*E13 | G13: 2500 | H13: =D13*G13 | J13: Local fabricator | K13: 2 wk | L13: Measures delivery CEP directly (Sizing §10 target: ≤3 m CEP). | M13: Chalk circles — not reusable in wind
A14: 9 | B14: Surveyed ground markers | C14: High-contrast 600 mm checkerboard/AprilTag panels, positions surveyed with RTK | D14: 12 | E14: 300 | F14: =D14*E14 | G14: 450 | H14: =D14*G14 | J14: In-house + RTK survey | K14: 1 wk | L14: Sizing §11: boresight and lever-arm calibration is SYSTEMATIC error correction — it does not average out. These markers are how you do it. | M14: None — then you cannot claim any geotag accuracy
B15: TOTAL | F15: =SUM(F5:F14) | H15: =SUM(H5:H14) | I15: =SUM(I5:I14)

Sheet 03 Ground Segment
A1: 03 — GROUND SEGMENT AND FIELD INFRASTRUCTURE
A2: One set for the whole programme. Rule C10 allows exactly one Ground Control Station.
A3: # | B3: Component | C3: Specification / Part | D3: Qty | E3: Unit Mass (g) | F3: Total Mass (g) | G3: Unit Price (INR) | H3: Ext. Price (INR) | I3: Actual Mass (g) | J3: Supplier / Source | K3: Lead Time | L3: Why this part / sizing reference | M3: Alternative
A4: GROUND CONTROL STATION
A5: 1 | B5: GCS laptop | C5: 16 GB RAM, discrete GPU, 1 TB SSD, sunlight-readable or shaded | D5: 1 | E5: 2200 | F5: =D5*E5 | G5: 110000 | H5: =D5*G5 | J5: Any | K5: 2 wk | L5: Runs the custom GCS, MAVLink router, mesh node and video decode. Rule C10 permits exactly ONE GCS. | M5: Ruggedised tablet — smaller screen hurts the C11 display requirement
A6: 2 | B6: Backup laptop | C6: Cloned image of the GCS, ready to swap | D6: 1 | E6: 2200 | F6: =D6*E6 | G6: 90000 | H6: =D6*G6 | J6: Any | K6: 2 wk | L6: A GCS failure ends the mission. Clone it and keep it powered in the field box. | M6: None — unacceptable risk
A7: 3 | B7: Sun shade / hood | C7: Laptop hood for outdoor daylight (rule C15) | D7: 1 | E7: 600 | F7: =D7*E7 | G7: 3500 | H7: =D7*G7 | J7: Generic | K7: 1 wk | L7: You cannot read a laptop screen in Indian midday sun. Judges will be watching this screen. | M7: Canopy tent shade
A8: 4 | B8: External monitor | C8: 15 in portable, for the judge/observer view | D8: 1 | E8: 900 | F8: =D8*E8 | G8: 18000 | H8: =D8*G8 | J8: Generic | K8: 2 wk | L8: Lets evaluators see the mission without crowding the operator. | M8: Screen-share to a tablet
A9: MESH GROUND NODE
A10: 5 | B10: Ground mesh node | C10: Same radio as the air nodes, in a weatherproof enclosure | D10: 1 | E10: 450 | F10: =D10*E10 | G10: 8500 | H10: =D10*G10 | J10: Generic | K10: 1-2 wk | L10: Sizing §12: 24 dBm Tx. | M10: Tier B/C to match the airborne tier
A11: 6 | B11: Sector antenna | C11: 9 dBi, 5.15-5.9 GHz, 90-120° sector, RP-SMA | D11: 2 | E11: 320 | F11: =D11*E11 | G11: 4500 | H11: =D11*G11 | J11: Generic | K11: 2 wk | L11: Sizing §12: 9 dBi at the GCS gives 33 dBm EIRP (legal) and 13.7 dB margin at 600 m. Two for spatial diversity. | M11: Omni 5 dBi: -4 dB margin
A12: 7 | B12: Antenna mast | C12: 2 m telescopic mast with tripod and guys | D12: 1 | E12: 3500 | F12: =D12*E12 | G12: 6500 | H12: =D12*G12 | J12: Generic | K12: 2 wk | L12: Sizing §12: elevating the ground antenna is the cheapest link-margin improvement available. Ground-level antennas lose 6-10 dB to clutter. | M12: Tripod only, 1.2 m
A13: 8 | B13: Low-loss coax | C13: LMR-240 or better, 3 m, RP-SMA | D13: 2 | E13: 220 | F13: =D13*E13 | G13: 1800 | H13: =D13*G13 | J13: Generic | K13: 2 wk | L13: At 5.8 GHz, cheap coax costs 1 dB/m. Keep runs short. | M13: Mount the radio at the antenna instead
A14: RTK BASE STATION — DECISION PENDING organiser confirmation (Dev Plan clarification Q1)
A15: 9 | B15: RTK base receiver | C15: u-blox ZED-F9P base kit with survey-grade antenna | D15: 1 | E15: 600 | F15: =D15*E15 | G15: 45000 | H15: =D15*G15 | J15: ArduSimple / Emlid | K15: 4 wk | L15: Sizing §11: takes geotag CEP50 from 2.54 m to 1.08 m. Corrections travel on the team local link, NOT the internet — but confirm permissibility in writing before relying on it. | M15: Emlid Reach RS3 (integrated, tripod-ready, ~INR 2.5 L)
A16: 10 | B16: Survey tripod + tribrach | C16: Fixed-height survey tripod | D16: 1 | E16: 3500 | F16: =D16*E16 | G16: 12000 | H16: =D16*G16 | J16: Survey supplier | K16: 2 wk | L16: Base position must be stable and repeatable across the test campaign. | M16: Camera tripod — insufficient rigidity
A17: 11 | B17: Base radio link | C17: 868 MHz RTCM link, base to rovers | D17: 1 | E17: 150 | F17: =D17*E17 | G17: 9500 | H17: =D17*G17 | J17: RFDesign | K17: 2-3 wk | L17: Broadcasts corrections to all three aircraft on a team-owned local link. | M17: Rebroadcast RTCM over the 5.8 GHz mesh
A18: FIELD POWER & INFRASTRUCTURE
A19: 12 | B19: Portable power station | C19: 1500-2000 Wh LiFePO4 with AC output | D19: 1 | E19: 18000 | F19: =D19*E19 | G19: 95000 | H19: =D19*G19 | J19: Generic | K19: 2 wk | L19: Charging 3 x 292 Wh packs between sorties plus GCS and instruments. A test day is 6-10 sorties. | M19: Inverter generator (noisy, fuel, but cheaper)
A20: 13 | B20: Solar panel | C20: 200 W folding, for multi-day field campaigns | D20: 1 | E20: 6000 | F20: =D20*E20 | G20: 18000 | H20: =D20*G20 | J20: Generic | K20: 2 wk | L20: Optional. Useful for remote test sites during the P7 data campaign. | M20: None
A21: 14 | B21: Field table + canopy | C21: Folding table, 3x3 m canopy, weights | D21: 1 | E21: 12000 | F21: =D21*E21 | G21: 9000 | H21: =D21*G21 | J21: Generic | K21: 1 wk | L21: Shade for the GCS and a stable surface. Also the judge-facing impression. | M21: —
A22: 15 | B22: Landing pad | C22: 3.66 x 3.66 m (12 ft) marked pad, pegged, with sequenced position markers | D22: 1 | E22: 4500 | F22: =D22*E22 | G22: 7500 | H22: =D22*G22 | J22: In-house / generic | K22: 2 wk | L22: Rule C14 fixes this size. Practise every launch and recovery on an exactly-sized pad from day one. | M22: Chalk marking — blows away, not repeatable
A23: 16 | B23: Windsock + anemometer | C23: Handheld anemometer with logging + 600 mm windsock | D23: 1 | E23: 400 | F23: =D23*E23 | G23: 4500 | H23: =D23*G23 | J23: Generic | K23: 1 wk | L23: Sizing §9.2: wind policy is constant GROUNDSPEED. You need to know the wind to verify the policy and to log conditions per sortie. | M23: Phone weather app — insufficient
A24: 17 | B24: Equipment cases | C24: Wheeled hard cases with custom foam, 3 aircraft + 1 ground kit | D24: 4 | E24: 7000 | F24: =D24*E24 | G24: 22000 | H24: =D24*G24 | J24: Pelican-type | K24: 3 wk | L24: Sizing §15: the 5-minute setup starts with getting aircraft out of cases. Foam layout is part of the setup choreography. | M24: Soft cases — slower and less protective
A25: SAFETY & COMPLIANCE
A26: 18 | B26: LiPo/Li-ion safe bags | C26: Large fire-resistant charging/storage bags | D26: 6 | E26: 300 | F26: =D26*E26 | G26: 1200 | H26: =D26*G26 | J26: Generic | K26: 1 wk | L26: Non-negotiable with 292 Wh packs in a student lab. | M26: —
A27: 19 | B27: Fire extinguisher | C27: Class D / lithium-rated, plus a bucket of dry sand | D27: 2 | E27: 5000 | F27: =D27*E27 | G27: 6500 | H27: =D27*G27 | J27: Local | K27: 1 wk | L27: Standard water/CO2 will not stop a lithium fire. | M27: —
A28: 20 | B28: First aid kit | C28: Trauma-capable, including laceration dressings | D28: 1 | E28: 1500 | F28: =D28*E28 | G28: 3500 | H28: =D28*G28 | J28: Local | K28: 1 wk | L28: 20 in carbon props at 3000 RPM cause serious injuries. Have this before the first spin-up. | M28: —
A29: 21 | B29: High-visibility vests + eye protection | C29: For the 2 setup crew and safety officer | D29: 5 | E29: 200 | F29: =D29*E29 | G29: 600 | H29: =D29*G29 | J29: Local | K29: 1 wk | L29: Range discipline. Also signals professionalism to evaluators. | M29: —
A30: 22 | B30: Safety pilot transmitter | C30: ExpressLRS/FrSky TX matched to the aircraft receivers | D30: 1 | E30: 700 | F30: =D30*E30 | G30: 18000 | H30: =D30*G30 | J30: Generic | K30: 2 wk | L30: Manual override capability during testing. Not used in the scored run. | M30: —
A31: 23 | B31: Barrier tape / cones | C31: 100 m tape, 8 cones, for range perimeter | D31: 1 | E31: 2000 | F31: =D31*E31 | G31: 1500 | H31: =D31*G31 | J31: Local | K31: 1 wk | L31: Defines the flight area at test sites and keeps spectators out of the descent cone. | M31: —
B32: TOTAL | F32: =SUM(F5:F31) | H32: =SUM(H5:H31) | I32: =SUM(I5:I31)

Sheet 04 Test & Lab Equipment
A1: 04 — TEST, LAB AND CALIBRATION EQUIPMENT
A2: Capital equipment for the programme. Several items directly retire assumptions listed in Sizing §16.
A3: # | B3: Component | C3: Specification / Part | D3: Qty | E3: Unit Mass (g) | F3: Total Mass (g) | G3: Unit Price (INR) | H3: Ext. Price (INR) | I3: Actual Mass (g) | J3: Supplier / Source | K3: Lead Time | L3: Why this part / sizing reference | M3: Alternative
A4: PROPULSION AND POWER CHARACTERISATION — closes assumptions A1, A2, A4, A5 in Sizing §16
A5: 1 | B5: Thrust stand | C5: RCbenchmark Series 1585 or equivalent, to 5 kgf, with torque and RPM | D5: 1 | E5: 3000 | F5: =D5*E5 | G5: 145000 | H5: =D5*G5 | J5: RCbenchmark / Tyto | K5: 4-6 wk | L5: Sizing §16 A1: figure of merit is assumed 0.60 and is the single largest uncertainty in the power model (±0.1 → ∓17% hover power). This instrument replaces the assumption with data. | M5: Load cell + Arduino DIY rig: ~INR 15k, much lower fidelity
A6: 2 | B6: Power analyser | C6: 130 A inline watt meter with logging | D6: 2 | E6: 180 | F6: =D6*E6 | G6: 4500 | H6: =D6*G6 | J6: Turnigy / Mauch | K6: 2 wk | L6: Measures real hover current against the 36 A predicted (Sizing §6). | M6: FC current telemetry — less accurate
A7: 3 | B7: Battery charger | C7: iCharger X8 or Junsi, 8S, 1000 W, with parallel board | D7: 2 | E7: 1200 | F7: =D7*E7 | G7: 32000 | H7: =D7*G7 | J7: Junsi / iCharger | K7: 3 wk | L7: 292 Wh pack at 1C needs ~300 W. Two chargers to keep a test day moving. | M7: Cheaper 200 W charger doubles turnaround
A8: 4 | B8: Charger PSU | C8: 24 V 40 A server PSU or bench supply | D8: 2 | E8: 1500 | F8: =D8*E8 | G8: 9000 | H8: =D8*G8 | J8: Generic | K8: 2 wk | L8: Feeds the chargers at full rated power. | M8: —
A9: 5 | B9: Cell tester | C9: 21700 capacity/IR tester, 8-bay | D9: 1 | E9: 900 | F9: =D9*E9 | G9: 14000 | H9: =D9*G9 | J9: Generic | K9: 2-3 wk | L9: Every cell must be capacity- and IR-matched before pack assembly. Counterfeit 21700s are widespread; this is how you catch them. | M9: Trust the vendor — do not
A10: 6 | B10: Spot welder | C10: Battery spot welder, 21700-capable, with nickel strip electrodes | D10: 1 | E10: 3500 | F10: =D10*E10 | G10: 18000 | H10: =D10*G10 | J10: Generic | K10: 2-3 wk | L10: Soldering directly to cells damages them. Spot welding is the correct method. | M10: Buy pre-built packs; less control over quality
A11: MEASUREMENT AND CALIBRATION
A12: 7 | B12: Precision scale | C12: 0.1 g resolution, 5 kg capacity | D12: 1 | E12: 2000 | F12: =D12*E12 | G12: 6500 | H12: =D12*G12 | J12: Generic | K12: 1 wk | L12: Every part weighed on arrival. Kits trimmed to exactly 200 g (rule C6). | M12: —
A13: 8 | B13: Hanging scale | C13: Calibrated, 50 kg, 10 g resolution — for the FLEET WEIGH-IN | D13: 1 | E13: 400 | F13: =D13*E13 | G13: 4500 | H13: =D13*G13 | J13: Generic | K13: 1 wk | L13: Rule C2 is a pass/fail check at 25 kg. Own a calibrated scale; do not discover a discrepancy at the venue. | M13: Bathroom scale — insufficient resolution
A14: 9 | B14: Digital calipers + micrometer | C14: 150 mm digital calipers, 0-25 mm micrometer | D14: 2 | E14: 300 | F14: =D14*E14 | G14: 3500 | H14: =D14*G14 | J14: Mitutoyo / generic | K14: 1 wk | L14: CF tube OD/ID verification, fastener checks. | M14: —
A15: 10 | B15: Torque driver | C15: 1-6 N·m adjustable, hex/Torx bits | D15: 1 | E15: 400 | F15: =D15*E15 | G15: 7500 | H15: =D15*G15 | J15: Wera / generic | K15: 2 wk | L15: Motor and arm-clamp bolts must be torqued to spec, not to feel. Under-torqued clamps creep; over-torqued crush CF. | M15: —
A16: 11 | B16: Propeller balancer | C16: Magnetic prop balancer for 18 in props | D16: 1 | E16: 600 | F16: =D16*E16 | G16: 3500 | H16: =D16*G16 | J16: Du-Bro / generic | K16: 2 wk | L16: Sizing §13: vibration fatigue is the real structural driver, and unbalanced props are the main source. | M16: —
A17: 12 | B17: Vibration analysis | C17: Use the FC IMU logs (free) + a USB accelerometer if needed | D17: 1 | E17: 50 | F17: =D17*E17 | G17: 8500 | H17: =D17*G17 | J17: Generic | K17: 2 wk | L17: ArduPilot/PX4 FFT logging is usually sufficient. Buy only if the notch tuning stalls. | M17: FC logs only
A18: 13 | B18: Camera calibration target | C18: A2 checkerboard on rigid flat board + AprilTag set | D18: 1 | E18: 900 | F18: =D18*E18 | G18: 3500 | H18: =D18*G18 | J18: Print + mount | K18: 1 wk | L18: Sizing §11: intrinsic calibration AND boresight extrinsic calibration. Skipping the second one leaves a 3-5 m systematic geotag bias. | M18: Printed on paper — flatness error corrupts the calibration
A19: BENCH AND FABRICATION
A20: 14 | B20: Soldering station | C20: Temperature-controlled 80-100 W, with a large chisel tip for 10 AWG | D20: 1 | E20: 2500 | F20: =D20*E20 | G20: 12000 | H20: =D20*G20 | J20: Hakko / generic | K20: 2 wk | L20: 10 AWG to XT90 needs real thermal mass. A 30 W iron will produce cold joints and in-flight failures. | M20: —
A21: 15 | B21: Hot air rework station | C21: For heat shrink and SMD work | D21: 1 | E21: 3000 | F21: =D21*E21 | G21: 7500 | H21: =D21*G21 | J21: Generic | K21: 2 wk | L21: — | M21: Heat gun
A22: 16 | B22: Bench power supply | C22: 0-30 V 10 A, current-limited | D22: 1 | E22: 4000 | F22: =D22*E22 | G22: 9500 | H22: =D22*G22 | J22: Generic | K22: 2 wk | L22: Bring up new boards current-limited. Saves at least one Jetson. | M22: —
A23: 17 | B23: Multimeter | C23: True-RMS with continuity, 10 A range | D23: 2 | E23: 350 | F23: =D23*E23 | G23: 4500 | H23: =D23*G23 | J23: Fluke / generic | K23: 1 wk | L23: — | M23: —
A24: 18 | B24: 3D printer | C24: FDM, 250 mm bed, PETG/ASA capable | D24: 1 | E24: 12000 | F24: =D24*E24 | G24: 55000 | H24: =D24*G24 | J24: Bambu / Creality | K24: 3 wk | L24: Canopy, magazine, ducts, jigs, and dozens of iterations of the release mechanism. Owning one is faster than outsourcing. | M24: Outsource printing; slower iteration
A25: 19 | B25: Hand tool set | C25: Hex drivers, Torx, pliers, wire strippers, flush cutters, tweezers | D25: 1 | E25: 2500 | F25: =D25*E25 | G25: 9000 | H25: =D25*G25 | J25: Wera / generic | K25: 1 wk | L25: — | M25: —
A26: 20 | B26: Rotary tool + CF cutting | C26: Dremel with diamond discs, plus dust extraction and P2 masks | D26: 1 | E26: 1800 | F26: =D26*E26 | G26: 9500 | H26: =D26*G26 | J26: Generic | K26: 2 wk | L26: CARBON DUST IS A RESPIRATORY AND ELECTRICAL HAZARD. Extraction and masks are not optional, and CF dust shorts electronics. | M26: Outsource all CF cutting
A27: SIMULATION AND DEVELOPMENT
A28: 21 | B28: Dev workstation / GPU | C28: RTX 4070-class or better, 32 GB RAM — for model training and SITL | D28: 1 | E28: 0 | F28: =D28*E28 | G28: 180000 | H28: =D28*G28 | J28: Any | K28: 3 wk | L28: Development Plan P4/P7: 200-run Monte Carlo campaigns and detector training. Cloud GPU is an alternative but the P7 dataset iteration loop is faster locally. | M28: Cloud GPU rental (~INR 60/hr)
A29: 22 | B29: Network switch + cabling | C29: 8-port gigabit switch, patch cables | D29: 1 | E29: 600 | F29: =D29*E29 | G29: 3500 | H29: =D29*G29 | J29: Generic | K29: 1 wk | L29: Multi-machine SITL and mesh bench testing. | M29: —
B30: TOTAL | F30: =SUM(F5:F29) | H30: =SUM(H5:H29) | I30: =SUM(I5:I29)

Sheet 05 Spares & Consumables
A1: 05 — SPARES AND CONSUMABLES
A2: The spare aircraft line is the largest discretionary item; treat it as a risk-buy-down decision, not a nice-to-have.
A3: # | B3: Component | C3: Specification / Part | D3: Qty | E3: Unit Mass (g) | F3: Total Mass (g) | G3: Unit Price (INR) | H3: Ext. Price (INR) | I3: Actual Mass (g) | J3: Supplier / Source | K3: Lead Time | L3: Why this part / sizing reference | M3: Alternative
A4: FLIGHT SPARES — Development Plan R4: a crash near the finals must not end the programme
A5: 1 | B5: Spare motor | C5: MN5008 KV170 | D5: 4 | E5: 135 | F5: =D5*E5 | G5: 9500 | H5: =D5*G5 | J5: T-Motor | K5: 4-6 wk | L5: One full aircraft set. Motors are the longest-lead flight-critical item. | M5: —
A6: 2 | B6: Spare ESC | C6: 60 A 6-12S | D6: 4 | E6: 45 | F6: =D6*E6 | G6: 3500 | H6: =D6*G6 | J6: Generic | K6: 3-4 wk | L6: ESCs fail from vibration and heat; a spare set is the minimum. | M6: —
A7: 3 | B7: Spare propeller pairs | C7: 18x6.1 CF folding CW/CCW | D7: 6 | E7: 116 | F7: =D7*E7 | G7: 2800 | H7: =D7*G7 | J7: T-Motor | K7: 4 wk | L7: Props are consumed by every hard landing. Six pairs is a realistic season. | M7: —
A8: 4 | B8: Spare arm assembly | C8: Tube + clamp + motor mount, built up | D8: 4 | E8: 162 | F8: =D8*E8 | G8: 2550 | H8: =D8*G8 | J8: In-house | K8: 2 wk | L8: Arms are what break in a tip-over. Pre-build them so a field repair is a 10-minute swap. | M8: —
A9: 5 | B9: Spare flight controller | C9: Pixhawk 6C, pre-flashed and pre-configured | D9: 1 | E9: 45 | F9: =D9*E9 | G9: 28000 | H9: =D9*G9 | J9: Holybro | K9: 3-4 wk | L9: Pre-loaded with the frozen parameter set (Development Plan P10). | M9: —
A10: 6 | B10: Spare GNSS rover | C10: ZED-F9P with antenna | D10: 1 | E10: 90 | F10: =D10*E10 | G10: 32000 | H10: =D10*G10 | J10: Holybro | K10: 4 wk | L10: — | M10: Fly with M9N as a degraded fallback
A11: 7 | B11: Spare companion computer | C11: Jetson Orin Nano, imaged and with the TensorRT engine pre-built | D11: 1 | E11: 185 | F11: =D11*E11 | G11: 52000 | H11: =D11*G11 | J11: NVIDIA | K11: 4-8 wk | L11: Sizing §15: never JIT-build a TensorRT engine at boot. The spare must be imaged and warm-cached too. | M11: —
A12: 8 | B12: Spare camera + lens | C12: IMX477 + 6 mm lens, boresight-calibrated on a spare mount | D12: 1 | E12: 100 | F12: =D12*E12 | G12: 11800 | H12: =D12*G12 | J12: Arducam | K12: 2-3 wk | L12: Note: swapping the camera invalidates the boresight calibration. Calibrate the spare in advance. | M12: —
A13: 9 | B13: Spare battery pack | C13: Complete 6S3P pack | D13: 3 | E13: 1449 | F13: =D13*E13 | G13: 22000 | H13: =D13*G13 | J13: In-house build | K13: 4 wk | L13: Two packs per aircraft minimum so a test day is not charger-limited; the third is the crash reserve. | M13: —
A14: 10 | B14: COMPLETE SPARE AIRCRAFT | C14: Fourth airframe, fully built and flight-tested | D14: 1 | E14: 5710 | F14: =D14*E14 | G14: 185000 | H14: =D14*G14 | J14: In-house | K14: 8 wk | L14: STRONGLY RECOMMENDED. Rule C1 needs only 2 aircraft flying, but a pre-flight failure on finals day with no spare means flying 2 and losing coverage. Budget-dependent. | M14: Rely on component spares only
A15: CONSUMABLES
A16: 11 | B16: Threadlocker | C16: Loctite 243 (medium), 50 ml | D16: 2 | E16: 50 | F16: =D16*E16 | G16: 900 | H16: =D16*G16 | J16: Local | K16: 1 wk | L16: Every fastener on a vibrating airframe. Use medium strength so field disassembly is possible. | M16: —
A17: 12 | B17: Cyanoacrylate + epoxy | C17: CA thin/thick, 30-min structural epoxy | D17: 1 | E17: 400 | F17: =D17*E17 | G17: 1800 | H17: =D17*G17 | J17: Local | K17: 1 wk | L17: — | M17: —
A18: 13 | B18: Heat shrink assortment | C18: 2-20 mm, adhesive-lined | D18: 1 | E18: 200 | F18: =D18*E18 | G18: 900 | H18: =D18*G18 | J18: Local | K18: 1 wk | L18: — | M18: —
A19: 14 | B19: Zip ties + lacing cord | C19: Assorted, plus Kevlar lacing for harness routing | D19: 1 | E19: 300 | F19: =D19*E19 | G19: 700 | H19: =D19*G19 | J19: Local | K19: 1 wk | L19: — | M19: —
A20: 15 | B20: Kapton + fibreglass tape | C20: 25 mm rolls | D20: 1 | E20: 120 | F20: =D20*E20 | G20: 800 | H20: =D20*G20 | J20: Local | K20: 1 wk | L20: Cell insulation and heat-resistant wrapping. | M20: —
A21: 16 | B21: 3M VHB tape | C21: 19 mm x 5 m, and foam mounting tape | D21: 1 | E21: 150 | F21: =D21*E21 | G21: 1200 | H21: =D21*G21 | J21: Local | K21: 1 wk | L21: — | M21: —
A22: 17 | B22: Solder + flux | C22: Leaded 60/40 1 mm, no-clean flux, desoldering braid | D22: 1 | E22: 500 | F22: =D22*E22 | G22: 1800 | H22: =D22*G22 | J22: Local | K22: 1 wk | L22: Leaded solder is easier and more reliable for hand-built flight hardware. | M22: Lead-free if institutionally required
A23: 18 | B23: 3D printer filament | C23: PETG 3 kg, ASA 1 kg, TPU 1 kg | D23: 1 | E23: 5000 | F23: =D23*E23 | G23: 9000 | H23: =D23*G23 | J23: Generic | K23: 2 wk | L23: Magazine and canopy iterations consume more than you expect. | M23: —
A24: 19 | B24: Carbon plate stock | C24: 2.5 mm and 3 mm 3K twill sheets, 400x500 mm | D24: 2 | E24: 900 | F24: =D24*E24 | G24: 7500 | H24: =D24*G24 | J24: CF supplier | K24: 3 wk | L24: For plate re-cuts and repair doublers. | M24: —
A25: 20 | B25: Velcro + battery straps | C25: Hook-loop, 50 mm, plus spare straps | D25: 1 | E25: 250 | F25: =D25*E25 | G25: 800 | H25: =D25*G25 | J25: Local | K25: 1 wk | L25: — | M25: —
A26: 21 | B26: Nitrile gloves + P2 masks | C26: Box of 100 + 20 masks | D26: 1 | E26: 600 | F26: =D26*E26 | G26: 1800 | H26: =D26*G26 | J26: Local | K26: 1 wk | L26: CF machining and epoxy work. | M26: —
A27: 22 | B27: Cleaning supplies | C27: IPA 1 L, lint-free wipes, compressed air | D27: 1 | E27: 1200 | F27: =D27*E27 | G27: 1500 | H27: =D27*G27 | J27: Local | K27: 1 wk | L27: Camera lens and connector cleaning; CF dust removal. | M27: —
B28: TOTAL | F28: =SUM(F5:F27) | H28: =SUM(H5:H27) | I28: =SUM(I5:I27)

Sheet 06 Software & Data
A1: 06 — SOFTWARE, DATA AND COMPLIANCE
A2: Mostly zero-cost, listed so nothing is forgotten. Two items are frequently missed and cost points: offline map tiles, and ETA status of radios.
A3: # | B3: Component | C3: Specification / Part | D3: Qty | E3: Unit Mass (g) | F3: Total Mass (g) | G3: Unit Price (INR) | H3: Ext. Price (INR) | I3: Actual Mass (g) | J3: Supplier / Source | K3: Lead Time | L3: Why this part / sizing reference | M3: Alternative
A4: FLIGHT AND AUTONOMY STACK — all open source
A5: 1 | B5: Autopilot firmware | C5: ArduPilot Copter 4.5+ or PX4 v1.15+ | D5: 1 | E5: 0 | F5: =D5*E5 | G5: 0 | H5: =D5*G5 | J5: ardupilot.org / px4.io | K5: — | L5: Sizing §1: proven stabilisation and failsafes. Choose one and standardise the whole fleet on it. | M5: —
A6: 2 | B6: Middleware | C6: ROS 2 Humble/Jazzy with Fast DDS | D6: 1 | E6: 0 | F6: =D6*E6 | G6: 0 | H6: =D6*G6 | J6: ros.org | K6: — | L6: Sizing: DDS discovery and QoS map well to a lossy mobile mesh. | M6: MAVSDK only — simpler, less capable
A7: 3 | B7: MAVLink bridge | C7: MAVROS or uXRCE-DDS | D7: 1 | E7: 0 | F7: =D7*E7 | G7: 0 | H7: =D7*G7 | J7: GitHub | K7: — | L7: FC to companion link. | M7: —
A8: 4 | B8: MAVLink router | C8: mavlink-router or MAVProxy | D8: 1 | E8: 0 | F8: =D8*E8 | G8: 0 | H8: =D8*G8 | J8: GitHub | K8: — | L8: Rule C10: multiplexes 3 unique SYSIDs into ONE ground station process. | M8: —
A9: 5 | B9: Mesh routing | C9: batman-adv (Linux kernel module) on OpenWrt or Ubuntu | D9: 1 | E9: 0 | F9: =D9*E9 | G9: 0 | H9: =D9*G9 | J9: open-mesh.org | K9: — | L9: Layer-2 mesh; the same technology commercial MANET radios run underneath. | M9: OLSR, Babel
A10: 6 | B10: Simulator | C10: Gazebo Harmonic + ArduPilot/PX4 SITL | D10: 1 | E10: 0 | F10: =D10*E10 | G10: 0 | H10: =D10*G10 | J10: gazebosim.org | K10: — | L10: Development Plan P4: 200-run Monte Carlo campaigns before any hardware flies. | M10: jMAVSim (lighter, less realistic)
A11: 7 | B11: Coverage planner | C11: DARP reference implementation (github.com/athakapo/DARP) | D11: 1 | E11: 0 | F11: =D11*E11 | G11: 0 | H11: =D11*G11 | J11: GitHub | K11: — | L11: Sizing/Plan §2.3: equal-area partitioning anchored to a common launch point. | M11: Write your own boustrophedon decomposition
A12: 8 | B12: Task allocation | C12: CBBA reference implementation | D12: 1 | E12: 0 | F12: =D12*E12 | G12: 0 | H12: =D12*G12 | J12: GitHub | K12: — | L12: Plan §2.4: Choi, Brunet & How (2009), provable conflict-free convergence. | M12: Centralised Hungarian assignment — fails on link loss
A13: PERCEPTION
A14: 9 | B14: Detector framework | C14: Ultralytics YOLO (AGPL — check licence terms for competition use) | D14: 1 | E14: 0 | F14: =D14*E14 | G14: 0 | H14: =D14*G14 | J14: ultralytics.com | K14: — | L14: Sizing §8.2. NOTE: AGPL has implications if you distribute. Verify against NIDAR IP terms. | M14: MMDetection (Apache 2.0), YOLOX
A15: 10 | B15: Inference runtime | C15: TensorRT + DeepStream (included with JetPack) | D15: 1 | E15: 0 | F15: =D15*E15 | G15: 0 | H15: =D15*G15 | J15: NVIDIA | K15: — | L15: Sizing §8.2: FP16 TensorRT is what gets you 24-40 FPS on an Orin Nano. | M15: ONNX Runtime — slower
A16: 11 | B16: Tiled inference | C16: SAHI (Akyon et al., ICIP 2022) | D16: 1 | E16: 0 | F16: =D16*E16 | G16: 0 | H16: =D16*G16 | J16: GitHub | K16: — | L16: Sizing §8.2: recovers small-object recall that whole-frame resizing destroys. | M16: Custom tiling loop
A17: 12 | B17: Annotation tool | C17: CVAT (self-hosted) or Roboflow | D17: 1 | E17: 0 | F17: =D17*E17 | G17: 0 | H17: =D17*G17 | J17: cvat.ai | K17: — | L17: Development Plan P7: ≥2,000 frames of your own field data. Self-host to avoid per-seat costs. | M17: LabelImg — no team workflow
A18: 13 | B18: Public datasets | C18: HERIDAL, SARD, WiSARD | D18: 1 | E18: 0 | F18: =D18*E18 | G18: 0 | H18: =D18*G18 | J18: Research groups (request access) | K18: 2-4 wk | L18: Sizing §8: baseline benchmarks. Reproduce published metrics (YOLOv5L: P 0.90 / R 0.89 on HERIDAL) to validate your pipeline before trusting your own data. | M18: COCO-pretrained only — will fail on supine targets
A19: 14 | B19: Camera calibration | C19: OpenCV / Kalibr | D19: 1 | E19: 0 | F19: =D19*E19 | G19: 0 | H19: =D19*G19 | J19: opencv.org | K19: — | L19: Sizing §11: intrinsics AND the camera-to-body boresight extrinsic. | M19: —
A20: GROUND STATION AND TOOLING
A21: 15 | B21: GCS framework | C21: React + Node/Python back-end (custom build) | D21: 1 | E21: 0 | F21: =D21*E21 | G21: 0 | H21: =D21*G21 | J21: In-house | K21: ~6 wk eng | L21: Plan §2.11: the rule C11 display set does not exist in stock Mission Planner or QGroundControl. Budget it as a real subsystem. | M21: QGroundControl + custom side panel
A22: 16 | B22: Map tiles | C22: Offline tile pack for the venue and test sites | D22: 1 | E22: 0 | F22: =D22*E22 | G22: 0 | H22: =D22*G22 | J22: OSM / QGIS export | K22: 1 wk | L22: RULE C12 FORBIDS INTERNET. Online map tiles will not load at the venue. Cache offline tiles in advance — teams lose points to this every year. | M22: No basemap — badly degrades the C11 display
A23: 17 | B23: Version control + CI | C23: Git, self-hosted runner | D23: 1 | E23: 0 | F23: =D23*E23 | G23: 0 | H23: =D23*G23 | J23: GitHub / GitLab | K23: — | L23: Plan §1.5: every flight runs a tagged commit. | M23: —
A24: 18 | B24: Containerisation | C24: Docker with an arm64 build for the Jetson | D24: 1 | E24: 0 | F24: =D24*E24 | G24: 0 | H24: =D24*G24 | J24: docker.com | K24: — | L24: Deploy the identical container to SITL and to the aircraft. | M24: Bare-metal installs — drift between machines
A25: REGULATORY AND ADMIN
A26: 19 | B26: DGCA compliance | C26: Airspace zone check for every test site; operator/pilot requirements | D26: 1 | E26: 0 | F26: =D26*E26 | G26: 0 | H26: =D26*G26 | J26: Digital Sky | K26: 2-4 wk | L26: Development Plan P0 exit gate. Confirm the zone colour for each site BEFORE booking a test campaign. | M26: —
A27: 20 | B27: WPC / ETA verification | C27: Equipment Type Approval status for every radio flown | D27: 1 | E27: 0 | F27: =D27*E27 | G27: 0 | H27: =D27*G27 | J27: WPC / vendor | K27: 4-8 wk | L27: Sizing §12: 5.825-5.875 GHz is delicensed for drones and 865-867 MHz for SRDs, but the EQUIPMENT still needs ETA. Check before purchase, not after. | M27: —
A28: 21 | B28: Insurance | C28: Third-party liability for flight operations | D28: 1 | E28: 0 | F28: =D28*E28 | G28: 0 | H28: =D28*G28 | J28: Insurer | K28: 3 wk | L28: Many test sites and institutions require it. | M28: —
B29: TOTAL | F29: =SUM(F5:F28) | H29: =SUM(H5:H28) | I29: =SUM(I5:I28)

Sheet 07 Mass Rollup
A1: 07 — MASS ROLLUP AND RULE C2 COMPLIANCE CHECK
A2: Rule C2: the COMBINED all-up weight of all deployed drones, including batteries, payloads and every accessory, must not exceed 25 kg.
A4: # | B4: Group | C4: Sizing model (g) | D4: BOM estimate (g) | E4: Actual measured (g) | F4: Delta vs model | G4: Note
A5: 1 | B5: Structure | C5: 1187 | D5: 1187 | F5: =IF(E5="","",E5-C5) | G5: 01 Air Vehicle BOM structure section
A6: 2 | B6: Propulsion (motors, ESCs, props, hubs) | C6: 934 | D6: 934 | F6: =IF(E6="","",E6-C6) | G6: MN5008 135 g x4 + ESC 45 g x4 + props 116 g x2 pr + hubs
A7: 3 | B7: Power (pack + distribution) | C7: 1724 | D7: 1724 | F7: =IF(E7="","",E7-C7) | G7: 6S3P pack 1449 g + PDB/BEC/wire/connectors 275 g
A8: 4 | B8: Avionics | C8: 217 | D8: 217 | F8: =IF(E8="","",E8-C8) | G8: FC, 2x F9P, antennas, RX, safety switch, SD
A9: 5 | B9: Compute & perception | C9: 444 | D9: 444 | F9: =IF(E9="","",E9-C9) | G9: Orin Nano 185 g, camera+lens+mount, SSD, cooler, cables
A10: 6 | B10: Communications | C10: 119 | D10: 119 | F10: =IF(E10="","",E10-C10) | G10: Mesh card + antennas + pigtails + 868 MHz radio
A11: 7 | B11: Payload mechanism | C11: 240 | D11: 240 | F11: =IF(E11="","",E11-C11) | G11: Magazine, 4 servos, detents, switches, harness
A12: 8 | B12: Survivor kits (4 x 200 g) | C12: 800 | D12: 800 | F12: =IF(E12="","",E12-C12) | G12: Rule C6 fixes this at exactly 200 g per kit
B14: MTOW per aircraft (g) | D14: =SUM(D5:D12)
B15: Bottom-up line-item total, tab 01 (g) | D15: ='01 Air Vehicle BOM'!F69 | G15: Sum of every line on tab 01. Differs from the group rollup above because group figures are the sizing-model allocations, not the summed parts.
B16: Reconciliation delta (g) | D16: =D15-D14 | G16: Investigate anything beyond +/-5%. Track the bottom-up number once parts arrive.
B17: Aircraft in fleet | D17: =3
B18: FLEET ALL-UP WEIGHT (g) | D18: =D14*D17
B19: Rule C2 limit (g) | D19: =25000
B20: Team working target (g) | D20: =24000
B21: Margin to rule limit (g) | D21: =D19-D18
B22: Margin to rule limit (%) | D22: =(D19-D18)/D19
B23: Build overweight tolerated before hitting target | D23: =D20/D18-1
B25: PERFORMANCE AT THIS MASS (recomputed from the sizing model)
B26: Hover electrical power (W) | D26: 784 | G26: Momentum theory, FM 0.60, 18 in props, rho 1.150
B27: Pack usable energy (Wh, 80% DoD) | D27: 234 | G27: 292 Wh x 0.80
B28: Hover endurance (min) | D28: 17.9 | G28: Usable energy / hover power
B29: Design mission duration (min) | D29: 7.7 | G29: Sizing §9.1 segment budget
B30: Endurance ratio | D30: 2.3 | G30: Target >= 2.0 per the reserve policy
B31: Mission energy (Wh) | D31: 101 | G31: Scaled from the 5.05 kg case by (m/m0)^1.5
B32: State of charge at landing (%) | D32: 65 | G32: 1 - mission energy / pack energy
B33: Hover current (A) | D33: 36.3 | G33: 784 W / 21.6 V
B34: Peak current at T/W=2 (A) | D34: 98 | G34: P ~ T^1.5, so peak power is 2.7x hover
B35: Pack burst capability (A) | D35: 135 | G35: 3P x 45 A (Molicel P45B)
B36: Current margin (%) | D36: 38 | G36: Pack burst vs peak demand
B37: Max thrust-to-weight | D37: 2.87 | G37: 4 x 4.1 kgf / 5.71 kg
B38: Hover throttle point (% of max thrust) | D38: 35 | G38: Below the ideal 45-55% band — over-motored, accepted for wind headroom
B40: REVISIONS FROM THE SIZING REPORT (hardware-forced)
B41: 1. Props 20 in -> 18x6.1. The MN5008 KV170 is rated for 17-18 in. Hover power rises 605 -> 666 W at the old mass.
B42: 2. Pack 6S2P -> 6S3P. 6S2P left only 9% current margin at peak thrust; 6S3P gives 38% and lifts the endurance ratio from 1.8x to 2.3x.
B43: 3. MTOW 5.05 -> 5.71 kg; fleet 15.16 -> 17.12 kg. Margin under the 25 kg rule falls from 39% to 32%. Still ample.
B44: 4. The motor is over-sized for the requirement (hover at 35% of max, not the ideal 45-55%). Accepted: T/W 2.87 buys wind and recovery authority, and the mass margin pays for it.

Sheet 08 Cost Summary
A1: 08 — PROGRAMME COST SUMMARY
A2: Indicative budgetary estimates in INR. Not quotations. Re-price at the Phase 1 procurement gate.
A4: # | B4: Category | C4: Qty / Sets | D4: Unit Cost (INR) | E4: Extended (INR) | F4: Note
A5: 1 | B5: Air vehicle, per aircraft | C5: 3 | D5: ='01 Air Vehicle BOM'!H69 | E5: =C5*D5 | F5: Flight hardware only. See tab 01.
A6: 2 | B6: Payload, kits and ground-truth targets | C6: 1 | D6: ='02 Payload & Kits'!H15 | E6: =C6*D6 | F6: Fleet quantities. See tab 02.
A7: 3 | B7: Ground segment and field infrastructure | C7: 1 | D7: ='03 Ground Segment'!H32 | E7: =C7*D7 | F7: One set. See tab 03.
A8: 4 | B8: Test, lab and calibration equipment | C8: 1 | D8: ='04 Test & Lab Equipment'!H30 | E8: =C8*D8 | F8: Capital equipment. See tab 04.
A9: 5 | B9: Spares and consumables | C9: 1 | D9: ='05 Spares & Consumables'!H28 | E9: =C9*D9 | F9: Includes the optional 4th aircraft. See tab 05.
A10: 6 | B10: Software, data and compliance | C10: 1 | D10: ='06 Software & Data'!H29 | E10: =C10*D10 | F10: Near zero — open-source stack.
B12: SUBTOTAL — hardware and equipment | E12: =SUM(E5:E10)
B13: Customs duty + freight on imported items | E13: =E12*0.22 | F13: Assumed 22% blended on the ~60% of spend that is imported (motors, F9P, Jetson, T-Motor props, thrust stand). Refine per HSN code.
B14: GST | E14: =(E12+E13)*0.18 | F14: 18% assumed. Institutional purchases may be exempt — check.
B15: Contingency | E15: =(E12+E13+E14)*0.2 | F15: 20%. Hardware programmes with student build quality consume it: crashes, magic smoke, re-spins of the release mechanism.
B16: TOTAL PROGRAMME COST | E16: =E12+E13+E14+E15
B18: LEAN CONFIGURATION (same mission capability, reduced margin)
B19: Deduct: 4th spare aircraft | E19: -185000
B20: Deduct: RTK base station kit | E20: -66500
B21: Deduct: 3x RTK rover + heading GNSS, revert to M9N | E21: -165000
B22: Deduct: instrumented thrust stand, use a DIY load-cell rig | E22: -130000
B23: Deduct: dev workstation, use existing lab GPU + cloud | E23: -180000
B24: Deduct: backup GCS laptop, use a team member machine | E24: -90000
B25: Deduct: solar panel | E25: -18000
B26: LEAN SUBTOTAL | E26: =E12+SUM(E19:E25)
B27: LEAN TOTAL (with duty, GST, contingency) | E27: =E26*1.22*1.18*1.2 | F27: Accepts: no spare airframe (R4 exposure), geotag CEP ~2.5 m instead of ~1.1 m, and figure of merit stays an assumption instead of a measurement.
B29: COST REDUCTION LEVERS (if the budget is constrained)
B30: 1. Drop the spare aircraft (~INR 1.85 L). Highest saving, highest risk. Keep component spares.
B31: 2. Drop the RTK base and rovers (~INR 1.1 L). Geotag CEP goes 1.1 m -> 2.5 m. Acceptable if the rulebook tolerance is >=5 m.
B32: 3. Build a DIY load-cell thrust stand instead of an RCbenchmark (~INR 1.3 L saved). Lower fidelity on the FM assumption, which is the biggest uncertainty in the power model.
B33: 4. Use an existing lab GPU workstation and cloud training instead of buying one (~INR 1.8 L).
B34: 5. Mesh Tier A (commodity 802.11 + batman-adv) is already the cheapest option — do not downgrade further; the link is mission-critical.
B35: DO NOT CUT: the safety equipment, the calibrated weigh-in scale, the calibration targets, or the field data campaign.
