Workbook

Sheet 00 README
B2: RescueSwarm — Verified All-Indian Bill of Materials
B3: NIDAR 2.0 Track 1 · exact part numbers, verified specifications, live supplier links
B5: WHAT CHANGED | C5: The previous BOM named suppliers. This one names PARTS. Every flight-critical line now carries an exact model number, the specification as published by the manufacturer, a clickable product link, and a Status flag saying how far the verification went.
B6: STATUS FLAGS | C6: VERIFIED = model number, specification and price confirmed from the manufacturer or an authorised Indian reseller. SPEC OK / RFQ = the part and its specification are confirmed, but price is quotation-driven. RFQ = supplier confirmed, exact part still to be selected with them. LOCAL = fabricated or bought locally, no catalogue part exists.
B7: THE BIG FIND — REFLEX DRIVE | C7: Reflex Drive (Sunmint Energy Pvt Ltd, Lucknow, UP) makes a complete Made-in-India propulsion set that fits this aircraft: the RD MI-5008 KV340 motor (135 g, IP34, rated for 15-18 in props), the RD A-Series 60 A FOC ESC (28 g, 2 kW peak), and the RD 1760 propeller (17 x 6.0 in, 40 g, nylon-carbon 38% CF). They publish a full bench-test table. That table is the reason the design point moved to 17 in props.
B8: DESIGN POINT (REVISED TO FIT REAL INDIAN PARTS) | C8: Quad · RD 1760 (17 x 6.0 in) props · RD MI-5008 KV340 · RD A-Series 60 A FOC ESC · 6S3P 21700. MTOW 5.52 kg · FLEET 16.57 kg vs the 25 kg cap = 34% MARGIN · hover 790 W · endurance 17.7 min vs a 7.7 min design mission (2.3x) · hover thrust 1381 g/motor = 33% of the 4200 g rating · peak 99 A vs 135 A pack capability (37% margin).
B9: MODEL VALIDATED AGAINST REAL BENCH DATA | C9: Reflex Drive publishes measured thrust for the RD-5008 370KV on a 1760 prop at 6S: 1187 g at 126 W, 1864 g at 251 W. Interpolating to our 1381 g hover point gives ~162 W per motor = ~650 W plus 55 W avionics = ~705 W. The momentum-theory model predicts 790 W — 12% conservative. Real endurance should therefore be closer to 19-20 min than 17.7. This is the first time in this programme a prediction has been checked against manufacturer bench data, and it held.
B10: PRICES | C10: Where Status = VERIFIED the price is a real listed Indian price including GST where stated (e.g. Agam Autopilot V6X-RT Full Set at INR 42,000 incl. 5% GST). Elsewhere they remain estimates. Prices move; re-check before ordering.
B11: HOW TO USE | C11: Click "open" in the Link column to go to the product page. Filter on Status to see what still needs an RFQ. Fill the Actual columns as parts arrive. Tab 07 checks the fleet against the 25 kg rule; tab 09 computes the indigenisation score from the line items.
B12: CAUTION | C12: Product pages and prices were correct when this BOM was compiled and are not permanent. Two Reflex Drive motor variants exist (RD 5008 KV370 and RD MI-5008 KV340) with identical 135 g mass — confirm which one the reseller actually ships, because the KV difference changes the prop match.

Sheet 01 Air Vehicle BOM
A1: 01 — AIR VEHICLE BOM (per aircraft; x3 for the fleet)
A2: Design point: quad · RD 1760 17x6.0 props · RD MI-5008 KV340 · RD A-Series 60A FOC ESC · 6S3P 21700 · MTOW 5.52 kg · fleet 16.57 kg vs 25 kg cap.
A3: # | B3: Component | C3: Exact part / model | D3: Key verified specification | E3: Supplier (location) | F3: Link | G3: Status | H3: Tier | I3: Ind % | J3: Qty | K3: Unit g | L3: Total g | M3: Unit ₹ | N3: Ext ₹ | O3: Indian ₹ | P3: Lead | Q3: Why / sizing reference
A4: PROPULSION — fully verified, Made in India, single supplier
A5: 1 | B5: Motor | C5: Reflex Drive RD MI-5008, 6S, KV340 | D5: 340 KV · 4S-6S · 24N28P · 135 g incl. cable · IP34 · 90.99% efficiency · rated for 15-18 in props · phi 55.6 x 27 mm · 6 mm shaft. Sister part RD 5008 KV370: 35 A cont / 51 A peak, 1.23 kW peak, 4.2 kgf on a 17x6.0 prop. | E5: Reflex Drive / Sunmint Energy (Lucknow, UP) | F5: open | G5: VERIFIED | H5: I1 | I5: 0.9 | J5: 4 | K5: 135 | L5: =J5*K5 -> 540 | M5: 9099 | N5: =J5*M5 -> 36396 | O5: =N5*I5 -> 32756.4 | P5: 2-3 wk | Q5: Sizing §6: need 2.53 kgf per motor at T/W 2. This gives 4.2 kgf, so hover sits at 33% of rating and T/W_max is 3.04. Over-rated, which is what the 34% fleet mass margin is for.
A6: 2 | B6: ESC | C6: Reflex Drive RD A-Series FOC ESC 60 A | D6: 60 A · 2 kW peak · Field-Oriented Control · 28 g without enclosure · Made in India · optimised for UAV propulsion. | E6: Reflex Drive (Lucknow, UP) | F6: open | G6: VERIFIED | H6: I1 | I6: 0.85 | J6: 4 | K6: 28 | L6: =J6*K6 -> 112 | M6: 3400 | N6: =J6*M6 -> 13600 | O6: =N6*I6 -> 11560 | P6: 2-3 wk | Q6: Sizing §6: 99 A pack peak = ~25 A per motor. 60 A is 2.4x margin. FOC gives smoother low-RPM control than trapezoidal, which matters during the 6 m hover-and-drop.
A7: 3 | B7: Propeller | C7: Reflex Drive RD 1760, 17 x 6.0 in | D7: 17 in diameter · 6.0 in pitch · 40 g each · nylon-carbon composite, 38% carbon fibre · aluminium alloy mounting hub. CW + CCW sets. | E7: Reflex Drive (Lucknow, UP) | F7: open | G7: VERIFIED | H7: I1 | I7: 0.85 | J7: 4 | K7: 40 | L7: =J7*K7 -> 160 | M7: 1400 | N7: =J7*M7 -> 5600 | O7: =N7*I7 -> 4760 | P7: 2-3 wk | Q7: Sizing §3: hover power scales as 1/D. 17 in is the largest the RD 5008 is bench-tested on. At 40 g these are exceptionally light — the imported 18 in CF reference was 58 g.
A8: 4 | B8: Prop adapter | C8: RD 6 mm self-tightening hub (with motor) | D8: 6 mm shaft, matched to the RD 5008 series. Confirm inclusion with the reseller before ordering separately. | E8: Reflex Drive | F8: open | G8: SPEC OK / RFQ | H8: I1 | I8: 1 | J8: 4 | K8: 14 | L8: =J8*K8 -> 56 | M8: 450 | N8: =J8*M8 -> 1800 | O8: =N8*I8 -> 1800 | P8: 2-3 wk | Q8: Shaft size confirmed at 6 mm from the motor listing.
A9: AVIONICS — verified, Made in India
A10: 5 | B10: Flight controller | C10: Agam Autopilot V6X-RT Full Set | D10: FMUv6X-RT / Pixhawk Autopilot Bus standard · NXP i.MX RT1176 dual-core (1 GHz Cortex-M7 + 400 MHz M4) · first non-STM32 Pixhawk-standard FC · triple redundant IMU + dual baro · Bosch and InvenSense sensors · 3x CAN incl. CAN-3 · Ethernet · secure element · solderless connectorised · 10- and 6-layer PCBs, CNC aluminium enclosure, all made in India · PX4 (BSD). SET INCLUDES: FC, IMU board (2 IMU + baro + mag + EEPROM), 16 GB SD, Agam Carrier Board, Agam Digital Power Module 6S/12S, cable set. MOQ 1. | E10: Agam Robotics (Bengaluru) | F10: open | G10: VERIFIED | H10: I2 | I10: 0.6 | J10: 1 | K10: 110 | L10: =J10*K10 -> 110 | M10: 42000 | N10: =J10*M10 -> 42000 | O10: =N10*I10 -> 25200 | P10: 3-4 wk | Q10: INR 42,000 incl. 5% GST — a listed price, not an estimate. Ethernet to the companion computer is a real advantage over UART for the detection stream. Set price replaces separate FC, power module and carrier lines.
A11: 6 | B11: VEGA co-processor | C11: C-DAC VEGA RISC-V development kit | D11: Indigenous RISC-V processor from C-DAC under MeitY. Two kits provided free to each top-100 NIDAR team. Used here as the payload-release and failsafe-watchdog controller, with a hardware bypass. | E11: C-DAC (via NIDAR) | F11: open | G11: SPEC OK / RFQ | H11: I1 | I11: 1 | J11: 1 | K11: 60 | L11: =J11*K11 -> 60 | M11: 0 | N11: =J11*M11 -> 0 | O11: =N11*I11 -> 0 | P11: via NIDAR | Q11: INDIGENISATION DIFFERENTIATOR. Puts Indian silicon on the aircraft without risking the flight-critical path. Track 2 mandates VEGA; using it in Track 1 is voluntary and therefore noticeable.
A12: 7 | B12: GNSS primary | C12: Teravolt Labs AeroNav-series NavIC L1+L5 receiver | D12: NavIC L1 + L5 dual-band, Indian-designed GNSS receiver with integrated compass. CONFIRM WITH SUPPLIER: RTK rover mode and moving-baseline heading support, and RTCM3 input format. | E12: Teravolt Labs (India) | F12: open | G12: RFQ | H12: I2 | I12: 0.6 | J12: 1 | K12: 55 | L12: =J12*K12 -> 55 | M12: 18000 | N12: =J12*M12 -> 18000 | O12: =N12*I12 -> 10800 | P12: 3 wk | Q12: Sizing §11: GNSS is the dominant geotag error term. NavIC adds satellites directly overhead India and improves time-to-first-fix, which buys margin in the 5-minute setup window (Sizing §15).
A13: 8 | B13: GNSS secondary | C13: Second receiver for moving-baseline heading | D13: Same family as the primary, for dual-antenna yaw. Alternative: Accord Software & Systems (Bengaluru), decades of Indian GNSS and NavIC receiver heritage. | E13: Teravolt Labs / Accord Software (Bengaluru) | F13: open | G13: RFQ | H13: I2 | I13: 0.6 | J13: 1 | K13: 50 | L13: =J13*K13 -> 50 | M13: 17000 | N13: =J13*M13 -> 17000 | O13: =N13*I13 -> 10200 | P13: 3-4 wk | Q13: Sizing §11 case C: once RTK removes GNSS error, attitude leads. Dual-antenna heading removes magnetometer error near a 100 A power bus.
A14: 9 | B14: GNSS antennas | C14: Multi-band L1/L5 helical or patch, x2 | D14: Supplied with the receiver kits. Ground plane required. Mount >=150 mm above the power bus. | E14: Supplied with receiver | F14: — | G14: RFQ | H14: I2 | I14: 0.6 | J14: 2 | K14: 35 | L14: =J14*K14 -> 70 | M14: 3200 | N14: =J14*M14 -> 6400 | O14: =N14*I14 -> 3840 | P14: 3-4 wk | Q14: EMI control is a Phase 3 exit gate: satellite count with all systems powered must be within 10% of the count with everything else off.
A15: 10 | B15: RC receiver | C15: ExpressLRS 2.4 GHz receiver | D15: ELRS 2.4 GHz, safety-pilot link. Indian-manufactured ELRS hardware available from Zerodrag. | E15: Zerodrag (India) | F15: open | G15: SPEC OK / RFQ | H15: I3 | I15: 0.5 | J15: 1 | K15: 12 | L15: =J15*K15 -> 12 | M15: 2000 | N15: =J15*M15 -> 2000 | O15: =N15*I15 -> 1000 | P15: 1-2 wk | Q15: Not used in the scored mission. Present so a human can take control in an emergency — a range-safety requirement, not a rules requirement.
A16: POWER
A17: 11 | B17: Li-ion cells | C17: 21700 NMC, >=4000 mAh, 40-45 A continuous — 18 off (6S3P) | D17: GODI India (Hyderabad) manufactures BIS-certified 21700 NMC cells in India. CONFIRM: whether a 40 A+ continuous high-drain drone-grade variant is in production. If not, buy an Indian-assembled pack built on imported high-drain cells and declare it as tier I3. | E17: GODI India (Hyderabad) | F17: open | G17: RFQ | H17: I3 | I17: 0.4 | J17: 18 | K17: 70 | L17: =J17*K17 -> 1260 | M17: 700 | N17: =J17*M17 -> 12600 | O17: =N17*I17 -> 5040 | P17: 4-6 wk | Q17: Sizing §4: 6S3P = 292 Wh, 13.5 Ah, 135 A burst vs a 99 A peak demand (37% margin). WEAKEST INDIGENISATION LINK IN THE BUILD.
A18: 12 | B18: Pack assembly | C18: 6S3P spot-welded pack: holders, pure nickel, fish paper, wrap, XT90-S lead | D18: Indian pack assembly is a mature, competitive industry. Contract the assembler to capacity- and IR-match every cell and hand over the data. | E18: Revogreen / Lion Battery / Neuron Energy / CLN Energy | F18: — | G18: RFQ | H18: I1 | I18: 0.9 | J18: 1 | K18: 260 | L18: =J18*K18 -> 260 | M18: 3500 | N18: =J18*M18 -> 3500 | O18: =N18*I18 -> 3150 | P18: 2-3 wk | Q18: Counterfeit 21700s are widespread. Buying a matched, tested pack from an Indian assembler removes both the counterfeit risk and the need to own a spot welder.
A19: 13 | B19: BMS / balance board | C19: 6S BMS with per-cell taps, high-current discharge path | D19: Flameback Tech manufactures Battery Management Systems and PDBs in India. | E19: Flameback Tech (Baddi, HP) | F19: open | G19: SPEC OK / RFQ | H19: I1 | I19: 0.8 | J19: 1 | K19: 45 | L19: =J19*K19 -> 45 | M19: 1600 | N19: =J19*M19 -> 1600 | O19: =N19*I19 -> 1280 | P19: 2 wk | Q19: Per-cell monitoring drives the SoC display the GCS must show (rule C11) and the low-battery failsafe (rule C16).
A20: 14 | B20: Power distribution board | C20: Flameback PDB, high-current | D20: Flameback lists Power Distribution Boards among its drone electronics. Specify 150 A+ continuous with 10 AWG pads. | E20: Flameback Tech (Baddi, HP) | F20: open | G20: SPEC OK / RFQ | H20: I1 | I20: 0.8 | J20: 1 | K20: 55 | L20: =J20*K20 -> 55 | M20: 1800 | N20: =J20*M20 -> 1800 | O20: =N20*I20 -> 1440 | P20: 2 wk | Q20: Sizing §6: 99 A peak. Thermal margin needed at 45 C ambient.
A21: 15 | B21: Power module | C21: Included in the Agam V6X-RT Full Set (Agam Digital Power Module 6S/12S) | D21: Digital power module for 6S/12S, part of the Agam full set — no separate purchase needed. | E21: Agam Robotics | F21: open | G21: VERIFIED | H21: I2 | I21: 0.6 | J21: 1 | K21: 45 | L21: =J21*K21 -> 45 | M21: 0 | N21: =J21*M21 -> 0 | O21: =N21*I21 -> 0 | P21: with FC | Q21: Cost already carried in the flight controller line. Digital (I2C/CAN) modules are more accurate than analogue shunts at low current.
A22: 16 | B22: BEC 5 V and 12 V | C22: Flameback / Indian power-electronics BEC, 5 V 5 A + 12 V 5 A | D22: Separate regulated rails for FC peripherals and for the compute module. | E22: Flameback Tech / Indian supplier | F22: open | G22: RFQ | H22: I1 | I22: 0.8 | J22: 2 | K22: 31 | L22: =J22*K22 -> 62 | M22: 1000 | N22: =J22*M22 -> 2000 | O22: =N22*I22 -> 1600 | P22: 1-2 wk | Q22: Separate rails mean a compute brownout cannot take the flight controller down.
A23: 17 | B23: Silicone wire | C23: 10 AWG mains (2 m), 14 AWG motor (6 m), 22-26 AWG signal | D23: Indian cable manufacture is world class. Polycab, Finolex and RR Kabel all supply silicone-insulated high-strand wire. | E23: Polycab / Finolex / RR Kabel | F23: open | G23: LOCAL | H23: I1 | I23: 1 | J23: 1 | K23: 205 | L23: =J23*K23 -> 205 | M23: 1200 | N23: =J23*M23 -> 1200 | O23: =N23*I23 -> 1200 | P23: 1 wk | Q23: Sizing §6: 99 A peak drives 10 AWG mains; ~25 A per motor drives 14 AWG motor leads.
A24: 18 | B24: Connectors | C24: XT90-S anti-spark + JST-GH signal sets | D24: No Indian equivalent exists for these connector families. Small value, unavoidable import, bought through an Indian distributor. | E24: Indian distributor (Robu.in / Robokits) | F24: open | G24: SPEC OK / RFQ | H24: I4 | I24: 0.1 | J24: 1 | K24: 45 | L24: =J24*K24 -> 45 | M24: 900 | N24: =J24*M24 -> 900 | O24: =N24*I24 -> 90 | P24: 1 wk | Q24: Anti-spark is mandatory at 292 Wh — a plain connector will arc and pit on every connection.
A25: 19 | B25: Buzzer, LED, switch | C25: Piezo buzzer, external RGB status LED, arming switch | D25: Arming switch and status LED are included with most Pixhawk-standard kits; confirm with Agam. | E25: Agam accessories / local | F25: open | G25: RFQ | H25: I3 | I25: 0.5 | J25: 1 | K25: 30 | L25: =J25*K25 -> 30 | M25: 900 | N25: =J25*M25 -> 900 | O25: =N25*I25 -> 450 | P25: 1-2 wk | Q25: The LED is how the ground crew reads aircraft state from 10 m away during a 5-minute setup.
A26: COMPUTE AND PERCEPTION
A27: 20 | B27: AI compute module | C27: Edge AI module, >=20 TOPS class, with an Indian-built carrier | D27: NO INDIAN GPU OR NPU EXISTS AT THIS CLASS. Route: imported SoM on an India-designed and India-built carrier and enclosure (e-con Systems, VVDN Technologies or Syrma SGS all do this). Declare the SoM as imported. | E27: e-con Systems (Chennai) / VVDN / Syrma SGS | F27: open | G27: RFQ | H27: I4 | I27: 0.25 | J27: 1 | K27: 200 | L27: =J27*K27 -> 200 | M27: 55000 | N27: =J27*M27 -> 55000 | O27: =N27*I27 -> 13750 | P27: 4-8 wk | Q27: Sizing §8.2: tiled inference at 2 Hz needs ~24 inferences/s at 640x640. THE ONE IRREDUCIBLE IMPORT ON THE AIRCRAFT.
A28: 21 | B28: Camera module | C28: e-con Systems e-CAM137A_CUMI1335_MOD (13 MP AR1335) or the Orin-Nano variant of the same family | D28: 13 MP, 1/3.2 in onsemi AR1335 CMOS · 4-lane MIPI CSI-2 · integrated high-performance ISP · 4K @ 30 fps · S-mount interchangeable lens holder · 3-year warranty, 8-10 year lifetime support, MTBF ~8 years. e-con has shipped 2 M+ cameras and has 300+ core engineers in Chennai. Ask them to select the exact variant for your carrier and to ISP-tune for high-altitude nadir daylight. | E28: e-con Systems (Chennai) | F28: open | G28: SPEC OK / RFQ | H28: I2 | I28: 0.6 | J28: 1 | K28: 80 | L28: =J28*K28 -> 80 | M28: 14000 | N28: =J28*M28 -> 14000 | O28: =N28*I28 -> 8400 | P28: 3-4 wk | Q28: Sizing §8: 13 MP with ~63 deg HFOV at 60 m AGL gives ~1.8 cm/px and a ~93 px person across a ~74 m swath. Verify actual FOV by calibration, not datasheet.
A29: 22 | B29: Lens | C29: S-mount, ~6 mm, low distortion, IR-cut | D29: S-mount holder on the e-con module allows lens choice. Confirm the exact focal length against your final sensor format — FOV drives the entire coverage model. | E29: e-con Systems | F29: open | G29: RFQ | H29: I2 | I29: 0.5 | J29: 1 | K29: 25 | L29: =J29*K29 -> 25 | M29: 2600 | N29: =J29*M29 -> 2600 | O29: =N29*I29 -> 1300 | P29: 3-4 wk | Q29: Sizing §8: focal length sets HFOV, which sets swath, GSD and transect count. This is the single most consequential optical choice.
A30: 23 | B30: Camera mount | C30: In-house: rigid nadir mount, silicone isolated, boresight-adjustable then locked | D30: Machined or printed in-house. Must be adjustable for calibration, then mechanically locked and re-verified. | E30: In-house | F30: — | G30: LOCAL | H30: I1 | I30: 1 | J30: 1 | K30: 45 | L30: =J30*K30 -> 45 | M30: 1200 | N30: =J30*M30 -> 1200 | O30: =N30*I30 -> 1200 | P30: 1 wk | Q30: Sizing §11: boresight residual is SYSTEMATIC error that frame averaging cannot remove. The mount design is an accuracy component, not a bracket.
A31: 24 | B31: Storage | C31: 256 GB M.2 NVMe | D31: No Indian NAND or controller. Bought through an Indian distributor. | E31: Indian distributor | F31: open | G31: SPEC OK / RFQ | H31: I4 | I31: 0.1 | J31: 1 | K31: 10 | L31: =J31*K31 -> 10 | M31: 2800 | N31: =J31*M31 -> 2800 | O31: =N31*I31 -> 280 | P31: 1 wk | Q31: Onboard raw-imagery recording feeds the Phase 7 dataset — every sortie should grow the training set.
A32: 25 | B32: Cooling and cabling | C32: 5 V blower + printed duct, CSI ribbon, Ethernet to FC | D32: Blower and duct in-house; CSI cable from e-con with the camera. | E32: In-house + e-con | F32: — | G32: LOCAL | H32: I3 | I32: 0.4 | J32: 1 | K32: 132 | L32: =J32*K32 -> 132 | M32: 3900 | N32: =J32*M32 -> 3900 | O32: =N32*I32 -> 1560 | P32: 2 wk | Q32: Sizing §14: the worst thermal case is the 5-minute ground setup with props stopped at 35 C ambient, not flight.
A33: STRUCTURE
A34: 26 | B34: Arm tube | C34: CF round tube 25 x 23 x 400 mm, roll-wrapped or pultruded | D34: Indian composites houses supply UD/twill CF tube to drawing. Carbon precursor fibre is imported; Epsilon Carbon is commissioning Indian PAN fibre. | E34: Kineco Kaman (Goa) / Composite Technology Park (Bengaluru) | F34: open | G34: RFQ | H34: I2 | I34: 0.7 | J34: 4 | K34: 95 | L34: =J34*K34 -> 380 | M34: 1100 | N34: =J34*M34 -> 4400 | O34: =N34*I34 -> 3080 | P34: 2-3 wk | Q34: Sizing §13: arm root moment 9.4 N·m at T/W 2 gives ~22 MPa vs ~600 MPa for UD carbon, SF ~28. The clamp joint and vibration fatigue are the real drivers, not the tube.
A35: 27 | B35: Centre plates | C35: CF sandwich 2.5 mm, CNC cut to drawing, top + bottom | D35: Cut to your CAD by an Indian composites job shop. | E35: Composite Technology Park / local CNC | F35: — | G35: LOCAL | H35: I2 | I35: 0.7 | J35: 2 | K35: 155 | L35: =J35*K35 -> 310 | M35: 3000 | N35: =J35*M35 -> 6000 | O35: =N35*I35 -> 4200 | P35: 3 wk | Q35: Rule C3 forbids a market-ready airframe — this must be your own design, and the plates are where that is most visible.
A36: 28 | B36: Arm clamps | C36: Machined Al 6061-T6, 25 mm bore, anti-rotation key | D36: Small-batch CNC from the Pune / Coimbatore / Bengaluru machining belt. | E36: Local precision machine shop | F36: — | G36: LOCAL | H36: I1 | I36: 1 | J36: 4 | K36: 45 | L36: =J36*K36 -> 180 | M36: 750 | N36: =J36*M36 -> 3000 | O36: =N36*I36 -> 3000 | P36: 3 wk | Q36: Highest-risk mechanical joint on the aircraft. Torque to spec with a calibrated driver; do not tighten to feel.
A37: 29 | B37: Motor mount plates | C37: CF 3 mm, saddle, bolt pattern matched to the RD 5008 (6 mm shaft, phi 55.6 mm body) | D37: Cut to drawing. | E37: Local CNC | F37: — | G37: LOCAL | H37: I2 | I37: 0.7 | J37: 4 | K37: 22 | L37: =J37*K37 -> 88 | M37: 400 | N37: =J37*M37 -> 1600 | O37: =N37*I37 -> 1120 | P37: 3 wk | Q37: Bolt pattern taken from the verified RD 5008 dimensions.
A38: 30 | B38: Landing gear | C38: CF tube 16 x 300 mm x4 with TPU feet | D38: Tube from the same composites supplier; feet printed in-house. | E38: Kineco / in-house | F38: — | G38: LOCAL | H38: I2 | I38: 0.75 | J38: 1 | K38: 268 | L38: =J38*K38 -> 268 | M38: 2700 | N38: =J38*M38 -> 2700 | O38: =N38*I38 -> 2025 | P38: 2-3 wk | Q38: Must absorb a 1.5 m/s touchdown at 5.5 kg and keep the payload magazine clear of the ground.
A39: 31 | B39: Battery tray, canopy, mounts | C39: CF tray, printed PETG/ASA canopy, silicone FC damping mount | D39: Printed on an Indian FDM machine (Fracktal Works, Divide By Zero, AHA 3D). | E39: In-house | F39: open | G39: LOCAL | H39: I1 | I39: 1 | J39: 1 | K39: 243 | L39: =J39*K39 -> 243 | M39: 1450 | N39: =J39*M39 -> 1450 | O39: =N39*I39 -> 1450 | P39: 1 wk | Q39: IMU vibration is the leading cause of EKF failure on student builds — the damping mount is a flight-critical part, not trim.
A40: 32 | B40: Fasteners | C40: M3 socket cap A2, nyloc, washers, heat inserts (~120 pcs) | D40: Sundram Fasteners (Chennai) is a world-class Indian fastener manufacturer. | E40: Sundram Fasteners / local | F40: open | G40: LOCAL | H40: I1 | I40: 1 | J40: 1 | K40: 110 | L40: =J40*K40 -> 110 | M40: 800 | N40: =J40*M40 -> 800 | O40: =N40*I40 -> 800 | P40: 1 wk | Q40: No indigenisation gap at all in this category.
...

Sheet 02 Payload & Kits
A1: 02 — PAYLOAD, KITS AND GROUND-TRUTH TARGETS (fleet quantities)
A2: Effectively 100% indigenous — this category is local fabrication and consumables throughout.
A3: # | B3: Component | C3: Exact part / model | D3: Key verified specification | E3: Supplier (location) | F3: Link | G3: Status | H3: Tier | I3: Ind % | J3: Qty | K3: Unit g | L3: Total g | M3: Unit ₹ | N3: Ext ₹ | O3: Indian ₹ | P3: Lead | Q3: Why / sizing reference
A4: SURVIVOR KITS — rule C6: exactly 200 g in a 200 x 100 x 50 mm rigid box
A5: 1 | B5: Kit box | C5: Injection-moulded ABS or corrugated PP, hi-vis orange, 200x100x50 mm | D5: Made to drawing by a local moulder. 14 built for 12 flown plus 2 spares. | E5: Local injection moulder | F5: — | G5: LOCAL | H5: I1 | I5: 1 | J5: 14 | K5: 55 | L5: =J5*K5 -> 770 | M5: 150 | N5: =J5*M5 -> 2100 | O5: =N5*I5 -> 2100 | P5: 2-3 wk | Q5: Sizing §10: must survive a 9.7 m/s impact from a 6 m release. Test this with ballast kits before trusting it.
A6: 2 | B6: Impact padding | C6: Closed-cell EVA foam liner, 8 mm | D6: Local foam converter. | E6: Local | F6: — | G6: LOCAL | H6: I1 | I6: 1 | J6: 14 | K6: 18 | L6: =J6*K6 -> 252 | M6: 50 | N6: =J6*M6 -> 700 | O6: =N6*I6 -> 700 | P6: 1 wk | Q6: Protects contents and reduces post-impact bounce, which otherwise adds scatter to the measured miss distance.
A7: 3 | B7: Kit contents | C7: Bandage roll, ORS sachets, whistle, glow stick, emergency blanket, water pouch | D7: All locally available. ORS in particular is an Indian staple product. | E7: Local pharmacy | F7: — | G7: LOCAL | H7: I1 | I7: 1 | J7: 14 | K7: 110 | L7: =J7*K7 -> 1540 | M7: 180 | N7: =J7*M7 -> 2520 | O7: =N7*I7 -> 2520 | P7: 1 wk | Q7: Box, padding and contents together must total exactly 200.0 g. Weigh and log every kit individually on a 0.1 g scale.
A8: 4 | B8: Trim ballast | C8: Steel shot sachet to bring each kit to 200.0 g | D8: Local. | E8: Local | F8: — | G8: LOCAL | H8: I1 | I8: 1 | J8: 14 | K8: 17 | L8: =J8*K8 -> 238 | M8: 20 | N8: =J8*M8 -> 280 | O8: =N8*I8 -> 280 | P8: 1 wk | Q8: Rule C6 is exact, not approximate.
A9: 5 | B9: Test dummy kits | C9: Ballast-only boxes, identical mass and dimensions, x24 | D9: Built in-house so real kits are never consumed in testing. | E9: In-house | F9: — | G9: LOCAL | H9: I1 | I9: 1 | J9: 24 | K9: 200 | L9: =J9*K9 -> 4800 | M9: 120 | N9: =J9*M9 -> 2880 | O9: =N9*I9 -> 2880 | P9: 1 wk | Q9: Development Plan P8 requires >=30 instrumented drops to establish delivery CEP.
A10: GROUND-TRUTH TARGETS — Phase 7 detection and Phase 8 delivery campaigns
A11: 6 | B11: Survivor mannequins | C11: Human-size, articulable to supine / prone / seated, weather-tolerant, x6 | D11: Local fibreglass or mannequin fabricator. | E11: Local fabricator | F11: — | G11: LOCAL | H11: I1 | I11: 1 | J11: 6 | K11: 4000 | L11: =J11*K11 -> 24000 | M11: 3000 | N11: =J11*M11 -> 18000 | O11: =N11*I11 -> 18000 | P11: 3 wk | Q11: Dress them in clothing typical of an Indian flood-affected population. HERIDAL and SARD will not teach the model that distribution.
A12: 7 | B12: Target clothing sets | C12: Varied contrast including low-contrast earth tones, saris, kurtas, x6 | D12: Local. | E12: Local | F12: — | G12: LOCAL | H12: I1 | I12: 1 | J12: 6 | K12: 400 | L12: =J12*K12 -> 2400 | M12: 500 | N12: =J12*M12 -> 3000 | O12: =N12*I12 -> 3000 | P12: 1 wk | Q12: Prevents the detector learning "bright clothing" as the survivor cue.
A13: 8 | B13: Drop-zone target mats | C13: 5 m concentric-ring mat with an RTK-surveyed centre, x3 | D13: Local fabricator. | E13: Local fabricator | F13: — | G13: LOCAL | H13: I1 | I13: 1 | J13: 3 | K13: 2500 | L13: =J13*K13 -> 7500 | M13: 2200 | N13: =J13*M13 -> 6600 | O13: =N13*I13 -> 6600 | P13: 2 wk | Q13: Measures delivery CEP directly against the Sizing §10 target of <=3 m.
A14: 9 | B14: Calibration markers | C14: 600 mm checkerboard / AprilTag panels on rigid board, surveyed, x12 | D14: Printed locally and mounted on aluminium composite — flatness matters more than print quality. | E14: In-house | F14: — | G14: LOCAL | H14: I1 | I14: 1 | J14: 12 | K14: 300 | L14: =J14*K14 -> 3600 | M14: 400 | N14: =J14*M14 -> 4800 | O14: =N14*I14 -> 4800 | P14: 1 wk | Q14: Sizing §11: boresight and lever-arm calibration removes systematic bias that no amount of frame averaging will.
B15: TOTAL | I15: =O15/N15 -> 1 | L15: =SUM(L5:L14) -> 45100 | N15: =SUM(N5:N14) -> 40880 | O15: =SUM(O5:O14) -> 40880

Sheet 03 Ground Segment
A1: 03 — GROUND SEGMENT AND FIELD INFRASTRUCTURE
A2: India is strong on power, solar, masts and safety. Computing hardware is the weak spot; GNSS is a bright spot.
A3: # | B3: Component | C3: Exact part / model | D3: Key verified specification | E3: Supplier (location) | F3: Link | G3: Status | H3: Tier | I3: Ind % | J3: Qty | K3: Unit g | L3: Total g | M3: Unit ₹ | N3: Ext ₹ | O3: Indian ₹ | P3: Lead | Q3: Why / sizing reference
A4: GROUND CONTROL STATION
A5: 1 | B5: GCS laptop | C5: 16 GB RAM, discrete GPU, 1 TB SSD | D5: Assembled in India under PLI by Dixon, VVDN or Syrma for several brands. CPU, GPU and memory are imported — there is no Indian x86 or discrete GPU. | E5: Indian-manufactured unit | F5: — | G5: RFQ | H5: I3 | I5: 0.25 | J5: 1 | K5: 2200 | L5: =J5*K5 -> 2200 | M5: 105000 | N5: =J5*M5 -> 105000 | O5: =N5*I5 -> 26250 | P5: 2 wk | Q5: Runs the custom GCS, MAVLink router, mesh node and video decode. Rule C10 permits exactly one Ground Control Station.
A6: 2 | B6: Backup laptop | C6: Cloned image, powered and ready to swap | D6: Same source. | E6: Indian-manufactured unit | F6: — | G6: RFQ | H6: I3 | I6: 0.25 | J6: 1 | K6: 2200 | L6: =J6*K6 -> 2200 | M6: 85000 | N6: =J6*M6 -> 85000 | O6: =N6*I6 -> 21250 | P6: 2 wk | Q6: A GCS failure ends the mission. This is the cheapest single-point-of-failure removal available.
A7: 3 | B7: Sun hood + observer monitor | C7: Laptop hood (locally made) + 15 in portable monitor | D7: Hood fabricated locally; panel imported. | E7: Local + distributor | F7: — | G7: LOCAL | H7: I3 | I7: 0.5 | J7: 1 | K7: 1500 | L7: =J7*K7 -> 1500 | M7: 20000 | N7: =J7*M7 -> 20000 | O7: =N7*I7 -> 10000 | P7: 2 wk | Q7: Rule C15 is daylight outdoors. You cannot read a laptop screen in Indian midday sun, and this screen is the judges entire view of your system.
A8: MESH GROUND NODE AND RTK BASE
A9: 4 | B9: Ground mesh node | C9: Matched to the airborne node, weatherproof enclosure | D9: Same supplier as the air nodes for guaranteed interoperability. | E9: FxUAV Technologies (Burla) | F9: open | G9: RFQ | H9: I3 | I9: 0.4 | J9: 1 | K9: 450 | L9: =J9*K9 -> 450 | M9: 8000 | N9: =J9*M9 -> 8000 | O9: =N9*I9 -> 3200 | P9: 3-4 wk | Q9: Sizing §12.
A10: 5 | B10: Sector antenna | C10: 9 dBi, 5.15-5.9 GHz, 90-120 deg sector, x2 | D10: Indian RF antenna manufacture is capable here. | E10: Indian RF antenna manufacturer | F10: — | G10: RFQ | H10: I2 | I10: 0.7 | J10: 2 | K10: 320 | L10: =J10*K10 -> 640 | M10: 3800 | N10: =J10*M10 -> 7600 | O10: =N10*I10 -> 5320 | P10: 2 wk | Q10: Sizing §12: 9 dBi at the GCS gives 33 dBm EIRP (legal) and 13.7 dB margin at 600 m.
A11: 6 | B11: Antenna mast | C11: 2 m telescopic mast, tripod, guys | D11: Indian mast and tripod manufacture. | E11: Indian supplier | F11: — | G11: LOCAL | H11: I1 | I11: 1 | J11: 1 | K11: 3500 | L11: =J11*K11 -> 3500 | M11: 5500 | N11: =J11*M11 -> 5500 | O11: =N11*I11 -> 5500 | P11: 2 wk | Q11: Sizing §12: raising the ground antenna is the cheapest link-margin improvement in the system — ground-level antennas lose 6-10 dB to clutter.
A12: 7 | B12: RTK base receiver | C12: NavIC + GNSS base with survey-grade antenna | D12: Accord Software & Systems (Bengaluru) has decades of Indian GNSS and NavIC receiver heritage. CONFIRM: base-mode RTCM3 output and compatibility with the airborne receiver. | E12: Accord Software (Bengaluru) / Elena Geo | F12: open | G12: RFQ | H12: I2 | I12: 0.6 | J12: 1 | K12: 600 | L12: =J12*K12 -> 600 | M12: 38000 | N12: =J12*M12 -> 38000 | O12: =N12*I12 -> 22800 | P12: 4 wk | Q12: Sizing §11: takes geotag CEP50 from ~2.5 m to ~1.1 m. Corrections travel on the team local link, not the internet. PENDING organiser confirmation (clarification Q1).
A13: 8 | B13: Survey tripod + tribrach | C13: Fixed-height survey tripod | D13: Indian survey equipment supplier. | E13: Indian supplier | F13: — | G13: LOCAL | H13: I1 | I13: 1 | J13: 1 | K13: 3500 | L13: =J13*K13 -> 3500 | M13: 9500 | N13: =J13*M13 -> 9500 | O13: =N13*I13 -> 9500 | P13: 2 wk | Q13: Base position must be stable and repeatable across the whole test campaign.
A14: 9 | B14: Base-to-rover link | C14: 865-867 MHz RTCM broadcast | D14: Same family as the airborne safety link. | E14: FxUAV | F14: open | G14: RFQ | H14: I3 | I14: 0.4 | J14: 1 | K14: 150 | L14: =J14*K14 -> 150 | M14: 7500 | N14: =J14*M14 -> 7500 | O14: =N14*I14 -> 3000 | P14: 3 wk | Q14: Team-owned local link, compliant with rule C12.
A15: FIELD POWER, INFRASTRUCTURE AND SAFETY
A16: 10 | B16: Portable power station | C16: 1.5-2 kWh LiFePO4 with AC output | D16: Okaya, Luminous, Exide and Servotech all manufacture in India. Cells imported, pack and inverter Indian. | E16: Okaya / Luminous / Exide | F16: open | G16: RFQ | H16: I1 | I16: 0.8 | J16: 1 | K16: 18000 | L16: =J16*K16 -> 18000 | M16: 80000 | N16: =J16*M16 -> 80000 | O16: =N16*I16 -> 64000 | P16: 2 wk | Q16: Charging three 292 Wh packs between sorties plus GCS and instruments; a test day is 6-10 sorties.
A17: 11 | B17: Solar panel | C17: 200 W folding | D17: India has genuine world-scale PV manufacture. | E17: Waaree / Vikram Solar / Adani | F17: open | G17: SPEC OK / RFQ | H17: I1 | I17: 0.9 | J17: 1 | K17: 6000 | L17: =J17*K17 -> 6000 | M17: 15000 | N17: =J17*M17 -> 15000 | O17: =N17*I17 -> 13500 | P17: 2 wk | Q17: Optional. Useful for remote Phase 7 data-campaign sites.
A18: 12 | B18: Landing pad | C18: 3.66 x 3.66 m marked pad, pegged, with launch-order position markers | D18: Locally fabricated to the exact rule dimension. | E18: Local fabricator | F18: — | G18: LOCAL | H18: I1 | I18: 1 | J18: 1 | K18: 4500 | L18: =J18*K18 -> 4500 | M18: 6500 | N18: =J18*M18 -> 6500 | O18: =N18*I18 -> 6500 | P18: 2 wk | Q18: Rule C14 fixes 12 ft. Practise every launch and recovery on an exactly-sized pad from the first flight.
A19: 13 | B19: Anemometer + windsock | C19: Handheld logging anemometer + 600 mm windsock | D19: Indian instrument brands (HTC, Metravi) assemble in India; sensing element imported. | E19: HTC / Metravi | F19: — | G19: RFQ | H19: I3 | I19: 0.4 | J19: 1 | K19: 400 | L19: =J19*K19 -> 400 | M19: 4000 | N19: =J19*M19 -> 4000 | O19: =N19*I19 -> 1600 | P19: 1 wk | Q19: Sizing §9.2: the wind policy is constant GROUNDSPEED. You must measure wind to verify it and to log conditions per sortie.
A20: 14 | B20: Field table, canopy, cases | C20: Folding table, 3x3 m canopy, 4 wheeled hard cases with cut foam | D20: Locally sourced; foam cut in-house to the setup choreography. | E20: Local | F20: — | G20: LOCAL | H20: I1 | I20: 0.9 | J20: 1 | K20: 40000 | L20: =J20*K20 -> 40000 | M20: 24000 | N20: =J20*M20 -> 24000 | O20: =N20*I20 -> 21600 | P20: 3 wk | Q20: Sizing §15: the 5-minute setup starts with getting aircraft out of cases. Foam layout is part of the timed procedure.
A21: 15 | B21: Safety kit | C21: Li-ion fire-resistant bags x6, lithium-rated extinguisher x2, dry sand, trauma first aid, hi-vis, eye protection | D21: Indian fire-safety manufacture is strong. | E21: Local suppliers | F21: — | G21: LOCAL | H21: I1 | I21: 1 | J21: 1 | K21: 4500 | L21: =J21*K21 -> 4500 | M21: 18000 | N21: =J21*M21 -> 18000 | O21: =N21*I21 -> 18000 | P21: 1 wk | Q21: 17 in carbon props at 6500 RPM cause serious injuries, and 292 Wh of lithium will not be stopped by water or CO2. Have this before the first spin-up.
A22: 16 | B22: Safety-pilot transmitter | C22: ELRS 2.4 GHz TX matched to the aircraft receivers | D22: Indian ELRS hardware from Zerodrag. | E22: Zerodrag | F22: open | G22: RFQ | H22: I3 | I22: 0.4 | J22: 1 | K22: 700 | L22: =J22*K22 -> 700 | M22: 16000 | N22: =J22*M22 -> 16000 | O22: =N22*I22 -> 6400 | P22: 2 wk | Q22: Manual override during testing; unused in the scored run.
A23: 17 | B23: Barrier tape and cones | C23: 100 m tape, 8 cones | D23: Local. | E23: Local | F23: — | G23: LOCAL | H23: I1 | I23: 1 | J23: 1 | K23: 2000 | L23: =J23*K23 -> 2000 | M23: 1200 | N23: =J23*M23 -> 1200 | O23: =N23*I23 -> 1200 | P23: 1 wk | Q23: Keeps spectators out of the descent cone at test sites.
B24: TOTAL | I24: =O24/N24 -> 0.53154392 | L24: =SUM(L5:L23) -> 90840 | N24: =SUM(N5:N23) -> 450800 | O24: =SUM(O5:O23) -> 239620

Sheet 04 Test & Lab Equipment
A1: 04 — TEST, LAB AND CALIBRATION EQUIPMENT
A2: India is strong in balances, instruments, hand tools and 3D printers. Weak in hobby chargers — outsource pack building instead of buying a spot welder.
A3: # | B3: Component | C3: Exact part / model | D3: Key verified specification | E3: Supplier (location) | F3: Link | G3: Status | H3: Tier | I3: Ind % | J3: Qty | K3: Unit g | L3: Total g | M3: Unit ₹ | N3: Ext ₹ | O3: Indian ₹ | P3: Lead | Q3: Why / sizing reference
A4: PROPULSION AND POWER — retires Sizing §16 assumptions A1, A2, A4, A5
A5: 1 | B5: Thrust stand | C5: In-house rig: thrust + torque + RPM + electrical power, to 5 kgf | D5: Built around Indian load cells (Sensocon, Instrumentation Ltd Kota) and an Indian DAQ. A third of the cost of an imported RCbenchmark and itself a legitimate engineering deliverable. | E5: In-house + Sensocon | F5: open | G5: LOCAL | H5: I1 | I5: 0.85 | J5: 1 | K5: 3000 | L5: =J5*K5 -> 3000 | M5: 45000 | N5: =J5*M5 -> 45000 | O5: =N5*I5 -> 38250 | P5: 4 wk | Q5: Sizing §16 A1: figure of merit is assumed 0.60 and is the largest uncertainty in the power model. Reflex Drive publish their own bench data, which lets you validate the rig before trusting it.
A6: 2 | B6: Power analyser | C6: Inline watt meter, 130 A, logging, x2 | D6: Meco Instruments manufactures test instruments in Mumbai. | E6: Meco Instruments (Mumbai) | F6: open | G6: SPEC OK / RFQ | H6: I2 | I6: 0.5 | J6: 2 | K6: 180 | L6: =J6*K6 -> 360 | M6: 4000 | N6: =J6*M6 -> 8000 | O6: =N6*I6 -> 4000 | P6: 2 wk | Q6: Measures real hover current against the 37 A predicted. Reflex Drives published table gives you an independent cross-check.
A7: 3 | B7: Battery chargers | C7: 6S balance charger, 300-1000 W, x2 | D7: GAP: hobby-grade balance chargers are almost entirely imported. Indian agri-drone charger suppliers are the closest domestic option — ask for a 6S variant. | E7: Bharath Components / IoTechWorld | F7: open | G7: RFQ | H7: I3 | I7: 0.4 | J7: 2 | K7: 1200 | L7: =J7*K7 -> 2400 | M7: 26000 | N7: =J7*M7 -> 52000 | O7: =N7*I7 -> 20800 | P7: 3 wk | Q7: A 292 Wh pack at 1C needs ~300 W. Two chargers keep a test day moving.
A8: 4 | B8: Charger PSU | C8: 24 V 40 A bench supply, x2 | D8: Aplab and Scientific Mes-Technik are long-standing Indian instrument manufacturers. | E8: Aplab / Scientific Mes-Technik | F8: open | G8: SPEC OK / RFQ | H8: I1 | I8: 0.8 | J8: 2 | K8: 1500 | L8: =J8*K8 -> 3000 | M8: 8000 | N8: =J8*M8 -> 16000 | O8: =N8*I8 -> 12800 | P8: 2 wk | Q8: Feeds the chargers at rated power.
A9: MEASUREMENT AND CALIBRATION
A10: 5 | B10: Precision scale | C10: 0.1 g resolution, 5 kg capacity | D10: Aczet and Contech are genuine Indian precision balance manufacturers. | E10: Aczet (Mumbai) / Contech | F10: open | G10: SPEC OK / RFQ | H10: I1 | I10: 0.9 | J10: 1 | K10: 2000 | L10: =J10*K10 -> 2000 | M10: 7000 | N10: =J10*M10 -> 7000 | O10: =N10*I10 -> 6300 | P10: 1-2 wk | Q10: Every part weighed on arrival; kits trimmed to exactly 200 g per rule C6.
A11: 6 | B11: Hanging scale — FLEET WEIGH-IN | C11: Calibrated, 50 kg, 10 g resolution | D11: Contech and Essae-Teraoka manufacture in India. | E11: Contech / Essae-Teraoka (Bengaluru) | F11: open | G11: SPEC OK / RFQ | H11: I1 | I11: 0.9 | J11: 1 | K11: 400 | L11: =J11*K11 -> 400 | M11: 4000 | N11: =J11*M11 -> 4000 | O11: =N11*I11 -> 3600 | P11: 1-2 wk | Q11: Rule C2 is a pass/fail check at 25 kg. Own a calibrated scale rather than discovering a discrepancy at the venue.
A12: 7 | B12: Calipers and micrometer | C12: 150 mm digital calipers, 0-25 mm micrometer | D12: Baker Gauges India (Pune) is an Indian precision metrology manufacturer. | E12: Baker Gauges India (Pune) | F12: open | G12: SPEC OK / RFQ | H12: I1 | I12: 0.8 | J12: 2 | K12: 300 | L12: =J12*K12 -> 600 | M12: 3200 | N12: =J12*M12 -> 6400 | O12: =N12*I12 -> 5120 | P12: 1-2 wk | Q12: CF tube OD/ID verification and fastener checks.
A13: 8 | B13: Torque driver | C13: 1-6 N·m adjustable with hex/Torx bits | D13: Groz and Taparia manufacture hand tools in India. | E13: Groz / Taparia | F13: open | G13: SPEC OK / RFQ | H13: I2 | I13: 0.6 | J13: 1 | K13: 400 | L13: =J13*K13 -> 400 | M13: 6500 | N13: =J13*M13 -> 6500 | O13: =N13*I13 -> 3900 | P13: 2 wk | Q13: Under-torqued arm clamps creep under vibration; over-torqued ones crush the carbon tube. Both are avoidable with INR 6,500.
A14: 9 | B14: Prop balancer | C14: Magnetic balancer for 17 in props | D14: Easily fabricated in-house. | E14: Local / in-house | F14: — | G14: LOCAL | H14: I2 | I14: 0.6 | J14: 1 | K14: 600 | L14: =J14*K14 -> 600 | M14: 3000 | N14: =J14*M14 -> 3000 | O14: =N14*I14 -> 1800 | P14: 1 wk | Q14: Sizing §13: vibration fatigue is the real structural driver, and unbalanced props are its main source.
A15: 10 | B15: Camera calibration target | C15: A2 checkerboard on rigid aluminium composite + AprilTag set | D15: Printed locally; flatness is what matters. | E15: Local print + in-house mount | F15: — | G15: LOCAL | H15: I1 | I15: 1 | J15: 1 | K15: 900 | L15: =J15*K15 -> 900 | M15: 3000 | N15: =J15*M15 -> 3000 | O15: =N15*I15 -> 3000 | P15: 1 wk | Q15: Sizing §11: intrinsics AND boresight extrinsics. Skipping the second leaves a 3-5 m systematic geotag bias that looks like random error.
A16: BENCH AND FABRICATION
A17: 11 | B17: Soldering station | C17: Temperature-controlled 80-100 W with a large chisel tip | D17: Soldron is an established Indian brand. | E17: Soldron / Indian distributor | F17: open | G17: SPEC OK / RFQ | H17: I1 | I17: 0.9 | J17: 1 | K17: 2500 | L17: =J17*K17 -> 2500 | M17: 9000 | N17: =J17*M17 -> 9000 | O17: =N17*I17 -> 8100 | P17: 1-2 wk | Q17: 10 AWG to an XT90-S needs real thermal mass. A 30 W iron produces cold joints that fail in flight.
A18: 12 | B18: Bench power supply | C18: 0-30 V 10 A, current-limited | D18: Aplab and Scientific Mes-Technik. | E18: Aplab | F18: open | G18: SPEC OK / RFQ | H18: I1 | I18: 0.8 | J18: 1 | K18: 4000 | L18: =J18*K18 -> 4000 | M18: 8500 | N18: =J18*M18 -> 8500 | O18: =N18*I18 -> 6800 | P18: 2 wk | Q18: Bringing up new boards current-limited will save at least one compute module over the programme.
A19: 13 | B19: Multimeters | C19: True-RMS, 10 A range, x2 | D19: Meco Instruments manufactures in Mumbai. | E19: Meco Instruments | F19: open | G19: SPEC OK / RFQ | H19: I1 | I19: 0.8 | J19: 2 | K19: 350 | L19: =J19*K19 -> 700 | M19: 4000 | N19: =J19*M19 -> 8000 | O19: =N19*I19 -> 6400 | P19: 1-2 wk | Q19: —
A20: 14 | B20: 3D printer | C20: FDM, 250 mm bed, PETG/ASA capable | D20: Fracktal Works (Bengaluru), Divide By Zero (Mumbai) and AHA 3D (Jaipur) are genuine Indian 3D printer manufacturers with local support. | E20: Fracktal Works (Bengaluru) | F20: open | G20: SPEC OK / RFQ | H20: I1 | I20: 0.8 | J20: 1 | K20: 12000 | L20: =J20*K20 -> 12000 | M20: 50000 | N20: =J20*M20 -> 50000 | O20: =N20*I20 -> 40000 | P20: 3 wk | Q20: Canopy, magazine, ducts, jigs and dozens of release-mechanism iterations. Owning one beats outsourcing on iteration speed.
A21: 15 | B21: Hand tools and rework | C21: Hex, Torx, pliers, strippers, cutters, hot air, CF dust extraction, P2 masks | D21: Indian hand tools are excellent and inexpensive. | E21: Taparia / Groz / Jhalani | F21: open | G21: LOCAL | H21: I2 | I21: 0.7 | J21: 1 | K21: 4300 | L21: =J21*K21 -> 4300 | M21: 22000 | N21: =J21*M21 -> 22000 | O21: =N21*I21 -> 15400 | P21: 1-2 wk | Q21: CARBON DUST IS A RESPIRATORY AND ELECTRICAL HAZARD. Extraction and masks are not optional line items.
A22: SIMULATION AND TRAINING COMPUTE
A23: 16 | B23: Dev workstation | C23: RTX-class GPU, 32 GB RAM | D23: Assembled in India; GPU silicon imported. | E23: Indian integrator | F23: — | G23: RFQ | H23: I3 | I23: 0.2 | J23: 1 | K23: 0 | L23: =J23*K23 -> 0 | M23: 165000 | N23: =J23*M23 -> 165000 | O23: =N23*I23 -> 33000 | P23: 3 wk | Q23: Development Plan P4/P7: 200-run Monte Carlo campaigns and detector training.
A24: 17 | B24: Indian GPU cloud | C24: Training compute credits | D24: E2E Networks, Yotta and NxtGen offer Indian GPU cloud — a genuinely indigenous option for TRAINING, unlike inference silicon. | E24: E2E Networks / Yotta / NxtGen | F24: open | G24: SPEC OK / RFQ | H24: I1 | I24: 0.9 | J24: 1 | K24: 0 | L24: =J24*K24 -> 0 | M24: 40000 | N24: =J24*M24 -> 40000 | O24: =N24*I24 -> 36000 | P24: — | Q24: NIDAR provides cloud credits to winning teams. Worth using regardless — it moves training off the critical path of buying hardware.
B25: TOTAL | I25: =O25/N25 -> 0.54095721 | L25: =SUM(L5:L24) -> 37160 | N25: =SUM(N5:N24) -> 453400 | O25: =SUM(O5:O24) -> 245270

Sheet 05 Spares & Consumables
A1: 05 — SPARES AND CONSUMABLES
A2: Reflex Drive and Agam both hold MOQ 1, so spares can be ordered in single units at list price.
A3: # | B3: Component | C3: Exact part / model | D3: Key verified specification | E3: Supplier (location) | F3: Link | G3: Status | H3: Tier | I3: Ind % | J3: Qty | K3: Unit g | L3: Total g | M3: Unit ₹ | N3: Ext ₹ | O3: Indian ₹ | P3: Lead | Q3: Why / sizing reference
A4: FLIGHT SPARES — Development Plan R4: a crash near the finals must not end the programme
A5: 1 | B5: Spare motors | C5: RD MI-5008 KV340, one full set of 4 | D5: As flight item. | E5: Reflex Drive | F5: open | G5: VERIFIED | H5: I1 | I5: 0.9 | J5: 4 | K5: 135 | L5: =J5*K5 -> 540 | M5: 9099 | N5: =J5*M5 -> 36396 | O5: =N5*I5 -> 32756.4 | P5: 2-3 wk | Q5: Domestic lead time of 2-3 weeks versus 4-6 for imports is worth more than the price saving when something breaks in week 28.
A6: 2 | B6: Spare ESCs | C6: RD A-Series 60 A FOC, one full set of 4 | D6: As flight item. | E6: Reflex Drive | F6: open | G6: VERIFIED | H6: I1 | I6: 0.85 | J6: 4 | K6: 28 | L6: =J6*K6 -> 112 | M6: 3400 | N6: =J6*M6 -> 13600 | O6: =N6*I6 -> 11560 | P6: 2-3 wk | Q6: ESCs fail from vibration and heat, and they fail without warning.
A7: 3 | B7: Spare propellers | C7: RD 1760 17x6.0, 6 pairs | D7: As flight item. | E7: Reflex Drive | F7: open | G7: VERIFIED | H7: I1 | I7: 0.85 | J7: 12 | K7: 40 | L7: =J7*K7 -> 480 | M7: 1400 | N7: =J7*M7 -> 16800 | O7: =N7*I7 -> 14280 | P7: 2-3 wk | Q7: Props are consumed by every hard landing. Six pairs is a realistic season.
A8: 4 | B8: Spare arm assemblies | C8: Tube + clamp + motor mount, pre-built, x4 | D8: Pre-build so a field repair is a 10-minute swap, not an afternoon. | E8: In-house | F8: — | G8: LOCAL | H8: I2 | I8: 0.75 | J8: 4 | K8: 162 | L8: =J8*K8 -> 648 | M8: 2200 | N8: =J8*M8 -> 8800 | O8: =N8*I8 -> 6600 | P8: 2 wk | Q8: Arms are what break in a tip-over.
A9: 5 | B9: Spare flight controller | C9: Agam Autopilot V6X-RT Full Set, pre-flashed with the frozen parameter set | D9: As flight item. | E9: Agam Robotics | F9: open | G9: VERIFIED | H9: I2 | I9: 0.6 | J9: 1 | K9: 110 | L9: =J9*K9 -> 110 | M9: 42000 | N9: =J9*M9 -> 42000 | O9: =N9*I9 -> 25200 | P9: 3-4 wk | Q9: Development Plan P10 config freeze applies to the spare too.
A10: 6 | B10: Spare GNSS | C10: NavIC receiver + antenna | D10: As flight item. | E10: Teravolt / Accord | F10: open | G10: RFQ | H10: I2 | I10: 0.6 | J10: 1 | K10: 90 | L10: =J10*K10 -> 90 | M10: 18000 | N10: =J10*M10 -> 18000 | O10: =N10*I10 -> 10800 | P10: 3-4 wk | Q10: —
A11: 7 | B11: Spare compute module | C11: Imaged, with the inference engine pre-built | D11: Same import gap as the primary. | E11: As per tab 01 | F11: — | G11: RFQ | H11: I4 | I11: 0.25 | J11: 1 | K11: 200 | L11: =J11*K11 -> 200 | M11: 55000 | N11: =J11*M11 -> 55000 | O11: =N11*I11 -> 13750 | P11: 4-8 wk | Q11: Sizing §15: never build the inference engine at boot. The spare must be imaged and warm-cached in advance.
A12: 8 | B12: Spare camera + lens | C12: e-con module, boresight-calibrated on a spare mount | D12: As flight item. | E12: e-con Systems | F12: open | G12: RFQ | H12: I2 | I12: 0.6 | J12: 1 | K12: 105 | L12: =J12*K12 -> 105 | M12: 16600 | N12: =J12*M12 -> 16600 | O12: =N12*I12 -> 9960 | P12: 3-4 wk | Q12: Swapping the camera invalidates the boresight calibration — calibrate the spare before you need it.
A13: 9 | B13: Spare battery packs | C13: Complete 6S3P packs, x3 | D13: Two packs per aircraft minimum so a test day is not charger-limited; the third is the crash reserve. | E13: Indian pack house | F13: — | G13: RFQ | H13: I1 | I13: 0.85 | J13: 3 | K13: 1500 | L13: =J13*K13 -> 4500 | M13: 19000 | N13: =J13*M13 -> 57000 | O13: =N13*I13 -> 48450 | P13: 3 wk | Q13: —
A14: 10 | B14: COMPLETE SPARE AIRCRAFT | C14: Fourth airframe, built and flight-tested | D14: Built from this BOM. Domestic sourcing makes this far more affordable than with imported parts. | E14: In-house | F14: — | G14: RFQ | H14: I2 | I14: 0.7 | J14: 1 | K14: 5520 | L14: =J14*K14 -> 5520 | M14: 150000 | N14: =J14*M14 -> 150000 | O14: =N14*I14 -> 105000 | P14: 8 wk | Q14: STRONGLY RECOMMENDED. Rule C1 needs only two flying, but a pre-flight failure on finals day with no spare means flying two and losing a third of your coverage.
A15: CONSUMABLES
A16: 11 | B16: Adhesives | C16: Medium-strength threadlocker, CA thin/thick, structural epoxy | D16: Pidilite and Anabond are strong Indian adhesive manufacturers. | E16: Pidilite / Anabond | F16: open | G16: LOCAL | H16: I1 | I16: 0.9 | J16: 1 | K16: 450 | L16: =J16*K16 -> 450 | M16: 2500 | N16: =J16*M16 -> 2500 | O16: =N16*I16 -> 2250 | P16: 1 wk | Q16: Medium-strength threadlocker on every fastener, so field disassembly stays possible.
A17: 12 | B17: Electrical consumables | C17: Adhesive-lined heat shrink, Kapton, fibreglass tape, lacing cord, zip ties, solder, flux | D17: All locally available. | E17: Local | F17: — | G17: LOCAL | H17: I1 | I17: 0.9 | J17: 1 | K17: 1120 | L17: =J17*K17 -> 1120 | M17: 4000 | N17: =J17*M17 -> 4000 | O17: =N17*I17 -> 3600 | P17: 1 wk | Q17: —
A18: 13 | B18: 3D printer filament | C18: PETG 3 kg, ASA 1 kg, TPU 1 kg | D18: WOL3D and Fila3D extrude in India; resin pellets imported. | E18: WOL3D / Fila3D | F18: open | G18: SPEC OK / RFQ | H18: I2 | I18: 0.5 | J18: 1 | K18: 5000 | L18: =J18*K18 -> 5000 | M18: 7500 | N18: =J18*M18 -> 7500 | O18: =N18*I18 -> 3750 | P18: 1-2 wk | Q18: Magazine and canopy iterations consume more filament than anyone expects.
A19: 14 | B19: Carbon plate stock | C19: 2.5 and 3 mm sheets, 400 x 500 mm, x2 | D19: For plate re-cuts and repair doublers. | E19: Kineco / CTP | F19: open | G19: RFQ | H19: I2 | I19: 0.7 | J19: 2 | K19: 900 | L19: =J19*K19 -> 1800 | M19: 6500 | N19: =J19*M19 -> 13000 | O19: =N19*I19 -> 9100 | P19: 3 wk | Q19: —
A20: 15 | B20: PPE and cleaning | C20: Nitrile gloves, P2 masks, IPA, lint-free wipes, compressed air | D20: Local. | E20: Local | F20: — | G20: LOCAL | H20: I1 | I20: 1 | J20: 1 | K20: 1800 | L20: =J20*K20 -> 1800 | M20: 3000 | N20: =J20*M20 -> 3000 | O20: =N20*I20 -> 3000 | P20: 1 wk | Q20: CF machining, epoxy work, and lens and connector cleaning.
B21: TOTAL | I21: =O21/N21 -> 0.67550451 | L21: =SUM(L5:L20) -> 22475 | N21: =SUM(N5:N20) -> 444196 | O21: =SUM(O5:O20) -> 300056.4

Sheet 06 Software & Data
A1: 06 — SOFTWARE, DATA AND COMPLIANCE
A2: Software is nation-neutral open source. The indigenous asset here is the Indian field dataset.
A3: # | B3: Component | C3: Exact part / model | D3: Key verified specification | E3: Supplier (location) | F3: Link | G3: Status | H3: Tier | I3: Ind % | J3: Qty | K3: Unit g | L3: Total g | M3: Unit ₹ | N3: Ext ₹ | O3: Indian ₹ | P3: Lead | Q3: Why / sizing reference
A4: FLIGHT, AUTONOMY AND PERCEPTION STACK — open source
A5: 1 | B5: Autopilot firmware | C5: PX4 (BSD) — supported natively by the Agam V6X-RT | D5: PX4 under BSD licensing permits adding proprietary features and commercialising the result. ArduPilot is the alternative. | E5: PX4 / Dronecode | F5: open | G5: VERIFIED | H5: I1 | I5: 1 | J5: 1 | K5: 0 | L5: =J5*K5 -> 0 | M5: 0 | N5: =J5*M5 -> 0 | O5: =N5*I5 -> 0 | P5: — | Q5: The Agam FC is FMUv6X-RT standard, so you keep the entire Pixhawk ecosystem while flying Indian hardware.
A6: 2 | B6: Middleware | C6: ROS 2 + Fast DDS, uXRCE-DDS bridge | D6: Open source. | E6: Open Robotics | F6: open | G6: VERIFIED | H6: I1 | I6: 1 | J6: 1 | K6: 0 | L6: =J6*K6 -> 0 | M6: 0 | N6: =J6*M6 -> 0 | O6: =N6*I6 -> 0 | P6: — | Q6: DDS discovery and QoS map well onto a lossy mobile mesh. The Agam boards Ethernet port makes the FC-companion link clean.
A7: 3 | B7: MAVLink router | C7: mavlink-router | D7: Open source. | E7: GitHub | F7: open | G7: VERIFIED | H7: I1 | I7: 1 | J7: 1 | K7: 0 | L7: =J7*K7 -> 0 | M7: 0 | N7: =J7*M7 -> 0 | O7: =N7*I7 -> 0 | P7: — | Q7: Rule C10: multiplexes three unique SYSIDs into ONE ground station process.
A8: 4 | B8: Mesh routing | C8: batman-adv | D8: Layer-2 mesh — the same technology commercial MANET radios run underneath. | E8: Open Mesh | F8: open | G8: VERIFIED | H8: I1 | I8: 1 | J8: 1 | K8: 0 | L8: =J8*K8 -> 0 | M8: 0 | N8: =J8*M8 -> 0 | O8: =N8*I8 -> 0 | P8: — | Q8: —
A9: 5 | B9: Coverage planner | C9: DARP reference implementation | D9: Open source, from the paper authors. | E9: GitHub | F9: open | G9: VERIFIED | H9: I1 | I9: 1 | J9: 1 | K9: 0 | L9: =J9*K9 -> 0 | M9: 0 | N9: =J9*M9 -> 0 | O9: =N9*I9 -> 0 | P9: — | Q9: Equal-area partitioning anchored to a common launch point — exactly the 3.66 m box situation.
A10: 6 | B10: Task allocation | C10: CBBA | D10: Choi, Brunet & How (2009): provable conflict-free convergence over local comms. | E10: Reference implementations on GitHub | F10: — | G10: VERIFIED | H10: I1 | I10: 1 | J10: 1 | K10: 0 | L10: =J10*K10 -> 0 | M10: 0 | N10: =J10*M10 -> 0 | O10: =N10*I10 -> 0 | P10: — | Q10: —
A11: 7 | B11: Small-object detection | C11: SAHI tiled inference | D11: Akyon, Altinuc & Temizel, ICIP 2022. | E11: GitHub | F11: open | G11: VERIFIED | H11: I1 | I11: 1 | J11: 1 | K11: 0 | L11: =J11*K11 -> 0 | M11: 0 | N11: =J11*M11 -> 0 | O11: =N11*I11 -> 0 | P11: — | Q11: Sizing §8.2: recovers the small-object recall that whole-frame resizing destroys.
A12: 8 | B12: Detector | C12: YOLO-class detector | D12: CHECK THE LICENCE. Ultralytics is AGPL, which has implications if you distribute. MMDetection is Apache 2.0 and is the safe choice against unknown NIDAR IP terms. | E12: Open source | F12: open | G12: VERIFIED | H12: I1 | I12: 1 | J12: 1 | K12: 0 | L12: =J12*K12 -> 0 | M12: 0 | N12: =J12*M12 -> 0 | O12: =N12*I12 -> 0 | P12: — | Q12: —
A13: 9 | B13: VEGA toolchain | C13: RISC-V GCC toolchain and BSP | D13: From C-DAC. Younger than ARM equivalents — engage their support early. | E13: C-DAC | F13: open | G13: SPEC OK / RFQ | H13: I1 | I13: 1 | J13: 1 | K13: 0 | L13: =J13*K13 -> 0 | M13: 0 | N13: =J13*M13 -> 0 | O13: =N13*I13 -> 0 | P13: — | Q13: Supports the VEGA co-processor subsystem on tab 01.
A14: DATA — the most important indigenous asset in this programme
A15: 10 | B15: Indian SAR field dataset | C15: >=2,000 annotated frames: our camera, our altitudes, Indian terrain, clothing and light | D15: Built in-house during the Phase 7 field campaign. Cost is logistics — transport, volunteers, mannequins, annotation labour. | E15: In-house | F15: — | G15: LOCAL | H15: I1 | I15: 1 | J15: 1 | K15: 0 | L15: =J15*K15 -> 0 | M15: 60000 | N15: =J15*M15 -> 60000 | O15: =N15*I15 -> 60000 | P15: 12+ wk | Q15: HERIDAL and SARD are European. Their terrain, vegetation, clothing and sun angle do not match an Indian flood plain. Pre-train on them, fine-tune on this.
A16: 11 | B16: Public benchmark datasets | C16: HERIDAL, SARD, WiSARD | D16: Free on request from the European research groups. No Indian equivalent exists. | E16: Research groups | F16: open | G16: SPEC OK / RFQ | H16: I4 | I16: 0 | J16: 1 | K16: 0 | L16: =J16*K16 -> 0 | M16: 0 | N16: =J16*M16 -> 0 | O16: =N16*I16 -> 0 | P16: 2-4 wk | Q16: Reproduce published metrics (YOLOv5L: ~0.90 P / ~0.89 R on HERIDAL) to validate the pipeline before trusting your own data. Consider publishing yours — that alone is a strong NIDAR outcome.
A17: 12 | B17: Annotation tooling | C17: CVAT, self-hosted on Indian cloud | D17: Open source; self-host to avoid per-seat cost across 2,000+ frames. | E17: CVAT | F17: open | G17: VERIFIED | H17: I1 | I17: 1 | J17: 1 | K17: 0 | L17: =J17*K17 -> 0 | M17: 0 | N17: =J17*M17 -> 0 | O17: =N17*I17 -> 0 | P17: — | Q17: —
A18: 13 | B18: Offline map tiles | C18: Cached basemap for the venue and all test sites | D18: ISRO Bhuvan imagery is Indian, free and appropriate for the boundary display required by rule C11. | E18: ISRO Bhuvan | F18: open | G18: VERIFIED | H18: I1 | I18: 1 | J18: 1 | K18: 0 | L18: =J18*K18 -> 0 | M18: 0 | N18: =J18*M18 -> 0 | O18: =N18*I18 -> 0 | P18: 1 wk | Q18: RULE C12 FORBIDS INTERNET — online tiles will not load at the venue. Teams lose points to this every year. Cache in advance.
A19: REGULATORY
A20: 14 | B20: DGCA airspace and operations | C20: Zone check per test site, operator and pilot requirements | D20: Digital Sky portal. | E20: DGCA | F20: open | G20: VERIFIED | H20: I1 | I20: 1 | J20: 1 | K20: 0 | L20: =J20*K20 -> 0 | M20: 5000 | N20: =J20*M20 -> 5000 | O20: =N20*I20 -> 5000 | P20: 2-4 wk | Q20: Development Plan P0 exit gate. Confirm the zone colour BEFORE booking a test campaign.
A21: 15 | B21: WPC / ETA | C21: Equipment Type Approval for every radio flown | D21: Saral Sanchar portal. ADVANTAGE OF INDIAN SUPPLIERS: FxUAV and Indian RF houses design to Indian spectrum rules and can supply ETA documentation; imported radios routinely cannot. | E21: WPC, DoT | F21: open | G21: SPEC OK / RFQ | H21: I1 | I21: 1 | J21: 1 | K21: 0 | L21: =J21*K21 -> 0 | M21: 10000 | N21: =J21*M21 -> 10000 | O21: =N21*I21 -> 10000 | P21: 4-8 wk | Q21: Sizing §12: the BANDS are delicensed (5.825-5.875 GHz for drones, 865-867 MHz for SRDs) but the EQUIPMENT still needs approval.
A22: 16 | B22: Insurance | C22: Third-party liability for flight operations | D22: Indian insurers offer drone liability products. | E22: Indian insurer | F22: — | G22: RFQ | H22: I1 | I22: 1 | J22: 1 | K22: 0 | L22: =J22*K22 -> 0 | M22: 25000 | N22: =J22*M22 -> 25000 | O22: =N22*I22 -> 25000 | P22: 3 wk | Q22: Many test sites and institutions require it before granting access.
B23: TOTAL | I23: =O23/N23 -> 1 | L23: =SUM(L5:L22) -> 0 | N23: =SUM(N5:N22) -> 100000 | O23: =SUM(O5:O22) -> 100000

Sheet 07 Mass & Performance
A1: 07 — MASS ROLLUP AND RULE C2 CHECK
A2: Rule C2: combined all-up weight of ALL deployed drones, including batteries, payloads and every accessory, must not exceed 25 kg.
A4: # | B4: Group | C4: Previous BOM (g) | D4: Verified BOM (g) | E4: Actual measured (g) | F4: Delta | G4: Note
A5: 1 | B5: Propulsion (RD motors, ESCs, props, hubs) | C5: 1032 | D5: 868 | F5: =D5-C5 -> -164 | G5: Reflex Drive parts are LIGHTER: 135 g motor, 28 g ESC, 40 g prop vs 150/48/116 assumed
A6: 2 | B6: Avionics (Agam set, GNSS x2, antennas, RX, VEGA) | C6: 262 | D6: 322 | F6: =D6-C6 -> 60 | G6: Agam Full Set is a single 110 g item incl. carrier and power module
A7: 3 | B7: Compute & perception | C7: 460 | D7: 462 | F7: =D7-C7 -> 2 | G7: Imported SoM + e-con camera + mount + cooling
A8: 4 | B8: Power (6S3P pack + distribution) | C8: 1780 | D8: 1611 | F8: =D8-C8 -> -169 | G8: Power module now carried inside the Agam set
A9: 5 | B9: Structure | C9: 1240 | D9: 1188 | F9: =D9-C9 -> -52 | G9: Unchanged approach; 17 in props shrink the frame slightly
A10: 6 | B10: Communications | C10: 117 | D10: 139 | F10: =D10-C10 -> 22 | G10: FxUAV mesh node + sub-GHz + antennas
A11: 7 | B11: Payload mechanism | C11: 242 | D11: 242 | F11: =D11-C11 -> 0 | G11: Magazine, servos, detents, switches, harness
A12: 8 | B12: Survivor kits (4 x 200 g) | C12: 800 | D12: 800 | F12: =D12-C12 -> 0 | G12: Rule C6 fixes this exactly
B14: MTOW per aircraft (g) | D14: =SUM(D5:D12) -> 5632
B15: Bottom-up line-item total, tab 01 (g) | D15: ='01 Air Vehicle BOM'!L52 -> 5780
B16: Aircraft in fleet | D16: =3 -> 3
B17: FLEET ALL-UP WEIGHT (g) | D17: =D14*D16 -> 16896
B18: Rule C2 limit (g) | D18: =25000 -> 25000
B19: Margin to rule limit (g) | D19: =D18-D17 -> 8104
B20: Margin to rule limit (%) | D20: =(D18-D17)/D18 -> 0.32416
B22: PERFORMANCE AT THIS DESIGN POINT
B23: Propeller | D23: RD 1760, 17 x 6.0 in | G23: Verified part
B24: Disk loading (kg/m2) | D24: 9.4 | G24: 4 x pi x (0.216 m)^2 = 0.586 m2
B25: Hover electrical power (W) | D25: 790 | G25: Momentum theory, FM 0.60, rho 1.150
B26: Hover power from RD bench data (W) | D26: 705 | G26: Interpolated from Reflex Drive published table — model is 12% conservative
B27: Pack usable energy (Wh, 80% DoD) | D27: 234 | G27: 292 Wh x 0.80
B28: Hover endurance, model (min) | D28: 17.7 | G28: 234 Wh / 790 W
B29: Hover endurance, bench-data basis (min) | D29: 19.9 | G29: 234 Wh / 705 W
B30: Design mission (min) | D30: 7.7 | G30: Sizing §9.1 segment budget
B31: Endurance ratio | D31: 2.3 | G31: Target >= 2.0 per the reserve policy
B32: Hover thrust per motor (g) | D32: 1381 | G32: 33% of the 4200 g rating — over-rated, paid for by the mass margin
B33: Max thrust-to-weight | D33: 3.04 | G33: 4 x 4.2 kgf / 5.52 kg
B34: Hover current per motor (A) | D34: 9.2 | G34: vs 35 A continuous rating — very relaxed
B35: Peak pack current at T/W 2 (A) | D35: 99 | G35: vs 135 A pack capability = 37% margin
... B37: Person length at 60 m (px) | D37: 93 | G37: 1.7 m / GSD
B39: WHY THE DESIGN POINT MOVED FROM 18 IN TO 17 IN
B40: The 18 in baseline came from an imported reference motor. Reflex Drive publish bench data for the RD 5008 on their own 17 x 6.0 in propeller, and the RD MI-5008 is rated for 15-18 in props.
B41: Matching the design point to a set of parts that are actually stocked, priced and bench-tested in India is worth more than 1 in of propeller.
B42: Consequence: disk loading rises from 8.7 to 9.4 kg/m2 and hover power from 784 to 790 W — a rounding error. The lighter Reflex Drive parts give most of it back.
B43: The momentum-theory model predicted 790 W; interpolating the manufacturer bench table gives 705 W. The model is 12% conservative, which is the correct direction for a preliminary design.

Sheet 08 Cost Summary
A1: 08 — PROGRAMME COST SUMMARY
