Workbook

Sheet 00 Indigenisation Policy
A1: SUPERSEDED - DO NOT QUOTE THESE FIGURES
A2: The live budget is RescueSwarm_Cost_Study.xlsx (ask 737,829, 7.38 L), generated from docs/proposal/figures/competition_budget.py. This sheet states 264,400 per aircraft against the adopted 157,800 -- 68 % high. First Indian-sourced pass. Superseded by the Verified sheet, then by the adopted configuration.
B6: RescueSwarm — All-Indian Bill of Materials
B7: NIDAR 2.0 (2026-27) Track 1 · every component sourced from an Indian supplier wherever one exists
B9: WHY | C9: NIDAR 2.0 is a MeitY / Drone Federation of India programme under SwaYaan, explicitly aimed at Atmanirbhar Bharat. Track 2 mandates the C-DAC VEGA processor. Track 1 does not mandate indigenous parts, but the programme's stated purpose is to move India "from drone assembly to manufacturing the drone's brain in India" — so an indigenised build is directly aligned with how this competition is judged and funded.
B10: TIER DEFINITIONS | C10: I1 = Indian company, Indian design, Indian manufacture. I2 = Indian design and assembly, imported silicon or raw fibre. I3 = Indian assembly and value-add from imported subassemblies. I4 = no Indian option exists at this capability level; imported, with a declared mitigation.
B11: HONEST HEADLINE | C11: Roughly 90% of line items have a real Indian supplier, and about 68% of PROGRAMME VALUE is Indian, against about 59% of flight-hardware value. The gap is not evasion - it is what happens when Indian-designed boards carry imported silicon. Four things have no Indian option at all: the AI inference SoM (no Indian GPU/NPU at this class), high-drain 21700 cells at 45 A, 802.11/LoRa RF chipsets, and high-current connectors. Tab 09 computes all of this from the line items, so the number you quote to evaluators is one you can defend. Do not transcribe it into a slide and leave it there - re-read tab 09 every time the BOM changes.
B12: WHY 60% AND NOT 90% | C12: An Indian flight controller, GNSS receiver or camera module is Indian design, Indian firmware, Indian manufacture — on an imported MCU or sensor die. This BOM scores those at 60% Indian value rather than 100%. That is a deliberately conservative accounting choice. If you score by supplier, or by design ownership, the number is far higher. State which basis you are using whenever you quote a figure.
B13: THE BEST FINDS | C13: 1. NavIC. Indian GNSS receivers process ISRO's NavIC L1+L5 natively, giving more satellites directly overhead than any imported GPS-only module, faster time-to-first-fix, and a fallback constellation if GPS is jammed. This is an indigenisation choice that makes the system TECHNICALLY BETTER, not just compliant. 2. Flameback Tech ships a 6-12S 60 A ESC that matches the sizing requirement exactly. 3. e-con Systems (Chennai) is a genuine world-class embedded-vision house with global-shutter MIPI modules. 4. Agam Robotics and Zuppa both ship flight-ready Indian autopilots.
B14: THE VEGA ANGLE | C14: C-DAC gives two VEGA processor dev kits to each of the top 100 teams. Even in Track 1, a VEGA-based subsystem — the payload release controller, the mesh node manager, or a redundant failsafe watchdog — is a credible, low-risk way to demonstrate indigenous silicon without putting an unproven RISC-V autopilot on the flight-critical path. Strongly recommended as a scored differentiator.
B15: WHAT CHANGED vs THE IMPORTED BOM | C15: Mass and performance are essentially unchanged: MTOW stays ~5.7 kg and the fleet stays ~17 kg against the 25 kg cap. Cost drops, because Indian motors, ESCs, props, structure and packs undercut T-Motor and Holybro. Lead times improve sharply — 4-6 weeks of import freight becomes 1-3 weeks domestic. The one performance question mark is the RTK/moving-baseline capability of the Indian GNSS options, which must be confirmed before Phase 1 closes.
B16: HOW TO USE | C16: Blue cells are inputs. The Tier column is colour-coded: green = Indian, orange = Indian assembly, red = import with no Indian option. The "Indian Value" column is Ext. Price x Indigenous %, and tab 09 rolls it up into an indigenisation score by mass and by value.
B17: CAUTION ON PRICES | C17: Indicative budgetary estimates only. Indian drone-component pricing is quotation-driven and moves fast; several of these suppliers do not publish list prices. Send an RFQ to every supplier named here in week 1 of Phase 0 — lead time discovery matters more than price discovery.

Sheet 01 Air Vehicle BOM
A1: 01 — AIR VEHICLE BOM, INDIAN SOURCES (per aircraft; x3 for the fleet)
A2: Design point unchanged: quad, 18 in props, 6S3P 21700, MTOW ~5.7 kg, fleet ~17 kg vs the 25 kg cap. Prices indicative INR.
A3: # | B3: Component | C3: Indian part / specification | D3: Indian supplier (location) | E3: Tier | F3: Indig. % | G3: Qty | H3: Unit Mass (g) | I3: Total Mass (g) | J3: Unit Price (INR) | K3: Ext. Price (INR) | L3: Indian Value (INR) | M3: Lead Time | N3: Why this part / sizing reference | O3: Indigenisation gap or action | P3: Source link | Q3: Sourcing note (verified 2026-08-10)
A4: STRUCTURE
A5: 1 | B5: Arm tube | C5: CF round tube 25 x 23 x 400 mm, pultruded/roll-wrapped | D5: Kineco Kaman Composites (Goa) / Composite Technology Park (Bengaluru) | E5: I2 | F5: 0.7 | G5: 4 | H5: 95 | I5: =G5*H5 | J5: 1100 | K5: =G5*J5 | L5: =K5*F5 | M5: 2 wk | N5: Sizing §13: arm root moment 9.4 N·m at T/W=2, 22 MPa vs ~600 MPa UD carbon, SF 28. Joint design, not the tube, is the driver. | O5: Carbon precursor fibre is imported (Epsilon Carbon is commissioning Indian PAN fibre). Weave and pultrusion are Indian. | P5: https://www.kinecokamanindia.com/ | Q5: Fabricator, not a catalogue part. Quote to drawing. Aerospace CF, Pilerne Goa.
A6: 2 | B6: Centre plate | C6: CF sandwich 2.5 mm, CNC cut, top + bottom | D6: Composite Technology Park, Bengaluru / local CNC job shop | E6: I2 | F6: 0.7 | G6: 2 | H6: 155 | I6: =G6*H6 | J6: 3000 | K6: =G6*J6 | L6: =K6*F6 | M6: 3 wk | N6: Rule C3 forbids a market-ready airframe — this must be your own design. | O6: Same fibre-origin caveat as the tubes. | P6: https://www.compositestechnologypark.com/about.html | Q6: Fabricator. CNC-cut CF sandwich to drawing.
A7: 3 | B7: Arm clamp set | C7: Machined Al 6061-T6, 25 mm bore, anti-rotation key | D7: Local precision machine shop (Pune / Coimbatore / Bengaluru belt) | E7: I1 | F7: 1 | G7: 4 | H7: 45 | I7: =G7*H7 | J7: 750 | K7: =G7*J7 | L7: =K7*F7 | M7: 3 wk | N7: Highest-risk mechanical joint. Must not creep under vibration. | O7: None. India has deep small-batch CNC capacity. | P7: Local supply - quote at order, no catalogue part
A8: 4 | B8: Motor mount plate | C8: CF 3 mm, tube saddle, bolt pattern matched to the chosen motor | D8: Local CNC / Composite Technology Park | E8: I2 | F8: 0.7 | G8: 4 | H8: 22 | I8: =G8*H8 | J8: 400 | K8: =G8*J8 | L8: =K8*F8 | M8: 3 wk | N8: Interfaces motor bolt circle to the arm. | O8: — | P8: https://www.compositestechnologypark.com/about.html | Q8: Fabricator. Same source as the centre plate.
A9: 5 | B9: Landing gear leg | C9: CF tube 16 x 300 mm with damped foot | D9: Kineco / local composites | E9: I2 | F9: 0.7 | G9: 4 | H9: 55 | I9: =G9*H9 | J9: 600 | K9: =G9*J9 | L9: =K9*F9 | M9: 2 wk | N9: Absorbs a 1.5 m/s touchdown at 5.7 kg; keeps the magazine clear of ground. | O9: — | P9: https://www.kinecokamanindia.com/ | Q9: Fabricator. Same source as the arm tube.
A10: 6 | B10: Landing foot | C10: TPU printed, 50 mm dia | D10: In-house on an Indian FDM printer | E10: I1 | F10: 1 | G10: 4 | H10: 12 | I10: =G10*H10 | J10: 100 | K10: =G10*J10 | L10: =K10*F10 | M10: — | N10: Damps landing impulse, protects tube ends. | O10: Filament: WOL3D / Fila3D (Indian extruders, imported resin pellets). | P10: In-house / fabricated to drawing - no catalogue part
A11: 7 | B11: Battery tray + strap | C11: CF tray, hook-loop straps, foam pad | D11: In-house + local hardware | E11: I1 | F11: 1 | G11: 1 | H11: 85 | I11: =G11*H11 | J11: 600 | K11: =G11*J11 | L11: =K11*F11 | M11: 1 wk | N11: Retains a ~1.45 kg pack under a 3 g landing load. | O11: — | P11: In-house / fabricated to drawing - no catalogue part
A12: 8 | B12: FC vibration mount | C12: Silicone damping-ball plate, 20-30 shore | D12: Indian rubber/silicone moulder + in-house plate | E12: I1 | F12: 1 | G12: 1 | H12: 18 | I12: =G12*H12 | J12: 350 | K12: =G12*J12 | L12: =K12*F12 | M12: 1 wk | N12: IMU vibration is the leading cause of EKF failure on student builds. | O12: — | P12: Local supply - quote at order, no catalogue part
A13: 9 | B13: Electronics canopy | C13: 3D-printed PETG/ASA shell, vented, splash-tolerant | D13: In-house (Fracktal Works / Divide By Zero printer) | E13: I1 | F13: 1 | G13: 1 | H13: 140 | I13: =G13*H13 | J13: 500 | K13: =G13*J13 | L13: =K13*F13 | M13: 1 wk | N13: Houses compute, mesh node, PDB; accepts the cooling duct. | O13: — | P13: In-house / fabricated to drawing - no catalogue part
A14: 10 | B14: Compute cooling blower | C14: 5 V 40 mm blower + printed duct, live from power-on | D14: Indian fan supplier + in-house duct | E14: I2 | F14: 0.6 | G14: 1 | H14: 32 | I14: =G14*H14 | J14: 400 | K14: =G14*J14 | L14: =K14*F14 | M14: 1 wk | N14: Sizing §14: worst thermal case is the 5-min ground setup with props stopped at 35 °C ambient. | O14: Small DC fans are largely imported; duct and integration are Indian. | P14: Local supply - quote at order, no catalogue part
A15: 11 | B15: Fastener kit | C15: M3 socket cap A2, nyloc, washers, heat inserts (~120 pcs) | D15: Sundram Fasteners (Chennai) / Unbrako India | E15: I1 | F15: 1 | G15: 1 | H15: 110 | I15: =G15*H15 | J15: 800 | K15: =G15*J15 | L15: =K15*F15 | M15: 1 wk | N15: — | O15: None. Indian fastener manufacture is world class. | P15: Local supply - quote at order, no catalogue part | Q15: Sundram Fasteners named in col D but not verified against a catalogue page.
A16: 12 | B16: Standoffs, spacers, grommets | C16: M3 aluminium 10-40 mm, rubber grommets, P-clips | D16: Local hardware | E16: I1 | F16: 1 | G16: 1 | H16: 95 | I16: =G16*H16 | J16: 600 | K16: =G16*J16 | L16: =K16*F16 | M16: 1 wk | N16: Chafe protection where the harness crosses CF — carbon dust is conductive and abrasive. | O16: — | P16: Local supply - quote at order, no catalogue part
A17: PROPULSION
A18: 13 | B18: Motor | C18: BLDC ~150-190 KV, 6-12S, 3.5-4.5 kgf on an 18 in prop | D18: Bharath Components (Gurugram, IoTechWorld) / Mechtex (Faridabad) / Vector Technics | E18: I1 | F18: 0.9 | G18: 4 | H18: 150 | I18: =G18*H18 | J18: 7000 | K18: =G18*J18 | L18: =K18*F18 | M18: 3-4 wk | N18: Sizing §6: need 2.53 kgf/motor at T/W = 2. Bharath quotes 3-5 kg rotor load to 9 kgf; Mechtex custom-winds 1.5-30 kgf. Ask for a custom wind to hit the exact KV. | O18: Magnets and some bearings imported. Winding, stator, housing and assembly are Indian. Request a measured thrust/current curve with the quote. | P18: https://bharathcomponents.com/buy-bldc-motor/ | Q18: 150 KV variant confirmed in catalogue, inside the 150-190 KV spec. Spec sheet: iotechworld.co.in/150kv-bharath-drone-bldc-motor.htm. Subsidiary of IoTechWorld. PRICE NOT PUBLISHED - quote required.
A19: 14 | B19: ESC | C19: 6-12S, 60 A rated, DShot/PWM, telemetry out | D19: Flameback Tech (India) | E19: I1 | F19: 0.8 | G19: 4 | H19: 48 | I19: =G19*H19 | J19: 3000 | K19: =G19*J19 | L19: =K19*F19 | M19: 2-3 wk | N19: Sizing §6: 98 A pack peak = ~25 A per motor. Flameback ships a 6-12S 60 A unit — a direct match to the requirement. | O19: MOSFETs and the MCU are imported silicon; board design, firmware and manufacture are Indian. | P19: https://www.flamebacktech.com/esc | Q19: CAUTION: catalogue advertises 30-45 A. This line specifies 60 A. Confirm a 60 A part exists before ordering.
A20: 15 | B20: Propeller pair | C20: 18 x 6.1 in CF folding, CW + CCW, matched set | D20: S R Aerospace (CSIR-NAL certified) / Bharath Components | E20: I2 | F20: 0.7 | G20: 2 | H20: 116 | I20: =G20*H20 | J20: 2200 | K20: =G20*J20 | L20: =K20*F20 | M20: 3 wk | N20: Sizing §3: hover power scales as 1/D. 18 in is the largest most Indian 5008-class motors are rated for. | O20: CSIR-NAL certification is a genuine quality signal. Fibre imported; layup and moulding Indian. | P20: https://www.sraeros.com/drone-propeller.html | Q20: CSIR-NAL certification claim confirmed on site. 18 in folding variant NOT confirmed in catalogue - confirm size and folding hub.
A21: 16 | B21: Prop adapter / folding hub | C21: Matched to the chosen motor shaft | D21: Supplied with motor / local machining | E21: I1 | F21: 1 | G21: 4 | H21: 14 | I21: =G21*H21 | J21: 500 | K21: =G21*J21 | L21: =K21*F21 | M21: 3 wk | N21: Confirm inclusion before ordering separately. | O21: — | P21: Local supply - quote at order, no catalogue part | Q21: Supplied with motor per col D - confirm inclusion at order.
A22: POWER
A23: 17 | B23: Li-ion cell | C23: 21700 NMC, >=4000 mAh, 40-45 A continuous — 18 off | D23: GODI India (Hyderabad, BIS-certified 21700 NMC) | E23: I3 | F23: 0.4 | G23: 18 | H23: 70 | I23: =G23*H23 | J23: 700 | K23: =G23*J23 | L23: =K23*F23 | M23: 4-6 wk | N23: Sizing §4: 6S3P = ~292 Wh, 13.5 Ah, 135 A burst vs a 98 A peak demand (38% margin). | O23: WEAKEST INDIGENISATION LINK. GODI makes BIS-certified 21700 NMC in India, but confirm a 40 A+ continuous drone-grade variant exists. If not, use an Indian-assembled pack with imported high-drain cells (tier I3) and say so openly — that is still the honest Indian best. | P23: https://evreporter.com/godi-receives-bis-certification-to-sell-li-ion-cells-in-india/ | Q23: BIS certification for 21700 NMC811 confirmed. NO public product page and NO published price - direct quote required. Weakest indigenisation link per col O.
A24: 18 | B24: Pack assembly | C24: 6S3P spot-welded pack, holders, nickel, fish paper, wrap | D24: Revogreen Batteries / Lion Battery / Neuron Energy / CLN Energy | E24: I1 | F24: 0.9 | G24: 1 | H24: 260 | I24: =G24*H24 | J24: 3500 | K24: =G24*J24 | L24: =K24*F24 | M24: 2-3 wk | N24: Indian pack assembly is a mature, competitive industry — unlike Indian cell manufacture. | O24: Have them capacity- and IR-match every cell and give you the data. | P24: https://revogreenbatteries.com/pages/custom-batteries | Q24: Custom pack service confirmed (Pune). Alternate: lionbattery.in/lithium-battery-for-drones/
A25: 19 | B25: BMS / balance board | C25: 6S, per-cell taps, high-current discharge path | D25: Flameback Tech / Indian pack house | E25: I1 | F25: 0.8 | G25: 1 | H25: 45 | I25: =G25*H25 | J25: 1600 | K25: =G25*J25 | L25: =K25*F25 | M25: 2 wk | N25: Balance charging and per-cell monitoring for the GCS SoC display (rule C11). | O25: Protection ICs imported. | P25: https://www.flamebacktech.com/ | Q25: BMS listed in product range; no dedicated 6S product page found.
A26: 20 | B26: Power distribution board | C26: 200 A continuous, 10 AWG pads | D26: Flameback Tech (India) | E26: I1 | F26: 0.8 | G26: 1 | H26: 55 | I26: =G26*H26 | J26: 1800 | K26: =G26*J26 | L26: =K26*F26 | M26: 2 wk | N26: Sizing §6: 98 A peak; 200 A rating gives thermal margin at 45 °C ambient. | O26: — | P26: https://www.flamebacktech.com/ | Q26: PDB listed in product range; 200 A rating not confirmed on a product page.
A27: 21 | B27: Power module / current sensor | C27: Hall-effect 100-200 A, 6-14S, with FC supply | D27: Bharath Components / Flameback Tech | E27: I1 | F27: 0.8 | G27: 1 | H27: 45 | I27: =G27*H27 | J27: 2800 | K27: =G27*J27 | L27: =K27*F27 | M27: 2-3 wk | N27: Drives the low-battery failsafe (rule C16) and the SoC display (rule C11). | O27: Hall sensor IC imported. | P27: https://www.flamebacktech.com/ | Q27: Alternate: bharathcomponents.com. Rating not confirmed on a product page.
A28: 22 | B28: BEC 5 V and 12 V | C28: 5 V 5 A + 12 V 5 A switching, low noise | D28: Flameback Tech / Indian power-electronics house | E28: I1 | F28: 0.8 | G28: 2 | H28: 31 | I28: =G28*H28 | J28: 1000 | K28: =G28*J28 | L28: =K28*F28 | M28: 1-2 wk | N28: Separate rails so a compute brownout cannot take the flight controller down. | O28: Regulator ICs imported. | P28: https://www.flamebacktech.com/ | Q28: Rating not confirmed on a product page.
A29: 23 | B29: Silicone wire and lugs | C29: 10 AWG mains 2 m, 14 AWG motor 6 m, 22-26 AWG signal | D29: Polycab / Finolex / RR Kabel | E29: I1 | F29: 1 | G29: 1 | H29: 205 | I29: =G29*H29 | J29: 1200 | K29: =G29*J29 | L29: =K29*F29 | M29: 1 wk | N29: Sizing §6: 98 A peak drives 10 AWG mains, 14 AWG motor leads. | O29: None. Indian cable manufacture is excellent. | P29: Local supply - quote at order, no catalogue part | Q29: Polycab / Finolex / RR Kabel named in col D; commodity, price at order.
A30: 24 | B30: Connectors | C30: Anti-spark high-current main connector + JST-GH style signal sets | D30: Indian distributor; connector bodies imported | E30: I4 | F30: 0.1 | G30: 1 | H30: 45 | I30: =G30*H30 | J30: 900 | K30: =G30*J30 | L30: =K30*F30 | M30: 1-2 wk | N30: Anti-spark is mandatory at 292 Wh — a plain connector will arc and pit. | O30: NO INDIAN EQUIVALENT for XT90-S / JST-GH class connectors. Small value, unavoidable import. Buy through an Indian distributor. | P30: Local supply - quote at order, no catalogue part | Q30: XT90-S class. Col O already records NO INDIAN EQUIVALENT.
A31: 25 | B31: Buzzer + LED | C31: Piezo + external RGB status LED | D31: Local electronics | E31: I3 | F31: 0.5 | G31: 1 | H31: 12 | I31: =G31*H31 | J31: 250 | K31: =G31*J31 | L31: =K31*F31 | M31: 1 wk | N31: Audible pre-arm and low-battery warning; visible state from 10 m. | O31: — | P31: Local supply - quote at order, no catalogue part
A32: AVIONICS
A33: 26 | B33: Flight controller | C33: Agam Autopilot V6X-RT — Made in India, multi-GNSS, redundant IMU, Ethernet to companion | D33: Agam Robotics (Bengaluru) | E33: I2 | F33: 0.6 | G33: 1 | H33: 50 | I33: =G33*H33 | J33: 26000 | K33: =G33*J33 | L33: =K33*F33 | M33: 3-4 wk | N33: Sizing §1: a proven autopilot handles stabilisation and failsafes; the companion handles autonomy. Ethernet to the companion is a real advantage over UART. | O33: NXP i.MXRT MCU imported; board design, firmware, secure element integration and manufacture are Indian. ALTERNATIVE: Zuppa NavGati (Chennai), which runs on C-DAC-developed PCBs and processors — higher indigenisation, less open-ecosystem tooling. | P33: https://www.agamrobotics.com/agamautopilotv6x-rt | Q33: CONFIRMED. FMUv6X-RT, NXP i.MXRT1176 dual-core - matches col N and col O exactly. Made in India, Bengaluru. Worldwide variant: agamrobotics.com/product-page/agam-autopilot-v6x-rt-worldwide
A34: 27 | B34: VEGA co-processor board | C34: C-DAC VEGA RISC-V dev kit, used as the payload-release and failsafe watchdog controller | D34: C-DAC (MeitY) — 2 kits free to each top-100 team | E34: I1 | F34: 1 | G34: 1 | H34: 60 | I34: =G34*H34 | J34: 0 | K34: =G34*J34 | L34: =K34*F34 | M34: via NIDAR | N34: INDIGENISATION DIFFERENTIATOR. Puts Indian silicon on the aircraft without risking the flight-critical path. Judges will notice. | O34: Fully indigenous. Scope it as a non-flight-critical subsystem with a hardware bypass. | P34: https://vegaprocessors.in/ | Q34: C-DAC / MeitY DIR-V programme confirmed. SoC docs: cdac-vega.gitlab.io/socoverview/microprocessors.html. Free-kit route via NIDAR is an ASSUMPTION - confirm with organisers.
A35: 28 | B35: GNSS primary | C35: AeroNav-series NavIC L1+L5 dual-band receiver with compass | D35: Teravolt Labs (India) | E35: I2 | F35: 0.6 | G35: 1 | H35: 55 | I35: =G35*H35 | J35: 18000 | K35: =G35*J35 | L35: =K35*F35 | M35: 3 wk | N35: Sizing §11: GNSS is the dominant geotag error term. NavIC adds satellites directly overhead and survives a GPS outage. | O35: ACTION: confirm RTK and moving-baseline heading support before Phase 1 closes. If Teravolt does not support it, evaluate Accord Software & Systems (Bengaluru) or Elena Geo Systems. Sizing §11 shows RTK is worth ~1.4 m of geotag accuracy. | P35: https://www.teravolt.in/product-page/aeronav-1-dual-band-gnss | Q35: PARTIAL. NavIC L1+L5 and BMM350 magnetometer confirmed. RTK AND MOVING-BASELINE ARE NOT CLAIMED ON THE PRODUCT PAGE - this is the open action in col O and it gates geotag case C. ArduPilot driver: ardupilot.org/copter/docs/common-AeroNav-1.html. Company is Chandigarh, not as implied by col D.
A36: 29 | B36: GNSS secondary (heading) | C36: Second receiver for moving-baseline yaw | D36: Teravolt Labs / Accord Software (Bengaluru) | E36: I2 | F36: 0.6 | G36: 1 | H36: 50 | I36: =G36*H36 | J36: 17000 | K36: =G36*J36 | L36: =K36*F36 | M36: 3 wk | N36: Sizing §11 case C: once RTK removes GNSS error, attitude leads. Dual-antenna heading removes magnetometer error near a 100 A bus. | O36: Same RTK confirmation action as above. | P36: https://www.teravolt.in/product-page/aeronav-1-dual-band-gnss | Q36: Same part and the same unconfirmed RTK/moving-baseline caveat as the primary.
A37: 30 | B37: GNSS antenna | C37: Multi-band L1/L5 helical/patch with ground plane | D37: Supplied with the Indian receiver kits | E37: I2 | F37: 0.6 | G37: 2 | H37: 35 | I37: =G37*H37 | J37: 3200 | K37: =G37*J37 | L37: =K37*F37 | M37: 3 wk | N37: Mount >=150 mm above the power bus and away from the compute module. | O37: — | P37: Local supply - quote at order, no catalogue part | Q37: Supplied with the receiver per col D - confirm inclusion.
A38: 31 | B38: RC receiver | C38: ExpressLRS 2.4 GHz receiver, safety-pilot link | D38: Zerodrag (India) | E38: I3 | F38: 0.5 | G38: 1 | H38: 12 | I38: =G38*H38 | J38: 2000 | K38: =G38*J38 | L38: =K38*F38 | M38: 1 wk | N38: Not used in the scored mission. Present so a human can take control in an emergency — a range-safety requirement. | O38: ELRS silicon imported; Zerodrag manufactures in India. | P38: https://zerodrag.in/products/express-lrs-receiver | Q38: CONFIRMED. Nexus1 ELRS 2.4 GHz, diversity, made in India, 12-month warranty.
A39: 32 | B39: Safety switch, LED, SD cards | C39: Arming interlock + 2 x 32 GB industrial microSD | D39: Indian distributor / Agam accessories | E39: I3 | F39: 0.4 | G39: 1 | H39: 22 | I39: =G39*H39 | J39: 1400 | K39: =G39*J39 | L39: =K39*F39 | M39: 1-2 wk | N39: Every flight must be logged (Development Plan §1.5). | O39: NAND flash has no Indian source. | P39: Local supply - quote at order, no catalogue part
A40: COMPUTE AND PERCEPTION
...

Sheet 02 Payload & Kits
A1: 02 — PAYLOAD, KITS AND GROUND-TRUTH TARGETS (fleet quantities)
A2: Near-100% indigenous — this whole category is local fabrication and consumables.
A3: # | B3: Component | C3: Indian part / specification | D3: Indian supplier (location) | E3: Tier | F3: Indig. % | G3: Qty | H3: Unit Mass (g) | I3: Total Mass (g) | J3: Unit Price (INR) | K3: Ext. Price (INR) | L3: Indian Value (INR) | M3: Lead Time | N3: Why this part / sizing reference | O3: Indigenisation gap or action
A4: SURVIVOR KITS — rule C6: exactly 200 g, 200 x 100 x 50 mm rigid box
A5: 1 | B5: Kit outer box | C5: Rigid ABS / corrugated PP, hi-vis orange, sealed | D5: Local injection moulder / packaging fabricator | E5: I1 | F5: 1 | G5: 14 | H5: 55 | I5: =G5*H5 | J5: 150 | K5: =G5*J5 | L5: =K5*F5 | M5: 2 wk | N5: Rule C6 fixes dimensions. 14 built for 12 flown plus 2 spares. Sizing §10: must survive 9.7 m/s impact. | O5: None. Indian moulding capacity is deep and cheap.
A6: 2 | B6: Impact padding | C6: Closed-cell EVA foam liner, 8 mm | D6: Local foam converter | E6: I1 | F6: 1 | G6: 14 | H6: 18 | I6: =G6*H6 | J6: 50 | K6: =G6*J6 | L6: =K6*F6 | M6: 1 wk | N6: Sizing §10: 9.7 m/s impact from a 6 m release. | O6: —
A7: 3 | B7: Kit contents | C7: Bandage, ORS sachets, whistle, glow stick, emergency blanket, water pouch | D7: Indian pharmacy / local (ORS is an Indian staple product) | E7: I1 | F7: 1 | G7: 14 | H7: 110 | I7: =G7*H7 | J7: 180 | K7: =G7*J7 | L7: =K7*F7 | M7: 1 wk | N7: Contents plus box plus padding must total exactly 200.0 g. Weigh and record every kit. | O7: None.
A8: 4 | B8: Trim ballast | C8: Steel shot in a sealed sachet to bring each kit to 200.0 g | D8: Local | E8: I1 | F8: 1 | G8: 14 | H8: 17 | I8: =G8*H8 | J8: 20 | K8: =G8*J8 | L8: =K8*F8 | M8: 1 wk | N8: Rule C6 is exact. Use a 0.1 g scale. | O8: —
A9: 5 | B9: Test dummy kits | C9: Ballast-only boxes, same mass and dimensions | D9: In-house | E9: I1 | F9: 1 | G9: 24 | H9: 200 | I9: =G9*H9 | J9: 120 | K9: =G9*J9 | L9: =K9*F9 | M9: 1 wk | N9: Development Plan P8 needs >=30 instrumented drops. Do not consume real kits in testing. | O9: —
A10: GROUND-TRUTH TARGETS for the P7 detection and P8 delivery campaigns
A11: 6 | B11: Survivor mannequin | C11: Human-size, articulable to supine/prone/seated, weather-tolerant | D11: Local mannequin / fibreglass fabricator | E11: I1 | F11: 1 | G11: 6 | H11: 4000 | I11: =G11*H11 | J11: 3000 | K11: =G11*J11 | L11: =K11*F11 | M11: 3 wk | N11: Development Plan P7: SAR targets are ~0.1% of frame area in atypical postures. Train and test against the same. | O11: IMPORTANT: dress them in clothing typical of an Indian flood-affected population, not Western SAR-dataset clothing. That distribution shift is exactly what HERIDAL/SARD will not teach your model.
A12: 7 | B12: Target clothing sets | C12: Varied contrast, including low-contrast earth tones and saris/kurtas | D12: Local | E12: I1 | F12: 1 | G12: 6 | H12: 400 | I12: =G12*H12 | J12: 500 | K12: =G12*J12 | L12: =K12*F12 | M12: 1 wk | N12: Prevents the model learning "bright clothing" as the detection cue. | O12: —
A13: 8 | B13: Drop-zone target mat | C13: 5 m concentric-ring mat with a surveyed centre | D13: Local fabricator | E13: I1 | F13: 1 | G13: 3 | H13: 2500 | I13: =G13*H13 | J13: 2200 | K13: =G13*J13 | L13: =K13*F13 | M13: 2 wk | N13: Measures delivery CEP directly (Sizing §10 target <=3 m). | O13: —
A14: 9 | B14: Surveyed calibration markers | C14: 600 mm checkerboard / AprilTag panels, RTK-surveyed positions | D14: Print + mount, in-house | E14: I1 | F14: 1 | G14: 12 | H14: 300 | I14: =G14*H14 | J14: 400 | K14: =G14*J14 | L14: =K14*F14 | M14: 1 wk | N14: Sizing §11: boresight and lever-arm calibration corrects SYSTEMATIC error that averaging cannot. | O14: —
B15: TOTAL | F15: =L15/K15 | I15: =SUM(I5:I14) | K15: =SUM(K5:K14) | L15: =SUM(L5:L14)

Sheet 03 Ground Segment
A1: 03 — GROUND SEGMENT AND FIELD INFRASTRUCTURE, INDIAN SOURCES
A2: Rule C10 allows exactly one Ground Control Station. Indian power, solar, safety and field infrastructure are strong; computing hardware is the weak spot.
A3: # | B3: Component | C3: Indian part / specification | D3: Indian supplier (location) | E3: Tier | F3: Indig. % | G3: Qty | H3: Unit Mass (g) | I3: Total Mass (g) | J3: Unit Price (INR) | K3: Ext. Price (INR) | L3: Indian Value (INR) | M3: Lead Time | N3: Why this part / sizing reference | O3: Indigenisation gap or action
A4: GROUND CONTROL STATION
A5: 1 | B5: GCS laptop | C5: 16 GB RAM, 1 TB SSD, hardware H.264 decode | D5: Indian-manufactured unit (Dixon / VVDN / Syrma-built brands, or HCL) | E5: I3 | F5: 0.25 | G5: 1 | H5: 2200 | I5: =G5*H5 | J5: 85000 | K5: =G5*J5 | L5: =K5*F5 | M5: 2 wk | N5: Runs the custom GCS, MAVLink router, mesh node and video decode. Rule C10 permits exactly ONE GCS. The load is 3 x 720p H.264 WebRTC decode plus a Python GCS -- any modern iGPU does that. Detector training moved to Indian GPU cloud (tab 06 line 13), so no machine here needs a discrete GPU. | O5: Assembled in India under PLI; CPU/GPU/memory imported. There is no Indian x86 or discrete GPU.
A6: 2 | B6: Backup laptop | C6: Cloned image, ready to swap; same software, lower spec | D6: Same | E6: I3 | F6: 0.25 | G6: 1 | H6: 2200 | I6: =G6*H6 | J6: 55000 | K6: =G6*J6 | L6: =K6*F6 | M6: 2 wk | N6: A GCS failure ends the mission. Clone it and keep it powered in the field box. It has to run the same software, not match the same benchmark -- a second full-price machine buys nothing the swap does not already give. | O6: —
A7: 3 | B7: Sun hood + observer monitor | C7: Laptop hood plus a 15 in portable monitor for evaluators | D7: Local fabricator + Indian distributor | E7: I3 | F7: 0.5 | G7: 1 | H7: 1500 | I7: =G7*H7 | J7: 12000 | K7: =G7*J7 | L7: =K7*F7 | M7: 2 wk | N7: You cannot read a laptop screen in Indian midday sun (rule C15: daylight outdoors). Judges watch this screen. Hood is locally fabricated; the monitor is a commodity 15 in portable panel. | O7: Hood is locally made; panel imported.
A8: MESH GROUND NODE
A9: 4 | B9: Ground mesh node | C9: Same radio as the air nodes, weatherproof enclosure | D9: FxUAV Technologies / Indian SBC house | E9: I3 | F9: 0.4 | G9: 1 | H9: 450 | I9: =G9*H9 | J9: 8000 | K9: =G9*J9 | L9: =K9*F9 | M9: 3 wk | N9: Sizing §12. | O9: Wi-Fi chipset imported.
A10: 5 | B10: Sector antenna | C10: 9 dBi, 5.15-5.9 GHz, 90-120° sector | D10: Indian RF antenna manufacturer | E10: I2 | F10: 0.7 | G10: 2 | H10: 320 | I10: =G10*H10 | J10: 3800 | K10: =G10*J10 | L10: =K10*F10 | M10: 2 wk | N10: Sizing §12: 9 dBi at the GCS gives 33 dBm EIRP (legal) and 13.7 dB margin at 600 m. | O10: Well within Indian capability.
A11: 6 | B11: Antenna mast | C11: 2 m telescopic mast, tripod and guys | D11: Indian mast/tripod maker | E11: I1 | F11: 1 | G11: 1 | H11: 3500 | I11: =G11*H11 | J11: 5500 | K11: =G11*J11 | L11: =K11*F11 | M11: 2 wk | N11: Sizing §12: elevating the ground antenna is the cheapest link-margin gain available. | O11: None.
A12: 7 | B12: Low-loss coax | C12: LMR-240 equivalent, 3 m, RP-SMA | D12: Indian RF cable assembler | E12: I2 | F12: 0.6 | G12: 2 | H12: 220 | I12: =G12*H12 | J12: 1500 | K12: =G12*J12 | L12: =K12*F12 | M12: 2 wk | N12: At 5.8 GHz cheap coax costs ~1 dB/m. Keep runs short. | O12: —
A13: RTK BASE STATION — CONFIRMED PERMITTED by the organisers. Worth ~82 delivery points. May NOT be positioned or started before the 5-minute setup window (SYS-42).
A14: 8 | B14: RTK base receiver | C14: NavIC + GNSS base with survey-grade antenna | D14: Accord Software & Systems (Bengaluru) / Elena Geo Systems / Teravolt Labs | E14: I2 | F14: 0.6 | G14: 1 | H14: 600 | I14: =G14*H14 | J14: 38000 | K14: =G14*J14 | L14: =K14*F14 | M14: 4 wk | N14: Sizing §11: takes geotag CEP50 from ~2.5 m to ~1.1 m. Corrections travel on the team local link, not the internet. | O14: Accord has decades of Indian GNSS receiver heritage including NavIC. Confirm base-mode RTCM output and rover compatibility with the airborne receiver you choose.
A15: 9 | B15: Survey tripod + tribrach | C15: Fixed-height survey tripod | D15: Indian survey equipment supplier | E15: I1 | F15: 1 | G15: 1 | H15: 3500 | I15: =G15*H15 | J15: 9500 | K15: =G15*J15 | L15: =K15*F15 | M15: 2 wk | N15: Base position must be stable and repeatable across the campaign. | O15: —
A16: 10 | B16: Base-to-rover link | C16: 865-867 MHz RTCM broadcast | D16: FxUAV / Indian module house | E16: I3 | F16: 0.4 | G16: 1 | H16: 150 | I16: =G16*H16 | J16: 7500 | K16: =G16*J16 | L16: =K16*F16 | M16: 3 wk | N16: Team-owned local link, compliant with rule C12. | O16: —
A17: FIELD POWER AND INFRASTRUCTURE
A18: 11 | B18: Portable power station | C18: 1.2 kWh LiFePO4 with AC output | D18: Okaya / Luminous / Exide / Servotech (all Indian) | E18: I1 | F18: 0.8 | G18: 1 | H18: 18000 | I18: =G18*H18 | J18: 55000 | K18: =G18*J18 | L18: =K18*F18 | M18: 2 wk | N18: Sized on the actual energy: 3 x 292 Wh packs at ~85 % charge efficiency is ~1.03 kWh, plus GCS and instruments. 1.2 kWh covers a sortie set and recharges off mains or a vehicle between them; 2 kWh was carrying a reserve nothing asked for. | O18: Indian pack assembly and inverter; cells imported. Strong Indian option here.
A19: 12 | B19: Solar panel | C19: 200 W folding | D19: Waaree / Vikram Solar / Adani Solar (Indian) | E19: I1 | F19: 0.9 | G19: 0 | H19: 6000 | I19: =G19*H19 | J19: 15000 | K19: =G19*J19 | L19: =K19*F19 | M19: 2 wk | N19: CUT. The BOM's own note called this optional, and 200 W of folding PV needs ~7 h of ideal sun to refill 1.2 kWh -- that is not an operational answer for a test day. Mains, a vehicle inverter or a hired genset covers remote P7 sites. Reinstate at INR 15,000 if a site has neither. | O19: India has genuine world-scale PV manufacture.
A20: 13 | B20: Field table, canopy, weights | C20: Folding table, 3x3 m canopy | D20: Local | E20: I1 | F20: 1 | G20: 1 | H20: 12000 | I20: =G20*H20 | J20: 8000 | K20: =G20*J20 | L20: =K20*F20 | M20: 1 wk | N20: Shade for the GCS and a stable surface. | O20: —
A21: 14 | B21: Landing pad | C21: 3.66 x 3.66 m marked pad, pegged, with sequenced position markers | D21: Local fabricator | E21: I1 | F21: 1 | G21: 1 | H21: 4500 | I21: =G21*H21 | J21: 6500 | K21: =G21*J21 | L21: =K21*F21 | M21: 2 wk | N21: Rule C14 fixes this at 12 ft. Practise every launch and recovery on an exactly-sized pad from day one. | O21: —
A22: 15 | B22: Anemometer + windsock | C22: Handheld logging anemometer, 600 mm windsock | D22: Indian instrument supplier (e.g. HTC / Metravi) | E22: I3 | F22: 0.4 | G22: 1 | H22: 400 | I22: =G22*H22 | J22: 4000 | K22: =G22*J22 | L22: =K22*F22 | M22: 1 wk | N22: Sizing §9.2: the wind policy is constant GROUNDSPEED. You must measure wind to verify it and to log conditions per sortie. | O22: Sensor imported, assembly Indian.
A23: 16 | B23: Equipment cases | C23: Wheeled hard cases with custom foam, 3 aircraft + ground kit | D23: Local case maker + local foam cutting (Indian case maker if quoted competitively) | E23: I1 | F23: 0.9 | G23: 4 | H23: 7000 | I23: =G23*H23 | J23: 11000 | K23: =G23*J23 | L23: =K23*F23 | M23: 3 wk | N23: Sizing S15: the 5-minute setup starts with getting aircraft out of cases. Foam layout is part of the choreography -- which is a function of the foam, not the shell. Locally fabricated wheeled cases meet it. QUOTE REQUIRED. | O23: —
A24: SAFETY AND COMPLIANCE
A25: 17 | B25: Li-ion safe bags | C25: Fire-resistant charging/storage bags | D25: Local supplier | E25: I2 | F25: 0.6 | G25: 6 | H25: 300 | I25: =G25*H25 | J25: 1000 | K25: =G25*J25 | L25: =K25*F25 | M25: 1 wk | N25: Non-negotiable with 292 Wh packs in a student lab. | O25: —
A26: 18 | B26: Fire extinguisher + sand | C26: Lithium-rated extinguisher, dry sand bucket | D26: Indian extinguisher manufacturer | E26: I1 | F26: 1 | G26: 2 | H26: 5000 | I26: =G26*H26 | J26: 5500 | K26: =G26*J26 | L26: =K26*F26 | M26: 1 wk | N26: Water and CO2 will not stop a lithium fire. | O26: None. Indian fire-safety manufacture is strong.
A27: 19 | B27: First aid kit | C27: Trauma-capable, laceration dressings | D27: Local pharmacy | E27: I1 | F27: 1 | G27: 1 | H27: 1500 | I27: =G27*H27 | J27: 3000 | K27: =G27*J27 | L27: =K27*F27 | M27: 1 wk | N27: 18 in carbon props cause serious injuries. Have this before the first spin-up. | O27: —
A28: 20 | B28: Hi-vis vests + eye protection | C28: For 2 setup crew plus safety officer | D28: Local safety supplier | E28: I1 | F28: 1 | G28: 5 | H28: 200 | I28: =G28*H28 | J28: 500 | K28: =G28*J28 | L28: =K28*F28 | M28: 1 wk | N28: Range discipline; also signals professionalism to evaluators. | O28: —
A29: 21 | B29: Safety-pilot transmitter | C29: ELRS/2.4 GHz TX matched to the aircraft receivers | D29: Zerodrag (India) / Indian distributor | E29: I3 | F29: 0.4 | G29: 1 | H29: 700 | I29: =G29*H29 | J29: 16000 | K29: =G29*J29 | L29: =K29*F29 | M29: 2 wk | N29: Manual override during testing; unused in the scored run. | O29: —
A30: 22 | B30: Barrier tape and cones | C30: 100 m tape, 8 cones | D30: Local | E30: I1 | F30: 1 | G30: 1 | H30: 2000 | I30: =G30*H30 | J30: 1200 | K30: =G30*J30 | L30: =K30*F30 | M30: 1 wk | N30: Defines the flight area and keeps spectators out of the descent cone. | O30: —
B31: TOTAL | F31: =L31/K31 | I31: =SUM(I5:I30) | K31: =SUM(K5:K30) | L31: =SUM(L5:L30)

Sheet 04 Test & Lab Equipment
A1: 04 — TEST, LAB AND CALIBRATION EQUIPMENT, INDIAN SOURCES
A2: India is strong in instruments, balances, hand tools and 3D printers. Weak in hobby chargers and cell testers — outsource pack building instead.
A3: # | B3: Component | C3: Indian part / specification | D3: Indian supplier (location) | E3: Tier | F3: Indig. % | G3: Qty | H3: Unit Mass (g) | I3: Total Mass (g) | J3: Unit Price (INR) | K3: Ext. Price (INR) | L3: Indian Value (INR) | M3: Lead Time | N3: Why this part / sizing reference | O3: Indigenisation gap or action
A4: PROPULSION AND POWER CHARACTERISATION — retires assumptions A1, A2, A4, A5 (Sizing §16)
A5: 1 | B5: Thrust stand | C5: Motor/prop test stand: thrust + torque + RPM + electrical power, to 5 kgf | D5: Build in-house around Indian load cells (Sensocon, Instrumentation Ltd Kota) + Indian DAQ | E5: I1 | F5: 0.85 | G5: 1 | H5: 3000 | I5: =G5*H5 | J5: 45000 | K5: =G5*J5 | L5: =K5*F5 | M5: 4 wk | N5: Sizing §16 A1: figure of merit is assumed 0.60 and is the LARGEST uncertainty in the power model (±0.1 gives ∓17% hover power). This instrument replaces the assumption with data. | O5: Building it in India costs a third of an imported RCbenchmark and is itself a legitimate engineering deliverable for the technical report. Indian load cells are good.
A6: 2 | B6: Power analyser | C6: Inline watt meter, 130 A, logging | D6: Meco Instruments (Mumbai) / Indian distributor | E6: I2 | F6: 0.5 | G6: 1 | H6: 180 | I6: =G6*H6 | J6: 4000 | K6: =G6*J6 | L6: =K6*F6 | M6: 2 wk | N6: Measures real hover current against the 36 A predicted (Sizing S6). One instrument, used on one thrust stand, by one person. | O6: Meco is a genuine Indian instrument manufacturer.
A7: 3 | B7: Battery charger | C7: 6S, 400-600 W, balance charging, 2 units | D7: Indian drone charger supplier (Bharath Components / IoTechWorld) or Indian bench PSU + BMS CC/CV | E7: I3 | F7: 0.4 | G7: 2 | H7: 1200 | I7: =G7*H7 | J7: 14000 | K7: =G7*J7 | L7: =K7*F7 | M7: 3 wk | N7: A 292 Wh pack at 1C needs ~300 W. Two chargers keep a test day moving. The 1000 W class was buying headroom above 1C that the cells should not see anyway -- 400-600 W each is the requirement. | O7: GAP: hobby-grade balance chargers are almost entirely imported. Agri-drone charger suppliers in India are the closest domestic option — ask them for a 6S variant.
A8: 4 | B8: Charger PSU | C8: 24 V 40 A bench/server supply (960 W, feeds both chargers) | D8: Aplab / Scientific Mes-Technik (Indian) | E8: I1 | F8: 0.8 | G8: 1 | H8: 1500 | I8: =G8*H8 | J8: 8000 | K8: =G8*J8 | L8: =K8*F8 | M8: 2 wk | N8: Feeds the chargers at rated power. Two 600 W chargers at 1C draw ~600 W combined, so one 960 W supply carries both with margin. | O8: Aplab is a long-standing Indian instrument maker.
A9: 5 | B9: Cell tester | C9: 21700 capacity and internal-resistance tester, 8-bay | D9: Indian distributor; or build around an Indian DAQ | E9: I4 | F9: 0.2 | G9: 1 | H9: 900 | I9: =G9*H9 | J9: 13000 | K9: =G9*J9 | L9: =K9*F9 | M9: 3 wk | N9: Every cell capacity- and IR-matched before pack assembly. Counterfeit 21700s are widespread. | O9: If you buy from an Indian pack house, contract them to do the matching and hand you the data — that removes the need to own this.
A10: 6 | B10: Spot welder | C10: 21700-capable battery spot welder | D10: Indian fabricator / Indian welding supplier | E10: I3 | F10: 0.4 | G10: 0 | H10: 3500 | I10: =G10*H10 | J10: 15000 | K10: =G10*J10 | L10: =K10*F10 | M10: 3 wk | N10: CUT. Tab 01 line 18 buys pack assembly as a service from an Indian pack house, which spot-welds. Owning a welder to do in-house what is already being paid for is a duplicate buy. Reinstate at INR 15,000 only if pack assembly is brought in-house. | O10: Or outsource pack building entirely to an Indian pack house — recommended.
A11: MEASUREMENT AND CALIBRATION
A12: 7 | B12: Precision scale | C12: 0.1 g resolution, 5 kg capacity | D12: Aczet (Mumbai) / Contech (Indian balance manufacturers) | E12: I1 | F12: 0.9 | G12: 1 | H12: 2000 | I12: =G12*H12 | J12: 7000 | K12: =G12*J12 | L12: =K12*F12 | M12: 1 wk | N12: Every part weighed on arrival; kits trimmed to exactly 200 g (rule C6). | O12: Aczet and Contech are real Indian balance manufacturers.
A13: 8 | B13: Hanging scale — FLEET WEIGH-IN | C13: Calibrated, 50 kg, 10 g resolution | D13: Contech / Essae-Teraoka (Bengaluru) | E13: I1 | F13: 0.9 | G13: 1 | H13: 400 | I13: =G13*H13 | J13: 4000 | K13: =G13*J13 | L13: =K13*F13 | M13: 1 wk | N13: Rule C2 is a pass/fail check at 25 kg. Own a calibrated scale; do not discover a discrepancy at the venue. | O13: None.
A14: 9 | B14: Calipers and micrometer | C14: 150 mm digital calipers, 0-25 mm micrometer | D14: Baker Gauges India (Pune) / Mitutoyo South Asia | E14: I1 | F14: 0.8 | G14: 1 | H14: 300 | I14: =G14*H14 | J14: 3200 | K14: =G14*J14 | L14: =K14*F14 | M14: 1 wk | N14: CF tube OD/ID verification. One set; this is a bench measurement, not two parallel stations. | O14: Baker Gauges is an Indian precision metrology manufacturer.
A15: 10 | B15: Torque driver | C15: 1-6 N·m adjustable with hex/Torx bits | D15: Groz / Taparia (Indian) or Indian distributor | E15: I2 | F15: 0.6 | G15: 1 | H15: 400 | I15: =G15*H15 | J15: 6500 | K15: =G15*J15 | L15: =K15*F15 | M15: 2 wk | N15: Motor and arm-clamp bolts must be torqued to spec. Under-torqued clamps creep; over-torqued crush CF. | O15: —
A16: 11 | B16: Propeller balancer | C16: Magnetic balancer for 18 in props | D16: Local fabricator / Indian distributor | E16: I2 | F16: 0.6 | G16: 1 | H16: 600 | I16: =G16*H16 | J16: 3000 | K16: =G16*J16 | L16: =K16*F16 | M16: 2 wk | N16: Sizing §13: vibration fatigue is the real structural driver, and unbalanced props are the main source. | O16: Easily made in-house.
A17: 12 | B17: Camera calibration target | C17: A2 checkerboard on a rigid flat board + AprilTag set | D17: Indian printer + local rigid mounting | E17: I1 | F17: 1 | G17: 1 | H17: 900 | I17: =G17*H17 | J17: 3000 | K17: =G17*J17 | L17: =K17*F17 | M17: 1 wk | N17: Sizing §11: intrinsics AND the boresight extrinsic. Skipping the second leaves a 3-5 m systematic geotag bias. | O17: Flatness matters — mount on aluminium composite, not paper.
A18: BENCH AND FABRICATION
A19: 13 | B19: Soldering station | C19: Temperature-controlled 80-100 W with a large chisel tip | D19: Soldron (Indian) / Metcal India | E19: I1 | F19: 0.9 | G19: 1 | H19: 2500 | I19: =G19*H19 | J19: 9000 | K19: =G19*J19 | L19: =K19*F19 | M19: 2 wk | N19: 10 AWG to a high-current connector needs real thermal mass. A 30 W iron gives cold joints and in-flight failures. | O19: Soldron is an established Indian brand.
A20: 14 | B20: Hot air rework + heat gun | C20: SMD rework and heat shrink | D20: Indian distributor | E20: I3 | F20: 0.4 | G20: 1 | H20: 3000 | I20: =G20*H20 | J20: 6500 | K20: =G20*J20 | L20: =K20*F20 | M20: 2 wk | N20: — | O20: —
A21: 15 | B21: Bench power supply | C21: 0-30 V 10 A, current-limited | D21: Aplab / Scientific Mes-Technik (Indian) | E21: I1 | F21: 0.8 | G21: 1 | H21: 4000 | I21: =G21*H21 | J21: 8500 | K21: =G21*J21 | L21: =K21*F21 | M21: 2 wk | N21: Bring up new boards current-limited. Saves at least one compute module. | O21: —
A22: 16 | B22: Multimeter | C22: True-RMS, 10 A range | D22: Meco Instruments (Mumbai) | E22: I1 | F22: 0.8 | G22: 2 | H22: 350 | I22: =G22*H22 | J22: 4000 | K22: =G22*J22 | L22: =K22*F22 | M22: 1 wk | N22: — | O22: Meco manufactures in India.
A23: 17 | B23: 3D printer | C23: FDM, 250 mm bed, PETG/ASA capable | D23: Fracktal Works (Bengaluru) / Divide By Zero (Mumbai) / AHA 3D (Jaipur) | E23: I1 | F23: 0.8 | G23: 1 | H23: 12000 | I23: =G23*H23 | J23: 50000 | K23: =G23*J23 | L23: =K23*F23 | M23: 3 wk | N23: Canopy, magazine, ducts, jigs, and dozens of release-mechanism iterations. Owning one beats outsourcing. | O23: Genuine Indian 3D printer manufacturers with local support.
A24: 18 | B24: Hand tool set | C24: Hex, Torx, pliers, strippers, flush cutters, tweezers | D24: Taparia / Groz / Jhalani (Indian) | E24: I1 | F24: 1 | G24: 1 | H24: 2500 | I24: =G24*H24 | J24: 7500 | K24: =G24*J24 | L24: =K24*F24 | M24: 1 wk | N24: — | O24: Indian hand tools are excellent and cheap.
A25: 19 | B25: Rotary tool + CF dust extraction | C25: Rotary tool, diamond discs, extraction, P2 masks | D25: Indian distributor + local extraction rig | E25: I2 | F25: 0.5 | G25: 1 | H25: 1800 | I25: =G25*H25 | J25: 8500 | K25: =G25*J25 | L25: =K25*F25 | M25: 2 wk | N25: CARBON DUST IS A RESPIRATORY AND ELECTRICAL HAZARD. Extraction and masks are not optional. | O25: —
A26: SIMULATION AND DEVELOPMENT
A27: 20 | B27: Dev workstation / GPU | C27: RTX-class GPU, 32 GB RAM, for model training and SITL | D27: Indian-assembled workstation (VVDN / Dixon / local integrator) | E27: I3 | F27: 0.2 | G27: 0 | H27: 0 | I27: =G27*H27 | J27: 165000 | K27: =G27*J27 | L27: =K27*F27 | M27: 3 wk | N27: CUT -- the largest single line in the programme. Detector training and the 200-run Monte Carlo move to Indian GPU cloud (tab 06 line 13, raised to INR 75,000). Cloud is cheaper than the capex, and MORE indigenous: E2E / Yotta / NxtGen score I1 at 0.9 against I3 at 0.2 for an assembled RTX box. Annotation (CVAT) and SITL run on the two GCS laptops. Reinstate at INR 165,000 only if sustained offline training becomes the bottleneck. | O27: GPU silicon imported. Alternative: Indian GPU cloud (E2E Networks, Yotta, NxtGen) — a genuinely indigenous compute option for TRAINING, and NIDAR winners receive cloud credits.
A28: 21 | B28: Network switch and cabling | C28: 8-port gigabit switch, patch cables | D28: Indian networking supplier | E28: I3 | F28: 0.3 | G28: 1 | H28: 600 | I28: =G28*H28 | J28: 3000 | K28: =G28*J28 | L28: =K28*F28 | M28: 1 wk | N28: Multi-machine SITL and mesh bench testing. | O28: —
B29: TOTAL | F29: =L29/K29 | I29: =SUM(I5:I28) | K29: =SUM(K5:K28) | L29: =SUM(L5:L28)

Sheet 05 Spares & Consumables
A1: 05 — SPARES AND CONSUMABLES, INDIAN SOURCES
A2: Domestic sourcing shortens spares lead time from 4-6 weeks to 2-3 — which is worth more than the price saving when something breaks in week 28.
A3: # | B3: Component | C3: Indian part / specification | D3: Indian supplier (location) | E3: Tier | F3: Indig. % | G3: Qty | H3: Unit Mass (g) | I3: Total Mass (g) | J3: Unit Price (INR) | K3: Ext. Price (INR) | L3: Indian Value (INR) | M3: Lead Time | N3: Why this part / sizing reference | O3: Indigenisation gap or action
A4: FLIGHT SPARES — Development Plan R4: a crash near the finals must not end the programme
A5: 1 | B5: Spare motors | C5: One full aircraft set | D5: Bharath Components / Mechtex | E5: I1 | F5: 0.9 | G5: 4 | H5: 150 | I5: =G5*H5 | J5: 7000 | K5: =G5*J5 | L5: =K5*F5 | M5: 3-4 wk | N5: Motors are the longest-lead flight-critical item — and domestic lead time beats import by weeks. | O5: —
A6: 2 | B6: Spare ESCs | C6: One full set | D6: Flameback Tech | E6: I1 | F6: 0.8 | G6: 4 | H6: 48 | I6: =G6*H6 | J6: 3000 | K6: =G6*J6 | L6: =K6*F6 | M6: 2-3 wk | N6: ESCs fail from vibration and heat. | O6: —
A7: 3 | B7: Spare propeller pairs | C7: 18 x 6.1 CF folding | D7: S R Aerospace / Bharath Components | E7: I2 | F7: 0.7 | G7: 6 | H7: 116 | I7: =G7*H7 | J7: 2200 | K7: =G7*J7 | L7: =K7*F7 | M7: 3 wk | N7: Props are consumed by every hard landing. | O7: —
A8: 4 | B8: Spare arm assemblies | C8: Tube + clamp + mount, pre-built | D8: In-house | E8: I2 | F8: 0.75 | G8: 4 | H8: 162 | I8: =G8*H8 | J8: 2200 | K8: =G8*J8 | L8: =K8*F8 | M8: 2 wk | N8: Arms are what break in a tip-over. Pre-build so a field repair is a 10-minute swap. | O8: —
A9: 5 | B9: Spare flight controller | C9: Pre-flashed with the frozen parameter set | D9: Agam Robotics | E9: I2 | F9: 0.6 | G9: 1 | H9: 50 | I9: =G9*H9 | J9: 26000 | K9: =G9*J9 | L9: =K9*F9 | M9: 3-4 wk | N9: Development Plan P10 config freeze. | O9: —
A10: 6 | B10: Spare GNSS | C10: NavIC receiver + antenna | D10: Teravolt Labs / Accord | E10: I2 | F10: 0.6 | G10: 1 | H10: 90 | I10: =G10*H10 | J10: 18000 | K10: =G10*J10 | L10: =K10*F10 | M10: 3 wk | N10: — | O10: —
A11: 7 | B11: Spare compute module | C11: Imaged, with the inference engine pre-built | D11: As per tab 01 | E11: I4 | F11: 0.25 | G11: 1 | H11: 200 | I11: =G11*H11 | J11: 38000 | K11: =G11*J11 | L11: =K11*F11 | M11: 4-8 wk | N11: Sizing S15: never build the inference engine at boot. The spare must be imaged and warm-cached too. Tracks tab 01 line 33. | O11: Same import gap as the primary.
A12: 8 | B12: Spare camera + lens | C12: Boresight-calibrated on a spare mount | D12: e-con Systems | E12: I2 | F12: 0.6 | G12: 1 | H12: 105 | I12: =G12*H12 | J12: 16600 | K12: =G12*J12 | L12: =K12*F12 | M12: 3-4 wk | N12: Swapping the camera invalidates the boresight calibration — calibrate the spare in advance. | O12: —
A13: 9 | B13: Spare battery packs | C13: Complete 6S3P packs | D13: Indian pack house | E13: I1 | F13: 0.85 | G13: 3 | H13: 1500 | I13: =G13*H13 | J13: 19000 | K13: =G13*J13 | L13: =K13*F13 | M13: 3 wk | N13: Two packs per aircraft minimum so a test day is not charger-limited; the third is the crash reserve. | O13: —
A14: 10 | B14: Spare airframe structure set | C14: Fourth frame kit: arms, clamps, centre plates, motor mounts, landing gear, tray, canopy, fasteners | D14: In-house from this BOM | E14: I2 | F14: 0.75 | G14: 1 | H14: 1300 | I14: =G14*H14 | J14: 25000 | K14: =G14*J14 | L14: =K14*F14 | M14: 3 wk | N14: REPLACES the INR 1.65 L complete fourth aircraft. Lines 1-9 above already hold a full set of motors, ESCs, props, arms, FC, GNSS, compute, camera and three packs -- INR 2.1 L, i.e. everything a fourth airframe needs EXCEPT the structure. Buying a whole aircraft on top of that bought most of it twice. This line buys the missing half, and its 2-3 wk lead is the part that cannot be compressed after a crash. | O14: RISK ACCEPTED: rebuilding consumes the spares, so a second failure in the same week is uncovered. Rule C1 needs only 2 aircraft flying. Reinstate the complete fourth aircraft at INR 165,000 if funding allows -- it is a schedule hedge, not a capability.
A15: CONSUMABLES
A16: 11 | B16: Threadlocker and adhesives | C16: Medium-strength threadlocker, CA, structural epoxy | D16: Pidilite / Anabond (Indian adhesive manufacturers) | E16: I1 | F16: 0.9 | G16: 1 | H16: 450 | I16: =G16*H16 | J16: 2500 | K16: =G16*J16 | L16: =K16*F16 | M16: 1 wk | N16: Every fastener on a vibrating airframe. Medium strength so field disassembly stays possible. | O16: Anabond and Pidilite are strong Indian adhesive makers.
A17: 12 | B17: Heat shrink, tape, lacing | C17: Adhesive-lined shrink, Kapton, fibreglass tape, lacing cord, zip ties | D17: Local electrical supplier | E17: I1 | F17: 1 | G17: 1 | H17: 620 | I17: =G17*H17 | J17: 2400 | K17: =G17*J17 | L17: =K17*F17 | M17: 1 wk | N17: — | O17: —
A18: 13 | B18: Solder and flux | C18: 60/40 1 mm, no-clean flux, desoldering braid | D18: Indian solder manufacturer | E18: I1 | F18: 0.8 | G18: 1 | H18: 500 | I18: =G18*H18 | J18: 1600 | K18: =G18*J18 | L18: =K18*F18 | M18: 1 wk | N18: — | O18: —
A19: 14 | B19: 3D printer filament | C19: PETG 3 kg, ASA 1 kg, TPU 1 kg | D19: WOL3D / Fila3D / Indian extruders | E19: I2 | F19: 0.5 | G19: 1 | H19: 5000 | I19: =G19*H19 | J19: 7500 | K19: =G19*J19 | L19: =K19*F19 | M19: 1-2 wk | N19: Magazine and canopy iterations consume more than you expect. | O19: Extrusion Indian, resin pellets imported.
A20: 15 | B20: Carbon plate stock | C20: 2.5 and 3 mm sheets, 400 x 500 mm | D20: Kineco / Composite Technology Park | E20: I2 | F20: 0.7 | G20: 2 | H20: 900 | I20: =G20*H20 | J20: 6500 | K20: =G20*J20 | L20: =K20*F20 | M20: 3 wk | N20: Plate re-cuts and repair doublers. | O20: —
A21: 16 | B21: PPE and cleaning | C21: Nitrile gloves, P2 masks, IPA, lint-free wipes, compressed air | D21: Local | E21: I1 | F21: 1 | G21: 1 | H21: 1800 | I21: =G21*H21 | J21: 3000 | K21: =G21*J21 | L21: =K21*F21 | M21: 1 wk | N21: CF machining, epoxy work, lens and connector cleaning. | O21: —
B22: TOTAL | F22: =L22/K22 | I22: =SUM(I5:I21) | K22: =SUM(K5:K21) | L22: =SUM(L5:L21)

Sheet 06 Software & Data
A1: 06 — SOFTWARE, DATA AND COMPLIANCE
A2: Software is nation-neutral open source. The indigenous asset here is the Indian field dataset — build it, and consider publishing it.
A3: # | B3: Component | C3: Indian part / specification | D3: Indian supplier (location) | E3: Tier | F3: Indig. % | G3: Qty | H3: Unit Mass (g) | I3: Total Mass (g) | J3: Unit Price (INR) | K3: Ext. Price (INR) | L3: Indian Value (INR) | M3: Lead Time | N3: Why this part / sizing reference | O3: Indigenisation gap or action
A4: FLIGHT, AUTONOMY AND PERCEPTION STACK — open source, zero licence cost
A5: 1 | B5: Autopilot firmware | C5: ArduPilot Copter or PX4 | D5: Open source; Indian FC vendors ship supported builds | E5: I1 | F5: 1 | G5: 1 | H5: 0 | I5: =G5*H5 | J5: 0 | K5: =G5*J5 | L5: =K5*F5 | M5: — | N5: Sizing §1. | O5: Both Agam and several Indian FCs run the standard stack, so you keep the ecosystem.
A6: 2 | B6: Middleware and bridge | C6: ROS 2 + Fast DDS, MAVROS or uXRCE-DDS | D6: Open source | E6: I1 | F6: 1 | G6: 1 | H6: 0 | I6: =G6*H6 | J6: 0 | K6: =G6*J6 | L6: =K6*F6 | M6: — | N6: DDS discovery and QoS map well to a lossy mobile mesh. | O6: —
A7: 3 | B7: MAVLink router | C7: mavlink-router / MAVProxy | D7: Open source | E7: I1 | F7: 1 | G7: 1 | H7: 0 | I7: =G7*H7 | J7: 0 | K7: =G7*J7 | L7: =K7*F7 | M7: — | N7: Rule C10: multiplexes 3 SYSIDs into ONE ground station. | O7: —
A8: 4 | B8: Mesh routing | C8: batman-adv | D8: Open source | E8: I1 | F8: 1 | G8: 1 | H8: 0 | I8: =G8*H8 | J8: 0 | K8: =G8*J8 | L8: =K8*F8 | M8: — | N8: Layer-2 mesh — the same technology commercial MANET radios run underneath. | O8: —
A9: 5 | B9: Simulator | C9: Gazebo + SITL | D9: Open source | E9: I1 | F9: 1 | G9: 1 | H9: 0 | I9: =G9*H9 | J9: 0 | K9: =G9*J9 | L9: =K9*F9 | M9: — | N9: Development Plan P4: 200-run Monte Carlo before any hardware flies. | O9: —
A10: 6 | B10: Coverage planner | C10: Static equal-area partition + boustrophedon, generated on the GCS (implementation-plan.md §1.3). DARP is presented as design, not implemented. | D10: Open source | E10: I1 | F10: 1 | G10: 1 | H10: 0 | I10: =G10*H10 | J10: 0 | K10: =G10*J10 | L10: =K10*F10 | M10: — | N10: Equal-area partitioning anchored to a common launch point. | O10: —
A11: 7 | B11: Task allocation | C11: Greedy claim-and-lock with deterministic tie-break (§1.4). CBBA is presented as design, not implemented. | D11: Open source | E11: I1 | F11: 1 | G11: 1 | H11: 0 | I11: =G11*H11 | J11: 0 | K11: =G11*J11 | L11: =K11*F11 | M11: — | N11: Choi, Brunet & How (2009): provable conflict-free convergence. | O11: —
A12: 8 | B12: Detector and runtime | C12: YOLO-class detector + vendor inference runtime + SAHI tiling | D12: Open source | E12: I1 | F12: 1 | G12: 1 | H12: 0 | I12: =G12*H12 | J12: 0 | K12: =G12*J12 | L12: =K12*F12 | M12: — | N12: Sizing §8.2. | O12: Check the AGPL terms of Ultralytics against NIDAR IP conditions; MMDetection (Apache 2.0) is the safe alternative.
A13: 9 | B13: VEGA toolchain | C13: RISC-V GCC toolchain and BSP for the VEGA kits | D13: C-DAC (MeitY) | E13: I1 | F13: 1 | G13: 1 | H13: 0 | I13: =G13*H13 | J13: 0 | K13: =G13*J13 | L13: =K13*F13 | M13: via NIDAR | N13: Supports the VEGA co-processor subsystem on tab 01. | O13: Fully indigenous. Engage C-DAC support early — the toolchain is younger than ARM equivalents.
A14: DATA — THE MOST IMPORTANT INDIGENISATION ITEM ON THIS SHEET
A15: 10 | B15: Indian SAR field dataset | C15: >=2,000 annotated frames: your camera, your altitudes, Indian terrain, Indian clothing, Indian light | D15: In-house field campaign (Development Plan P7) | E15: I1 | F15: 1 | G15: 1 | H15: 0 | I15: =G15*H15 | J15: 60000 | K15: =G15*J15 | L15: =K15*F15 | M15: 12+ wk | N15: Development Plan P7 is the long pole. This is the single highest-leverage indigenous asset you will build. | O15: HERIDAL and SARD are European. Their terrain, vegetation, clothing and sun angle do not match an Indian flood plain. Use them for pre-training and benchmarking, then fine-tune on your own data. Cost is logistics: transport, volunteers, mannequins, annotation labour.
A16: 11 | B16: Public datasets | C16: HERIDAL, SARD, WiSARD | D16: European research groups (free, on request) | E16: I4 | F16: 0 | G16: 1 | H16: 0 | I16: =G16*H16 | J16: 0 | K16: =G16*J16 | L16: =K16*F16 | M16: 2-4 wk | N16: Sizing §8: reproduce published metrics to validate your pipeline before trusting your own data. | O16: No Indian equivalent exists. Consider publishing yours — that alone is a strong NIDAR outcome.
A17: 12 | B17: Annotation tooling | C17: CVAT, self-hosted | D17: Open source, hosted on Indian cloud | E17: I1 | F17: 1 | G17: 1 | H17: 0 | I17: =G17*H17 | J17: 0 | K17: =G17*J17 | L17: =K17*F17 | M17: — | N17: Self-host to avoid per-seat cost on 2,000+ frames. | O17: —
A18: 13 | B18: Training compute | C18: GPU hours for detector training and the SITL Monte Carlo | D18: E2E Networks / Yotta / NxtGen (Indian GPU cloud) | E18: I1 | F18: 0.9 | G18: 1 | H18: 0 | I18: =G18*H18 | J18: 75000 | K18: =G18*J18 | L18: =K18*F18 | M18: — | N18: A genuinely indigenous option for training compute, unlike inference silicon. Raised from INR 40,000 to absorb the cut dev workstation (tab 04 line 20): net saving INR 1.30 L, and it moves INR 75,000 of spend from I3 0.2 to I1 0.9. | O18: NIDAR provides cloud credits to winning teams. Indian GPU cloud is a real and growing capability.
A19: 14 | B19: Offline map tiles | C19: Cached basemap for the venue and all test sites Plus MediaMTX as the WebRTC video gateway: rule 8.14 needs a live feed from each drone, and three MJPEG streams would break the link budget. | D19: Survey of India / Bhuvan (ISRO) / OSM export | E19: I1 | F19: 1 | G19: 1 | H19: 0 | I19: =G19*H19 | J19: 0 | K19: =G19*J19 | L19: =K19*F19 | M19: 1 wk | N19: RULE C12 FORBIDS INTERNET — online tiles will not load at the venue. Teams lose points to this every year. | O19: ISRO Bhuvan imagery is Indian, free, and appropriate for the C11 boundary display. Cache it in advance.
A20: REGULATORY AND ADMIN
A21: 15 | B21: DGCA airspace and operations | C21: Zone check for every test site, operator and pilot requirements | D21: DGCA Digital Sky | E21: I1 | F21: 1 | G21: 1 | H21: 0 | I21: =G21*H21 | J21: 5000 | K21: =G21*J21 | L21: =K21*F21 | M21: 2-4 wk | N21: Development Plan P0 exit gate. Confirm the zone colour BEFORE booking a campaign. | O21: —
A22: 16 | B22: WPC / ETA | C22: Equipment Type Approval for every radio flown | D22: WPC, DoT / supplier declarations | E22: I1 | F22: 1 | G22: 1 | H22: 0 | I22: =G22*H22 | J22: 10000 | K22: =G22*J22 | L22: =K22*F22 | M22: 4-8 wk | N22: Sizing §12: 5.825-5.875 GHz is delicensed for drones and 865-867 MHz for SRDs, but the EQUIPMENT still needs ETA. | O22: ADVANTAGE OF INDIAN SUPPLIERS: FxUAV and Indian RF houses design to Indian spectrum rules and can supply ETA documentation. Imported radios routinely cannot.
A23: 17 | B23: Insurance | C23: Third-party liability for flight operations | D23: Indian insurer (drone liability products exist) | E23: I1 | F23: 1 | G23: 1 | H23: 0 | I23: =G23*H23 | J23: 25000 | K23: =G23*J23 | L23: =K23*F23 | M23: 3 wk | N23: Many test sites and institutions require it. | O23: —
B24: TOTAL | F24: =L24/K24 | I24: =SUM(I5:I23) | K24: =SUM(K5:K23) | L24: =SUM(L5:L23)

Sheet 07 Mass Rollup
A1: 07 — MASS ROLLUP AND RULE C2 COMPLIANCE CHECK
A2: Rule C2: combined all-up weight of ALL deployed drones, including batteries, payloads and every accessory, must not exceed 25 kg.
A4: # | B4: Group | C4: Sizing model (g) | D4: Indian BOM (g) | E4: Actual measured (g) | F4: Delta vs model | G4: Note
A5: 1 | B5: Structure | C5: 1187 | D5: 1240 | F5: =D5-C5 | G5: Indian CF tube and plate are marginally heavier per the quoted wall thicknesses
A6: 2 | B6: Propulsion (motors, ESCs, props, hubs) | C6: 934 | D6: 1032 | F6: =D6-C6 | G6: Indian motors quoted at ~150 g vs 135 g for the imported reference
A7: 3 | B7: Power (pack + distribution) | C7: 1724 | D7: 1780 | F7: =D7-C7 | G7: Pack assembly mass from an Indian pack house, incl. holders and BMS
A8: 4 | B8: Avionics | C8: 217 | D8: 262 | F8: =D8-C8 | G8: Includes the VEGA co-processor board at ~60 g
A9: 5 | B9: Compute & perception | C9: 444 | D9: 460 | F9: =D9-C9 | G9: Indian camera module and mount; imported SoM
